Workbook
Name prov_cd: 'SELECT PROVINCE'!$B$1
Name province_codes: 'SELECT PROVINCE'!$B$6:$B$16
Name rate_table: 'SELECT PROVINCE'!$B$6:$C$16

Sheet 26MY_CIV5D_DATA
B1: 1 | C1: 2 | D1: 3 | E1: 4 | F1: 5 | G1: 6 | H1: 23 | I1: 24 | J1: 25 | K1: 26 | L1: 27 | M1: 28 | N1: 29 | O1: 30 | P1: 31 | Q1: 32 | R1: 33 | S1: 34 | T1: 35 | U1: 36 | V1: 37
B2: Model Name | C2: Civic Hatch & Type R | D2: Civic à Hayon & Type R | W2: Yes | X2: Yes | Y2: Yes | Z2: Yes | AA2: Yes | AB2: Yes | AC2: Yes | AD2: Yes | AE2: Yes
B3: Model Year | C3: 2026 | W3: No | X3: No | Y3: No | Z3: No | AA3: No | AB3: No | AC3: No | AD3: No | AE3: No
B4: Publication Date | C4: 46142 | D4: yyyy/mm/dd | M4: * if it's "N/A" or "S" do not show on trim | W4: NEW | X4: NEW | Y4: NEW | Z4: NEW | AA4: NEW | AB4: NEW | AC4: NEW | AD4: NEW | AE4: NEW
M5: Trim Application* | W5: N/A
B6: PARTS | C6: HAC | L6: =prov_cd -> YT | P6: SPORT | Q6: SPORT Hybride | S6: Sport Touring Hybride | T6: Type R | W6: Images | AG6: Wheels | AH6: Charging | AI6: Featured | AJ6: Included | AK6: Accessories
B7: Part Number / Kit Part Number | C7: Part Number | D7: Item Name English | E7: Item Name French | F7: Description English | G7: Description French | H7: FRT | I7: Residual-ized $ | J7: Dealer Net | K7: List Price | L7: Install Price | P7: SPORT | Q7: SPORT Hybrid | S7: Sport Touring Hybrid | T7: Type R | U7: Comments English | V7: Comments French | W7: SiteCore | X7: Overlay 1 | Y7: Overlay 2 | Z7: Overlay 3 | AA7: Overlay 4 | AB7: Overlay 5 | AC7: Overlay 6 | AD7: Overlay 7 | AE7: Overlay 8 | AF7: Display Order | AK7: Safety & Exterior Protection | AL7: Winter Season | AM7: Exterior & Interior Utility | AN7: Interior Styling | AO7: Exterior Styling | AP7: Misc-ellaneous | AR7: Dependancies | AS7: Exclusions
B8: 25CIV-ENK-WTPK | C8: 25CIV-ENK-WTPK | D8: 16” Enkei M52 Wheels & Michelin X-ICE Snow Tire Package | E8: Ensemble de roues Enkei M52 de 16 po et de pneus Michelin X-ICE Snow | F8: These attractive & custom Enkei M52 wheels are hub centric and compatible with your factory lug nuts. Compliment these wheels with the Michelin X-ICE Snow tires for the ultimate traction & style during our Canadian winters. | G8: Ces attrayantes et distinctives roues Enkei M52 sont centrées sur le moyeu et compatibles avec les écrous de roue d’origine de votre véhicule. Jumelez ces roues aux pneus Michelin X ICE Snow pour un style et une adhérence convenant parfaitement à nos hivers canadiens. | H8: 1.2 | J8: =J12+J30 -> 1596.56 | K8: =K12+K30 -> 2028 | L8: =K8+(H8*VLOOKUP(prov_cd,rate_table,2,FALSE)) -> 2245.2 | P8: • | Q8: N/A | S8: N/A | T8: N/A | U8: Priced as a set of 4 wheels. | V8: Prix établi pour ensemble de 4 pneus. | W8: Yes | AF8: 6 | AG8: • | AI8: • | AL8: •
B9: 25CIV-STL-WTPK | C9: 25CIV-STL-WTPK | D9: 16” Winter Steel Wheels & Michelin X-ICE Snow Tire Package | E9: Ensemble de roues d’hiver de 16 po en acier et de pneus Michelin X-ICE Snow | F9: Steel wheels offer great value and allow you to save your factory wheels from our harsh Canadian winters. Compliment these wheels with the Michelin X-ICE Snow tires for the ultimate traction & style during our Canadian winters. | G9: Des roues en acier offrent un excellent rapport qualité-prix et vous permettent de préserver les roues d’origine de votre véhicule de nos rigoureux hivers canadiens. Jumelez ces roues aux pneus Michelin X ICE Snow pour un une adhérence optimale lors de nos hivers canadiens. | H9: 1.2 | J9: =J12+J29 -> 1150.4 | K9: =K12+K29 -> 1522.72 | L9: =K9+(H9*VLOOKUP(prov_cd,rate_table,2,FALSE)) -> 1739.92 | P9: • | Q9: N/A | S9: N/A | T9: N/A | U9: Priced as a set of 4 wheels. | V9: Prix établi pour ensemble de 4 pneus. | W9: Yes | AF9: 7 | AG9: • | AI9: • | AL9: •
B10: 480-670-6545-SP or 480-670-6545-GB | C10: N/A only used for app chart | D10: 16" Enkei M52 Wheels - Silver or Gloss Black
B11: 480-670-6545-SP ou 480-670-6545-GB | C11: N/A only used for app chart | E11: Roues Enkei M52 de 16 po - argent ou noir brillant
B12: 34417 | C12: N/A only used for app chart | D12: Michelin X-ICE Snow Tires - 215/55/16 | E12: Pneus Michelin X-ICE Snow - 215/55/16 | J12: =VLOOKUP(B12,'[1]MASTER PART LIST'!$B:$C,2,FALSE)*4 -> 832.56 | K12: =VLOOKUP(B12,'[1]MASTER PART LIST'!$B:$D,3,FALSE)*4 -> 1000
B13: 25CIV5-ARO-PK | C13: =B14 -> 25CIV-5AR-NH883 | D13: Aero Kit | E13: Ensemble Aero | F13: Enhance the styling of your Civic Hatch with the Aero Kit. Includes body coloured front underbody spoiler and HPD Tailgate Spoiler. All packaged together with a 10% discount. | G13: Améliorez le style de votre Civic Hatch avec le Kit Aero. Comprend un déflecteur de bas de caisse avant de couleur assortie à la carrosserie et déflecteur de hayon HPD. Le tout est offert sous forme d’ensemble avec un rabais de 10 %. | H13: =H14 -> 2.2 | J13: =J14 -> 660.6 | K13: =K14 -> 1101.6 | L13: =K13+(H13*VLOOKUP(prov_cd,rate_table,2,FALSE)) -> 1499.8 | P13: • | Q13: • | S13: • | T13: N/A | U13: 10% Discount Applied. Includes body coloured front underbody spoiler and tailgate spoiler. | V13: Rabais de 10 % appliqué. Comprend déflecteur de bas de caisse avant de la couleur de la carrosserie et un becquet de hayon. | W13: Yes | AF13: 5 | AI13: • | AO13: • | AS13: Front Underbody Spoiler - 08F01-T20-130A Tailgate Spoiler, HPD - 08F02-T47-130
A14: need | B14: 25CIV-5AR-NH883 | D14: Platinum White Pearl (NH-883P) | E14: Blanc platine nacré (NH-883P) | H14: =H49+H70 -> 2.2 | J14: =(J49+J70)*0.9 -> 660.6 | K14: =(K49+K70)*0.9 -> 1101.6 | L14: =K14+(H14*VLOOKUP(prov_cd,rate_table,2,FALSE)) -> 1499.8 | P14: • | Q14: • | S14: • | T14: N/A
A15: need | B15: 25CIV-5AR-NH932 | D15: Solar Reflection Silver (NH-932M) | E15: Refl et solaire argent métallisé (NH-932M) | H15: =H50+H71 -> 2.2 | J15: =(J50+J71)*0.9 -> 660.6 | K15: =(K50+K71)*0.9 -> 1101.6 | L15: =K15+(H15*VLOOKUP(prov_cd,rate_table,2,FALSE)) -> 1499.8 | P15: • | Q15: • | S15: • | T15: N/A
A16: need | B16: 25CIV-5AR-NH904 | D16: Meteoroid Gray Pearl (NH-904M) | E16: Gris météore nacré (NH-904M) | H16: =H51+H72 -> 2.2 | J16: =(J51+J72)*0.9 -> 660.6 | K16: =(K51+K72)*0.9 -> 1101.6 | L16: =K16+(H16*VLOOKUP(prov_cd,rate_table,2,FALSE)) -> 1499.8 | P16: N/A | Q16: • | S16: N/A | T16: N/A
A17: need | B17: 25CIV-5AR-NH912 | D17: Urban Grey Pearl (NH-912P) | E17: Gris urbain nacré (NH-912P) | H17: =H137+H139 -> 2.2 | J17: =(J137+J139)*0.9 -> 660.6 | K17: =(K137+K139)*0.9 -> 1101.6 | L17: =K17+(H17*VLOOKUP(prov_cd,rate_table,2,FALSE)) -> 1499.8 | P17: N/A | Q17: N/A | S17: • | T17: N/A
A18: need | B18: 25CIV-5AR-NH731 | D18: Crystal Black Pearl (NH-731P) | E18: Noir cristal nacré (NH-731P) | H18: =H52+H73 -> 2.2 | J18: =(J52+J73)*0.9 -> 660.6 | K18: =(K52+K73)*0.9 -> 1101.6 | L18: =K18+(H18*VLOOKUP(prov_cd,rate_table,2,FALSE)) -> 1499.8 | P18: • | Q18: • | S18: • | T18: N/A
A19: need | B19: 25CIV-5AR-R513 | D19: Rallye Red (R-513) | E19: Rouge rallye (R-513) | H19: =H53+H74 -> 2.2 | J19: =(J53+J74)*0.9 -> 660.6 | K19: =(K53+K74)*0.9 -> 1101.6 | L19: =K19+(H19*VLOOKUP(prov_cd,rate_table,2,FALSE)) -> 1499.8 | P19: N/A | Q19: • | S19: • | T19: N/A
A20: need | B20: 25CIV-5AR-B637 | D20: Boost Blue Pearl (B-637P) | E20: Bleu turbo nacré (B-637P) | H20: =H138+H75 -> 2.2 | J20: =(J54+J75)*0.9 -> 660.6 | K20: =(K54+K75)*0.9 -> 1101.6 | L20: =K20+(H20*VLOOKUP(prov_cd,rate_table,2,FALSE)) -> 1499.8 | P20: N/A | Q20: N/A | S20: • | T20: N/A
B21: 22CIV-COLD-PK20 | C21: 22CIV-COLD-PK20 | D21: Cold Weather Package - 2.0L | E21: Ensemble de temps froid - 2,0 L | F21: Package includes: Engine Block Heater and Auto Battery Charger/Maintainer. Packaged together with a 5% discount. | G21: L’ensemble inclut : Chauffe-moteur et chargeur/mainteneur automatique de batterie de 12 V Optimate. Offerts en ensemble avec une remise de 5 %. | H21: =H86+H88 -> 1.4 | J21: =(J86+J88)*0.95 -> 230.85 | K21: =(K86+K88)*0.95 -> 384.75 | L21: =K21+(H21*VLOOKUP(prov_cd,rate_table,2,FALSE)) -> 638.15 | P21: • | Q21: • | S21: • | T21: N/A | U21: 5% Discount Applied. | V21: Rabais de 5 % appliqué. | W21: Yes | AF21: 9 | AI21: • | AL21: • | AS21: Engine Block Heater - 2.0L - 08T44-SNA-302 Optimate 12V Auto Battery Charger/Maintainer - 31670-BMS-004H
B22: 23CIV-COLD-TR | C22: 23CIV-COLD-TR | D22: Cold Weather Package - Type R | E22: Ensemble de temps froid - Type R | F22: Package includes: Engine Block Heater and Auto Battery Charger/Maintainer. Packaged together with a 5% discount. | G22: L’ensemble inclut : Chauffe-moteur et chargeur/mainteneur automatique de batterie de 12 V Optimate. Offerts en ensemble avec une remise de 5 %. | H22: =H102+H88 -> 1.4 | J22: =(J102+J88)*0.95 -> 278.35 | K22: =(K102+K88)*0.95 -> 464.55 | L22: =K22+(H22*VLOOKUP(prov_cd,rate_table,2,FALSE)) -> 717.95 | P22: N/A | Q22: N/A | S22: N/A | T22: • | U22: 5% Discount Applied. | V22: Rabais de 5 % appliqué. | AK22: • | AS22: Engine Block Heater Type R - 08T44-TGH-300 Optimate 12V Auto Battery Charger/Maintainer - 31670-BMS-004H
B23: 25CIV5D-PRO-PET | C23: =B23 -> 25CIV5D-PRO-PET | D23: Protection Package - Petrol | E23: Ensemble de protection - Petrol | F23: Package includes: All-Season Floor Mats, Rear Splash Guards, and Trunk Tray. | G23: L’ensemble inclut : Tapis toutes saisons, garde-boue arrière, et plateau de coffre. | H23: =H79+H84+H47 -> 0.6 | J23: =(J79+J84+J47)*0.9 -> 297 | K23: =K79+K84+K47 -> 550 | L23: =K23+(H23*VLOOKUP(prov_cd,rate_table,2,FALSE)) -> 658.6 | P23: • | Q23: N/A | S23: N/A | T23: N/A | W23: Yes | AF23: 2 | AI23: • | AM23: • | AS23: Floor Mats - All-Season - 08P17-T20-110 Trunk Tray - 08U45-T47-100B Rear Splash Guards - 08P09-T47-300
B24: 25CIV5-PRO-HYB | C24: 25CIV5-PRO-HYB | D24: Protection Package - Hybrid | E24: Ensemble de protection - Hybrid | F24: Package includes: All-Season Floor Mats, Rear Splash Guards, and Trunk Tray. | G24: L’ensemble inclut : Tapis toutes saisons, garde-boue arrière, et plateau de coffre. | H24: =H80+H84+H47 -> 0.6 | J24: =(J80+J84+J47)*0.9 -> 297 | K24: =K80+K84+K47 -> 550 | L24: =K24+(H24*VLOOKUP(prov_cd,rate_table,2,FALSE)) -> 658.6 | P24: N/A | Q24: • | S24: • | T24: N/A | W24: Yes | AF24: 3 | AI24: • | AM24: • | AS24: Floor Mats Hybrid - All-Season - 08P17-T20-110A Trunk Tray - 08U45-T47-100 Rear Splash Guards - 08P09-T47-300
B25: 23TYPER-PROPK | C25: =B25 -> 23TYPER-PROPK | D25: Protection Package - Type R | E25: Ensemble de protection - Type R | F25: Package includes: All-Season Floor Mats, and Cargo Tray. | G25: L’ensemble inclut : Tapis toutes saisons et plateau de coffre. | H25: =(H79+H108) -> 0.2 | J25: =(J79+J108)*0.9 -> 245.7 | K25: =(K79+K108) -> 455 | L25: =K25+(H25*VLOOKUP(prov_cd,rate_table,2,FALSE)) -> 491.2 | P25: N/A | Q25: N/A | S25: N/A | T25: • | AF25: 4 | AI25: • | AS25: Floor Mats All-Season Type R - 08P17-T20-110 Cargo Tray Type R - 08U45-T60-100
B26: 25CIV5-PRO-FLM | C26: 25CIV5-PRO-FLM | D26: Protection Package - Film | E26: Ensemble de protection - Film | F26: Package includes: Door Edge and Door Sill Protection Films, and Rear Bumper Applique. | G26: L’ensemble inclut : Pellicule pour rebord de portière, pellicule de protection de seuil de portière, et pellicule pour pare-chocs arrière. | H26: =H46+H41+H78 -> 1 | J26: =(J46+J41+J78)*0.9 -> 205.2 | K26: =(K46+K41+K78)*0.9 -> 330.3 | L26: =K26+(H26*VLOOKUP(prov_cd,rate_table,2,FALSE)) -> 511.3 | P26: N/A | Q26: N/A | S26: N/A | T26: N/A | U26: 10% Discount Applied. Cannot be installed with Door Edge Guards | V26: Rabais de 10 % appliqué. Ne peut être installé simultanément avec protecteurs de bordure de porte. | W26: Yes | AF26: 8 | AI26: • | AK26: • | AS26: Door Edge Film - 08P20-T20-100A Door Sill Protection Film - 08P04-T20-100 08P01-T47-100 Rear Bumper Protector
B27: 26TYPER-RACE | C27: =B27 -> 26TYPER-RACE | D27: Racing Package - Type R | E27: Ensemble de course – Type R | F27: Package includes: Carbon Fiber Wing Spoiler, Alcantara Steering Wheel and Red Leather Shift Knob | G27: L'ensemble comprend un aileron arrière en fibre de carbone, un volant en Alcantara et un pommeau de levier de vitesse gainé de cuir rouge. | H27: =H105+H109+H110 -> 1 | J27: =J105+J109+J110 -> 3928 | K27: =K105+K109+K110 -> 6431 | L27: =K27+(H27*VLOOKUP(prov_cd,rate_table,2,FALSE)) -> 6612 | P27: N/A | Q27: N/A | S27: N/A | T27: • | AF27: 1 | AI27: •
A29: no image | B29: 42700-TBA-A12 | C29: 42700-TBA-A12 | D29: 16” Winter Steel Wheels | E29: Roues d’hiver de 16 po en acier | F29: Steel wheels offer great value and allow you to save your factory wheels from our harsh Canadian winters. Price listed excludes winter tires and installation. Set of 4. | G29: Des roues en acier offrent un excellent rapport qualité-prix et vous permettent de préserver les roues d’origine de votre véhicule de nos rigoureux hivers canadiens. Le prix indiqué exclut les pneus d'hiver et l'installation. Ensemble de quatre. | H29: 1.6 | J29: =VLOOKUP(B29,'[1]MASTER PART LIST'!$B:$C,2,FALSE)*4 -> 317.84 | K29: =VLOOKUP(B29,'[1]MASTER PART LIST'!$B:$D,3,FALSE)*4 -> 522.72 | L29: =K29+(H29*VLOOKUP(prov_cd,rate_table,2,FALSE)) -> 812.32 | P29: • | Q29: N/A | S29: N/A | T29: N/A | U29: Priced as a set of 4 wheels. Tires sold separately. | V29: Prix pour un ensemble de 4 roues. Pneus vendus séparément. | AF29: 12 | AG29: • | AK29: •
B30: 480-670-6545GB | C30: 480-670-6545GB | D30: 16" Enkei M52 Wheel - Gloss Black | E30: Jantes Enkei M52 de 16 po noir lustré | F30: Look great all year round with a custom set of attractive winter alloy wheels. Designed & Approved for your Honda, these attractive and strong Enkei alloy wheels are compatible with your factory lug nuts & feature a unique hub centric design. Priced as a set of 4 wheels. Tires sold separately. | G30: Vous aurez fière allure tout au long de l'année avec un ensemble personnalisé de jantes en alliage pour l'hiver. Conçues et approuvées pour votre Honda, ces jantes en alliage Enkei robustes et attrayantes sont compatibles avec vos écrous de roue d'origine et présentent une conception unique centrée sur le moyeu. Prix pour un jeu de 4 jantes. Pneus vendus séparément. | H30: 1.6 | J30: =VLOOKUP(B30,'[1]MASTER PART LIST'!$B:$C,2,FALSE)*4 -> 764 | K30: =VLOOKUP(B30,'[1]MASTER PART LIST'!$B:$D,3,FALSE)*4 -> 1028 | L30: =K30+(H30*VLOOKUP(prov_cd,rate_table,2,FALSE)) -> 1317.6 | P30: T | Q30: N/A | S30: N/A | T30: N/A | U30: Priced as a set of 4 wheels. Tires sold separately. | V30: Prix pour un ensemble de 4 roues. Pneus vendus séparément. | W30: Yes | AF30: 13 | AG30: • | AK30: •
B31: 480-670-6545SP | C31: 480-670-6545SP | D31: 16" Enkei M52 Wheel - Silver | E31: Jantes Enkei M52 de 16 po argent | F31: Look great all year round with a custom set of attractive winter alloy wheels. Designed & Approved for your Honda, these attractive and strong Enkei alloy wheels are compatible with your factory lug nuts & feature a unique hub centric design. Priced as a set of 4 wheels. Tires sold separately. | G31: Vous aurez fière allure tout au long de l'année avec un ensemble personnalisé de jantes en alliage pour l'hiver. Conçues et approuvées pour votre Honda, ces jantes en alliage Enkei robustes et attrayantes sont compatibles avec vos écrous de roue d'origine et présentent une conception unique centrée sur le moyeu. Prix pour un jeu de 4 jantes. Pneus vendus séparément. | H31: 1.6 | J31: =VLOOKUP(B31,'[1]MASTER PART LIST'!$B:$C,2,FALSE)*4 -> 764 | K31: =VLOOKUP(B31,'[1]MASTER PART LIST'!$B:$D,3,FALSE)*4 -> 1028 | L31: =K31+(H31*VLOOKUP(prov_cd,rate_table,2,FALSE)) -> 1317.6 | P31: T | Q31: N/A | S31: N/A | T31: N/A | U31: Priced as a set of 4 wheels. Tires sold separately. | V31: Prix pour un ensemble de 4 roues. Pneus vendus séparément. | W31: Yes | AF31: 14 | AG31: • | AK31: •
B32: 509-775-6545BH | C32: 509-775-6545BH | D32: 17" Enkei Draco Wheel, Gloss Black | E32: Jantes Enkei de 17 po noir lustré | F32: Look great all year round with a custom set of attractive winter alloy wheels. Designed & Approved for your Honda, these attractive and strong Enkei alloy wheels are compatible with your factory lug nuts & feature a unique hub centric design. Priced as a set of 4 wheels. Tires sold separately. | G32: Vous aurez fière allure tout au long de l'année avec un ensemble personnalisé de jantes en alliage pour l'hiver. Conçues et approuvées pour votre Honda, ces jantes en alliage Enkei robustes et attrayantes sont compatibles avec vos écrous de roue d'origine et présentent une conception unique centrée sur le moyeu. Prix pour un jeu de 4 jantes. Pneus vendus séparément. | H32: 1.6 | J32: =VLOOKUP(B32,'[1]MASTER PART LIST'!$B:$C,2,FALSE)*4 -> 856 | K32: =VLOOKUP(B32,'[1]MASTER PART LIST'!$B:$D,3,FALSE)*4 -> 1148 | L32: =K32+(H32*VLOOKUP(prov_cd,rate_table,2,FALSE)) -> 1437.6 | P32: T | Q32: N/A | S32: N/A | T32: N/A | U32: Priced as a set of 4 wheels. Tires sold separately. | V32: Prix pour un ensemble de 4 roues. Pneus vendus séparément. | W32: Yes | AF32: 15 | AG32: •
B33: 509-775-6545SH | C33: 509-775-6545SH | D33: 17" Enkei Draco Wheel, Silver | E33: Jantes Enkei de 17 po argent | F33: Look great all year round with a custom set of attractive winter alloy wheels. Designed & Approved for your Honda, these attractive and strong Enkei alloy wheels are compatible with your factory lug nuts & feature a unique hub centric design. Priced as a set of 4 wheels. Tires sold separately. | G33: Vous aurez fière allure tout au long de l'année avec un ensemble personnalisé de jantes en alliage pour l'hiver. Conçues et approuvées pour votre Honda, ces jantes en alliage Enkei robustes et attrayantes sont compatibles avec vos écrous de roue d'origine et présentent une conception unique centrée sur le moyeu. Prix pour un jeu de 4 jantes. Pneus vendus séparément. | H33: 1.6 | J33: =VLOOKUP(B33,'[1]MASTER PART LIST'!$B:$C,2,FALSE)*4 -> 856 | K33: =VLOOKUP(B33,'[1]MASTER PART LIST'!$B:$D,3,FALSE)*4 -> 1148 | L33: =K33+(H33*VLOOKUP(prov_cd,rate_table,2,FALSE)) -> 1437.6 | P33: T | Q33: N/A | S33: N/A | T33: N/A | U33: Priced as a set of 4 wheels. Tires sold separately. | V33: Prix pour un ensemble de 4 roues. Pneus vendus séparément. | W33: Yes | AF33: 16 | AG33: •
B34: 08W18-T20-100 | C34: 08W18-T20-100 | D34: 18" Alloy Wheel - Black | E34: Jantes de 18 pouces noir | F34: Attract even more attention with these stunning 18" Alloy Wheels structurally matched to the original vehicle design so that handling remains undisturbed. Priced as a set of 4. Recommended tires sold separately. | G34: Attirez encore plus l’attention avec ces superbes jantes de 18 pouces dont la structure est adaptée à la conception originale du véhicule afin que la maniabilité reste inchangée. Prix pour ensemble de 4. Pneus recommandés vendus séparément | H34: 1.6 | J34: =VLOOKUP(B34,'[1]MASTER PART LIST'!$B:$C,2,FALSE)*4 -> 2316 | K34: =VLOOKUP(B34,'[1]MASTER PART LIST'!$B:$D,3,FALSE)*4 -> 3564 | L34: =K34+(H34*VLOOKUP(prov_cd,rate_table,2,FALSE)) -> 3853.6 | P34: E | Q34: E | S34: E | T34: N/A | U34: Priced as a set of 4 wheels. Tires sold separately. | V34: Prix pour un ensemble de 4 roues. Pneus vendus séparément. | W34: Yes | X34: No | Y34: No | Z34: No | AF34: 10 | AG34: •
B35: 08W19-T60-100 | C35: =B35 -> 08W19-T60-100 | D35: 19" Light Weight Alloy Wheel | E35: Jantes de 19 pouces | F35: Stronger, lighter, and visually distinct, these Alloy Wheels are everything you want rolled into an impressive presentation. 5.29 pounds lighter than OEM wheels. Distinct Shark Gray metallic-finish, laser-etched logo | G35: Plus résistantes, plus légères et visuellement distinctes, ces jantes en alliage ont tout ce que vous recherchez, réunies dans une présentation impressionnante.. Pèsent moins de 5,29 livres que les roues d’origine. Fini gris requin métallisé distinct, logo gravé au laser. | H35: 1.6 | J35: =VLOOKUP(B35,'[1]MASTER PART LIST'!$B:$C,2,FALSE)*4 -> 4664 | K35: =VLOOKUP(B35,'[1]MASTER PART LIST'!$B:$D,3,FALSE)*4 -> 6664 | L35: =K35+(H35*VLOOKUP(prov_cd,rate_table,2,FALSE)) -> 6953.6 | P35: N/A | Q35: N/A | S35: N/A | T35: E | U35: Priced as a set of 4 wheels. Tires sold separately. Laser-etched logo & shark gray metallic finish | V35: Prix pour un ensemble de 4 roues. Pneus vendus séparément. | AF35: 11 | AG35: •
A36: ** needs to be added to WEB** | B36: 08W42-TG7-301A | C36: 08W42-TG7-301A | D36: Wheel Locks - Black (Type R) | E36: Écrous de roue antivols - Noirs (Type R) | F36: A great way to help ensure that your wheels stay on your vehicle where they belong. | G36: Un excellent moyen de vous assurer que les roues demeurent sur votre véhicule là où elles devraient se trouver. | H36: 0.2 | J36: =VLOOKUP(B36,'[1]MASTER PART LIST'!$B:$C,2,FALSE) -> 88 | K36: =VLOOKUP(B36,'[1]MASTER PART LIST'!$B:$D,3,FALSE) -> 147 | L36: =K36+(H36*VLOOKUP(prov_cd,rate_table,2,FALSE)) -> 183.2 | P36: N/A | Q36: N/A | S36: N/A | T36: • | AF36: 17 | AK36: •
B37: 08W42-TK4-301 | C37: 08W42-TK4-301 | D37: Wheel Locks - Chrome (Type R) | E37: Écrous de roue antivols - Chromés (Type R) | F37: A great way to help ensure that your wheels stay on your vehicle where they belong. Chrome-plated triple-nickel finish for a brilliant shine and corrosion prevention | G37: Un excellent moyen de vous assurer que les roues demeurent sur votre véhicule, où elles devraient se trouver. La finition chromée triple nickel procure un éclat brillant et une prévention contre la corrosion. | H37: 0.2 | J37: =VLOOKUP(B37,'[1]MASTER PART LIST'!$B:$C,2,FALSE) -> 94 | K37: =VLOOKUP(B37,'[1]MASTER PART LIST'!$B:$D,3,FALSE) -> 157 | L37: =K37+(H37*VLOOKUP(prov_cd,rate_table,2,FALSE)) -> 193.2 | P37: N/A | Q37: N/A | S37: N/A | T37: • | AF37: 18 | AK37: •
B38: 08W42-S2A-101 | C38: 08W42-S2A-101 | D38: Wheel Locks - Black | E38: Écrous de roue antivols - Noirs | F38: A great way to help ensure that your wheels stay on your vehicle where they belong. Functions like a regular lug nut, but requires a special key tool for installation and removal. Hardened-steel construction is durable and theft-resistant. | G38: Un excellent moyen de vous assurer que les roues demeurent sur votre véhicule, là où elles devraient se trouver. S’utilisent comme des écrous réguliers, mais nécessitent un outil spécial pour l’installation et le retrait. Fabriqués en acier trempé, ils sont durables et antivol. | H38: 0.2 | J38: =VLOOKUP(B38,'[1]MASTER PART LIST'!$B:$C,2,FALSE) -> 61 | K38: =VLOOKUP(B38,'[1]MASTER PART LIST'!$B:$D,3,FALSE) -> 102 | L38: =K38+(H38*VLOOKUP(prov_cd,rate_table,2,FALSE)) -> 138.2 | P38: • | Q38: • | S38: • | T38: N/A | W38: Yes | AF38: 19 | AK38: • | AS38: 08W42-SCV-302 Wheel Locks - Chrome
B39: 08W42-SCV-302 | C39: 08W42-SCV-302 | D39: Wheel Locks - Chrome | E39: Écrous de roue antivols - Chromés | F39: A great way to help ensure that your wheels stay on your vehicle where they belong. Chrome-plated triple-nickel finish for a brilliant shine and corrosion prevention | G39: Un excellent moyen de vous assurer que les roues demeurent sur votre véhicule, où elles devraient se trouver. La finition chromée triple nickel procure un éclat brillant et une prévention contre la corrosion. | H39: 0.2 | J39: =VLOOKUP(B39,'[1]MASTER PART LIST'!$B:$C,2,FALSE) -> 54 | K39: =VLOOKUP(B39,'[1]MASTER PART LIST'!$B:$D,3,FALSE) -> 90 | L39: =K39+(H39*VLOOKUP(prov_cd,rate_table,2,FALSE)) -> 126.2 | P39: • | Q39: • | S39: • | T39: N/A | W39: Yes | AF39: 20 | AK39: • | AS39: 08W42-S2A-101 Wheel Locks - Black
B40: 08W42-TGG-100 | C40: 08W42-TGG-101 | D40: Wheel Lug Nuts - Black | E40: Écrous de roue - Noir | F40: Create a different look with a set of black lug nuts. Each package has a quantity of 4 lugs. | G40: Créez un aspect différent grâce à cet ensemble d’écrous de roue noirs qui complète les roues en alliage du véhicule. Chaque paquet contient 4 écrous de roue. | H40: 0.2 | J40: =VLOOKUP(B40,'[1]MASTER PART LIST'!$B:$C,2,FALSE) -> 57 | K40: =VLOOKUP(B40,'[1]MASTER PART LIST'!$B:$D,3,FALSE) -> 91 | L40: =K40+(H40*VLOOKUP(prov_cd,rate_table,2,FALSE)) -> 127.2 | P40: • | Q40: • | S40: • | T40: N/A | U40: Includes: 1 set (i.e. 4 lug nuts). A complete install requires 5 sets (i.e. 20 lug nuts) for 4 wheels. | V40: Inclut 4 écrous de roue en 1 jeu. L'installation complète nécessite 5 jeux pour 4 roues (20 écrous de roue). | W40: Yes | AF40: 21 | AO40: •
B41: 08P20-T20-100A | C41: 08P20-T20-100A | D41: Door Edge Film | E41: Pellicule pour rebord de portière | F41: Help protect against unsightly nicks and scrapes around your door edges. | G41: La pellicule aide à protéger les surfaces des rebords de portières contre des égratignures et éraflures inesthétiques. | H41: 0.5 | J41: =VLOOKUP(B41,'[1]MASTER PART LIST'!$B:$C,2,FALSE) -> 67 | K41: =VLOOKUP(B41,'[1]MASTER PART LIST'!$B:$D,3,FALSE) -> 112 | L41: =K41+(H41*VLOOKUP(prov_cd,rate_table,2,FALSE)) -> 202.5 | P41: • | Q41: • | S41: • | T41: N/A | U41: Cannot be installed with Door Edge Guards | V41: Ne peut être installé simultanément avec protecteurs de bordure de porte. | W41: Yes | AF41: 48 | AK41: • | AS41: 25CIV5-PRO-FLM Protection Package - Film 08P20-T20-130 Door Edge Guards
...

Sheet SELECT PROVINCE
A1: Select Province: Choissisez votre province: | B1: YT
B4: Current Labor Rates
B5: Taux de main d'oeuvre en cours
B6: AB | C6: 171
B7: BC | C7: 181
B8: MB | C8: 164
B9: NB | C9: 142
B10: NL | C10: 142
B11: NS | C11: 142
B12: ON | C12: 160 | F12: =prov_cd -> YT
B13: PEI | C13: 134
B14: QC | C14: 152
B15: SK | C15: 164
B16: YT | C16: 181
B18: Publication Date / Date de publication: | C18: ='26MY_CIV5D_DATA'!$C$4 -> 46142
A23: All published prices, trim specifications, and availability are subject to change without prior notice.
A24: Tout prix, spécifications de versions et disponibilté d'accessoires publiés sont sujets à changer sans pré-avis.

Sheet 26MY_CIV5D_APP_EN
B2: Honda Internal | C2: Honda Accessories
C3: Model Name | D3: ='26MY_CIV5D_DATA'!C2 -> Civic Hatch & Type R
C4: Model Year | D4: ='26MY_CIV5D_DATA'!$C$3 -> 2026
C5: S = Standard (accessory comes standard on this trim)
C6: T = Tire Size Change (the size of the accessory wheel is smaller/larger than the OE Wheel. Customer will require new tires to fit these wheels.)
C7: E = Exchange Standard Equipment (the size of the accessory wheel is the same size as the OE wheel and therefore they can use the OE tire.)
C8: N/A = Not Applicable (accessory cannot be applied to this trim)
H10: Province
C11: 1.0 Packages and Kits | H11: =prov_cd -> YT
C12: Description | D12: Part Number | E12: Dealer Net | F12: List Price | G12: FRT | H12: Installed Price | I12: Application | Q12: Comments
I13: ='26MY_CIV5D_DATA'!M$7 -> 0 | J13: ='26MY_CIV5D_DATA'!N$7 -> 0 | K13: ='26MY_CIV5D_DATA'!O$7 -> 0 | L13: ='26MY_CIV5D_DATA'!P$7 -> SPORT | M13: ='26MY_CIV5D_DATA'!Q$7 -> SPORT Hybrid | N13: ='26MY_CIV5D_DATA'!R$7 -> 0 | O13: ='26MY_CIV5D_DATA'!S$7 -> Sport Touring Hybrid | P13: ='26MY_CIV5D_DATA'!T$7 -> Type R
B14: 26TYPER-RACE | C14: =VLOOKUP(B14,'26MY_CIV5D_DATA'!B:AS,3,FALSE) -> Racing Package - Type R | D14: =B14 -> 26TYPER-RACE | E14: =VLOOKUP(B14,'26MY_CIV5D_DATA'!B:AS,9,FALSE) -> 3928 | F14: =VLOOKUP(B14,'26MY_CIV5D_DATA'!B:AS,10,FALSE) -> 6431 | G14: =VLOOKUP(B14,'26MY_CIV5D_DATA'!B:AS,7,FALSE) -> 1 | H14: =VLOOKUP(B14,'26MY_CIV5D_DATA'!B:AS,11,FALSE) -> 6612 | I14: =VLOOKUP(B14,'26MY_CIV5D_DATA'!B:AS,12,FALSE) -> 0 | J14: =VLOOKUP(B14,'26MY_CIV5D_DATA'!B:AS,13,FALSE) -> 0 | K14: =VLOOKUP($B14,'26MY_CIV5D_DATA'!$B:$AS,14,FALSE) -> 0 | L14: =VLOOKUP(B14,'26MY_CIV5D_DATA'!B:AS,15,FALSE) -> N/A | M14: =VLOOKUP(B14,'26MY_CIV5D_DATA'!B:AS,16,FALSE) -> N/A | N14: =VLOOKUP($B14,'26MY_CIV5D_DATA'!$B:$AS,17,FALSE) -> 0 | O14: =VLOOKUP(B14,'26MY_CIV5D_DATA'!B:AS,18,FALSE) -> N/A | P14: =VLOOKUP(B14,'26MY_CIV5D_DATA'!B:AS,19,FALSE) -> • | Q14: =IF(VLOOKUP(B14,'26MY_CIV5D_DATA'!B:AS,20,FALSE)="","",VLOOKUP(B14,'26MY_CIV5D_DATA'!B:AS,20,FALSE))
B15: 08F02-T60-100 | C15: =VLOOKUP(B15,'26MY_CIV5D_DATA'!B:AS,3,FALSE) -> Carbon Fiber Wing Spoiler - Type R | D15: =B15 -> 08F02-T60-100
B16: 08U97-T60-110 | C16: =VLOOKUP(B16,'26MY_CIV5D_DATA'!B:AS,3,FALSE) -> Steering Wheel, Alcantara - Type R | D16: =B16 -> 08U97-T60-110
B17: 08U92-T60-110 | C17: =VLOOKUP(B17,'26MY_CIV5D_DATA'!B:AS,3,FALSE) -> Shift Knob - Type R | D17: =B17 -> 08U92-T60-110
B19: 25CIV-ENK-WTPK | C19: =VLOOKUP(B19,'26MY_CIV5D_DATA'!B:AS,3,FALSE) -> 16” Enkei M52 Wheels & Michelin X-ICE Snow Tire Package | E19: =VLOOKUP(B19,'26MY_CIV5D_DATA'!B:AS,9,FALSE) -> 1596.56 | F19: =VLOOKUP(B19,'26MY_CIV5D_DATA'!B:AS,10,FALSE) -> 2028 | G19: =VLOOKUP(B19,'26MY_CIV5D_DATA'!B:AS,7,FALSE) -> 1.2 | H19: =VLOOKUP(B19,'26MY_CIV5D_DATA'!B:AS,11,FALSE) -> 2245.2 | I19: =VLOOKUP(B19,'26MY_CIV5D_DATA'!B:AS,12,FALSE) -> 0 | J19: =VLOOKUP(B19,'26MY_CIV5D_DATA'!B:AS,13,FALSE) -> 0 | K19: =VLOOKUP($B19,'26MY_CIV5D_DATA'!$B:$AS,14,FALSE) -> 0 | L19: =VLOOKUP(B19,'26MY_CIV5D_DATA'!B:AS,15,FALSE) -> • | M19: =VLOOKUP(B19,'26MY_CIV5D_DATA'!B:AS,16,FALSE) -> N/A | N19: =VLOOKUP($B19,'26MY_CIV5D_DATA'!$B:$AS,17,FALSE) -> 0 | O19: =VLOOKUP(B19,'26MY_CIV5D_DATA'!B:AS,18,FALSE) -> N/A | P19: =VLOOKUP(B19,'26MY_CIV5D_DATA'!B:AS,19,FALSE) -> N/A | Q19: =IF(VLOOKUP(B19,'26MY_CIV5D_DATA'!B:AS,20,FALSE)="","",VLOOKUP(B19,'26MY_CIV5D_DATA'!B:AS,20,FALSE)) -> Priced as a set of 4 wheels.
B20: 480-670-6545-SP or 480-670-6545-GB | C20: =VLOOKUP(B20,'26MY_CIV5D_DATA'!B:AS,3,FALSE) -> 16" Enkei M52 Wheels - Silver or Gloss Black | D20: =B20 -> 480-670-6545-SP or 480-670-6545-GB
B21: 34417 | C21: =VLOOKUP(B21,'26MY_CIV5D_DATA'!B:AS,3,FALSE) -> Michelin X-ICE Snow Tires - 215/55/16 | D21: =B21 -> 34417
B23: 25CIV-STL-WTPK | C23: =VLOOKUP(B23,'26MY_CIV5D_DATA'!B:AS,3,FALSE) -> 16” Winter Steel Wheels & Michelin X-ICE Snow Tire Package | E23: =VLOOKUP(B23,'26MY_CIV5D_DATA'!B:AS,9,FALSE) -> 1150.4 | F23: =VLOOKUP(B23,'26MY_CIV5D_DATA'!B:AS,10,FALSE) -> 1522.72 | G23: =VLOOKUP(B23,'26MY_CIV5D_DATA'!B:AS,7,FALSE) -> 1.2 | H23: =VLOOKUP(B23,'26MY_CIV5D_DATA'!B:AS,11,FALSE) -> 1739.92 | I23: =VLOOKUP(B23,'26MY_CIV5D_DATA'!B:AS,12,FALSE) -> 0 | J23: =VLOOKUP(B23,'26MY_CIV5D_DATA'!B:AS,13,FALSE) -> 0 | K23: =VLOOKUP($B23,'26MY_CIV5D_DATA'!$B:$AS,14,FALSE) -> 0 | L23: =VLOOKUP(B23,'26MY_CIV5D_DATA'!B:AS,15,FALSE) -> • | M23: =VLOOKUP(B23,'26MY_CIV5D_DATA'!B:AS,16,FALSE) -> N/A | N23: =VLOOKUP($B23,'26MY_CIV5D_DATA'!$B:$AS,17,FALSE) -> 0 | O23: =VLOOKUP(B23,'26MY_CIV5D_DATA'!B:AS,18,FALSE) -> N/A | P23: =VLOOKUP(B23,'26MY_CIV5D_DATA'!B:AS,19,FALSE) -> N/A | Q23: =IF(VLOOKUP(B23,'26MY_CIV5D_DATA'!B:AS,20,FALSE)="","",VLOOKUP(B23,'26MY_CIV5D_DATA'!B:AS,20,FALSE)) -> Priced as a set of 4 wheels.
B24: 42700-TBA-A12 | C24: =VLOOKUP(B24,'26MY_CIV5D_DATA'!B:AS,3,FALSE) -> 16” Winter Steel Wheels | D24: =B24 -> 42700-TBA-A12
B25: 34417 | C25: =VLOOKUP(B25,'26MY_CIV5D_DATA'!B:AS,3,FALSE) -> Michelin X-ICE Snow Tires - 215/55/16 | D25: =B25 -> 34417
B27: 25CIV5-ARO-PK | C27: =VLOOKUP(B27,'26MY_CIV5D_DATA'!B:AS,3,FALSE) -> Aero Kit | E27: =VLOOKUP(B27,'26MY_CIV5D_DATA'!B:AS,9,FALSE) -> 660.6 | F27: =VLOOKUP(B27,'26MY_CIV5D_DATA'!B:AS,10,FALSE) -> 1101.6 | G27: =VLOOKUP(B27,'26MY_CIV5D_DATA'!B:AS,7,FALSE) -> 2.2 | H27: =VLOOKUP(B27,'26MY_CIV5D_DATA'!B:AS,11,FALSE) -> 1499.8 | I27: =VLOOKUP(B27,'26MY_CIV5D_DATA'!B:AS,12,FALSE) -> 0 | J27: =VLOOKUP(B27,'26MY_CIV5D_DATA'!B:AS,13,FALSE) -> 0 | K27: =VLOOKUP($B27,'26MY_CIV5D_DATA'!$B:$AS,14,FALSE) -> 0 | L27: =VLOOKUP(B27,'26MY_CIV5D_DATA'!B:AS,15,FALSE) -> • | M27: =VLOOKUP(B27,'26MY_CIV5D_DATA'!B:AS,16,FALSE) -> • | N27: =VLOOKUP($B27,'26MY_CIV5D_DATA'!$B:$AS,17,FALSE) -> 0 | O27: =VLOOKUP(B27,'26MY_CIV5D_DATA'!B:AS,18,FALSE) -> • | P27: =VLOOKUP(B27,'26MY_CIV5D_DATA'!B:AS,19,FALSE) -> N/A | Q27: =IF(VLOOKUP(B27,'26MY_CIV5D_DATA'!B:AS,20,FALSE)="","",VLOOKUP(B27,'26MY_CIV5D_DATA'!B:AS,20,FALSE)) -> 10% Discount Applied. Includes body coloured front underbody spoiler and tailgate spoiler.
B28: 25CIV-5AR-NH883 | C28: =VLOOKUP(B28,'26MY_CIV5D_DATA'!B:AS,3,FALSE) -> Platinum White Pearl (NH-883P) | D28: =B28 -> 25CIV-5AR-NH883
B29: 25CIV-5AR-NH932 | C29: =VLOOKUP(B29,'26MY_CIV5D_DATA'!B:AS,3,FALSE) -> Solar Reflection Silver (NH-932M) | D29: =B29 -> 25CIV-5AR-NH932
B30: 25CIV-5AR-NH904 | C30: =VLOOKUP(B30,'26MY_CIV5D_DATA'!B:AS,3,FALSE) -> Meteoroid Gray Pearl (NH-904M) | D30: =B30 -> 25CIV-5AR-NH904
B31: 25CIV-5AR-NH912 | C31: =VLOOKUP(B31,'26MY_CIV5D_DATA'!B:AS,3,FALSE) -> Urban Grey Pearl (NH-912P) | D31: =B31 -> 25CIV-5AR-NH912
B32: 25CIV-5AR-NH731 | C32: =VLOOKUP(B32,'26MY_CIV5D_DATA'!B:AS,3,FALSE) -> Crystal Black Pearl (NH-731P) | D32: =B32 -> 25CIV-5AR-NH731
B33: 25CIV-5AR-R513 | C33: =VLOOKUP(B33,'26MY_CIV5D_DATA'!B:AS,3,FALSE) -> Rallye Red (R-513) | D33: =B33 -> 25CIV-5AR-R513
B34: 25CIV-5AR-B637 | C34: =VLOOKUP(B34,'26MY_CIV5D_DATA'!B:AS,3,FALSE) -> Boost Blue Pearl (B-637P) | D34: =B34 -> 25CIV-5AR-B637
B36: 22CIV-COLD-PK20 | C36: =VLOOKUP(B36,'26MY_CIV5D_DATA'!B:AS,3,FALSE) -> Cold Weather Package - 2.0L | D36: =B36 -> 22CIV-COLD-PK20 | E36: =VLOOKUP(B36,'26MY_CIV5D_DATA'!B:AS,9,FALSE) -> 230.85 | F36: =VLOOKUP(B36,'26MY_CIV5D_DATA'!B:AS,10,FALSE) -> 384.75 | G36: =VLOOKUP(B36,'26MY_CIV5D_DATA'!B:AS,7,FALSE) -> 1.4 | H36: =VLOOKUP(B36,'26MY_CIV5D_DATA'!B:AS,11,FALSE) -> 638.15 | I36: =VLOOKUP(B36,'26MY_CIV5D_DATA'!B:AS,12,FALSE) -> 0 | J36: =VLOOKUP(B36,'26MY_CIV5D_DATA'!B:AS,13,FALSE) -> 0 | K36: =VLOOKUP($B36,'26MY_CIV5D_DATA'!$B:$AS,14,FALSE) -> 0 | L36: =VLOOKUP(B36,'26MY_CIV5D_DATA'!B:AS,15,FALSE) -> • | M36: =VLOOKUP(B36,'26MY_CIV5D_DATA'!B:AS,16,FALSE) -> • | N36: =VLOOKUP($B36,'26MY_CIV5D_DATA'!$B:$AS,17,FALSE) -> 0 | O36: =VLOOKUP(B36,'26MY_CIV5D_DATA'!B:AS,18,FALSE) -> • | P36: =VLOOKUP(B36,'26MY_CIV5D_DATA'!B:AS,19,FALSE) -> N/A | Q36: =IF(VLOOKUP(B36,'26MY_CIV5D_DATA'!B:AS,20,FALSE)="","",VLOOKUP(B36,'26MY_CIV5D_DATA'!B:AS,20,FALSE)) -> 5% Discount Applied.
B37: 08T44-SNA-302 | C37: =VLOOKUP(B37,'26MY_CIV5D_DATA'!B:AS,3,FALSE) -> Engine Block Heater - 2.0L | D37: =B37 -> 08T44-SNA-302
B38: 31670-BMS-004H | C38: =VLOOKUP(B38,'26MY_CIV5D_DATA'!B:AS,3,FALSE) -> Optimate 12V Auto Battery Charger/Maintainer | D38: =B38 -> 31670-BMS-004H
B40: 23CIV-COLD-TR | C40: =VLOOKUP(B40,'26MY_CIV5D_DATA'!B:AS,3,FALSE) -> Cold Weather Package - Type R | D40: =B40 -> 23CIV-COLD-TR | E40: =VLOOKUP(B40,'26MY_CIV5D_DATA'!B:AS,9,FALSE) -> 278.35 | F40: =VLOOKUP(B40,'26MY_CIV5D_DATA'!B:AS,10,FALSE) -> 464.55 | G40: =VLOOKUP(B40,'26MY_CIV5D_DATA'!B:AS,7,FALSE) -> 1.4 | H40: =VLOOKUP(B40,'26MY_CIV5D_DATA'!B:AS,11,FALSE) -> 717.95 | I40: =VLOOKUP(B40,'26MY_CIV5D_DATA'!B:AS,12,FALSE) -> 0 | J40: =VLOOKUP(B40,'26MY_CIV5D_DATA'!B:AS,13,FALSE) -> 0 | K40: =VLOOKUP($B40,'26MY_CIV5D_DATA'!$B:$AS,14,FALSE) -> 0 | L40: =VLOOKUP(B40,'26MY_CIV5D_DATA'!B:AS,15,FALSE) -> N/A | M40: =VLOOKUP(B40,'26MY_CIV5D_DATA'!B:AS,16,FALSE) -> N/A | N40: =VLOOKUP($B40,'26MY_CIV5D_DATA'!$B:$AS,17,FALSE) -> 0 | O40: =VLOOKUP(B40,'26MY_CIV5D_DATA'!B:AS,18,FALSE) -> N/A | P40: =VLOOKUP(B40,'26MY_CIV5D_DATA'!B:AS,19,FALSE) -> • | Q40: =IF(VLOOKUP(B40,'26MY_CIV5D_DATA'!B:AS,20,FALSE)="","",VLOOKUP(B40,'26MY_CIV5D_DATA'!B:AS,20,FALSE)) -> 5% Discount Applied.
B41: 08T44-TGH-300 | C41: =VLOOKUP(B41,'26MY_CIV5D_DATA'!B:AS,3,FALSE) -> Engine Block Heater - Type R | D41: =B41 -> 08T44-TGH-300
B42: 31670-BMS-004H | C42: =VLOOKUP(B42,'26MY_CIV5D_DATA'!B:AS,3,FALSE) -> Optimate 12V Auto Battery Charger/Maintainer | D42: =B42 -> 31670-BMS-004H
B44: 25CIV5D-PRO-PET | C44: =VLOOKUP(B44,'26MY_CIV5D_DATA'!B:AS,3,FALSE) -> Protection Package - Petrol | D44: =B44 -> 25CIV5D-PRO-PET | E44: =VLOOKUP(B44,'26MY_CIV5D_DATA'!B:AS,9,FALSE) -> 297 | F44: =VLOOKUP(B44,'26MY_CIV5D_DATA'!B:AS,10,FALSE) -> 550 | G44: =VLOOKUP(B44,'26MY_CIV5D_DATA'!B:AS,7,FALSE) -> 0.6 | H44: =VLOOKUP(B44,'26MY_CIV5D_DATA'!B:AS,11,FALSE) -> 658.6 | I44: =VLOOKUP(B44,'26MY_CIV5D_DATA'!B:AS,12,FALSE) -> 0 | J44: =VLOOKUP(B44,'26MY_CIV5D_DATA'!B:AS,13,FALSE) -> 0 | K44: =VLOOKUP($B44,'26MY_CIV5D_DATA'!$B:$AS,14,FALSE) -> 0 | L44: =VLOOKUP(B44,'26MY_CIV5D_DATA'!B:AS,15,FALSE) -> • | M44: =VLOOKUP(B44,'26MY_CIV5D_DATA'!B:AS,16,FALSE) -> N/A | N44: =VLOOKUP($B44,'26MY_CIV5D_DATA'!$B:$AS,17,FALSE) -> 0 | O44: =VLOOKUP(B44,'26MY_CIV5D_DATA'!B:AS,18,FALSE) -> N/A | P44: =VLOOKUP(B44,'26MY_CIV5D_DATA'!B:AS,19,FALSE) -> N/A | Q44: =IF(VLOOKUP(B44,'26MY_CIV5D_DATA'!B:AS,20,FALSE)="","",VLOOKUP(B44,'26MY_CIV5D_DATA'!B:AS,20,FALSE))
B45: 08P17-T20-110 | C45: =VLOOKUP(B45,'26MY_CIV5D_DATA'!B:AS,3,FALSE) -> Floor Mats - All-Season | D45: =B45 -> 08P17-T20-110
B46: 08U45-T47-100B | C46: =VLOOKUP(B46,'26MY_CIV5D_DATA'!B:AS,3,FALSE) -> Cargo Tray | D46: =B46 -> 08U45-T47-100B
B47: 08P09-T47-300 | C47: =VLOOKUP(B47,'26MY_CIV5D_DATA'!B:AS,3,FALSE) -> Splash Guards - Rear | D47: =B47 -> 08P09-T47-300
B49: 25CIV5-PRO-HYB | C49: =VLOOKUP(B49,'26MY_CIV5D_DATA'!B:AS,3,FALSE) -> Protection Package - Hybrid | D49: =B49 -> 25CIV5-PRO-HYB | E49: =VLOOKUP(B49,'26MY_CIV5D_DATA'!B:AS,9,FALSE) -> 297 | F49: =VLOOKUP(B49,'26MY_CIV5D_DATA'!B:AS,10,FALSE) -> 550 | G49: =VLOOKUP(B49,'26MY_CIV5D_DATA'!B:AS,7,FALSE) -> 0.6 | H49: 602 | I49: =VLOOKUP(B49,'26MY_CIV5D_DATA'!B:AS,12,FALSE) -> 0 | J49: =VLOOKUP(B49,'26MY_CIV5D_DATA'!B:AS,13,FALSE) -> 0 | K49: =VLOOKUP($B49,'26MY_CIV5D_DATA'!$B:$AS,14,FALSE) -> 0 | L49: =VLOOKUP(B49,'26MY_CIV5D_DATA'!B:AS,15,FALSE) -> N/A | M49: =VLOOKUP(B49,'26MY_CIV5D_DATA'!B:AS,16,FALSE) -> • | N49: =VLOOKUP($B49,'26MY_CIV5D_DATA'!$B:$AS,17,FALSE) -> 0 | O49: =VLOOKUP(B49,'26MY_CIV5D_DATA'!B:AS,18,FALSE) -> • | P49: =VLOOKUP(B49,'26MY_CIV5D_DATA'!B:AS,19,FALSE) -> N/A | Q49: =IF(VLOOKUP(B49,'26MY_CIV5D_DATA'!B:AS,20,FALSE)="","",VLOOKUP(B49,'26MY_CIV5D_DATA'!B:AS,20,FALSE))
...

Sheet 26MY_CIV5D_APP_FR
B2: Honda Internal | C2: Accessoires Honda
C3: Nom du modèle | D3: ='26MY_CIV5D_DATA'!$D$2 -> Civic à Hayon & Type R
C4: Année modèle | D4: ='26MY_CIV5D_DATA'!$C$3 -> 2026
C5: S = De série (accessoire de série sur cette version).
C6: T = Taille des pneus (la taille de la jante accessoire diffère de la jante d’origine. Le client aura besoin de nouveaux pneus pour ces jantes).
C7: E = Échange d’équipement de série (la taille de la jante accessoire est la même que celle de la jante d’origine. Le client peut utiliser les pneus d’origine).
C8: N/A = Sans objet (l’accessoire ne peut être utilisé pour cette version).
H10: Province
C11: 1.0 Groupes et ensembles | H11: =prov_cd -> YT
C12: La description | D12: Numéro de pièce | E12: Prix net | F12: Prix de liste | G12: T.F.F. | H12: Prix installé | I12: Application | Q12: Commentaires
I13: ='26MY_CIV5D_DATA'!M$6 -> 0 | J13: ='26MY_CIV5D_DATA'!N$6 -> 0 | K13: ='26MY_CIV5D_DATA'!O$6 -> 0 | L13: ='26MY_CIV5D_DATA'!P$6 -> SPORT | M13: ='26MY_CIV5D_DATA'!Q$6 -> SPORT Hybride | N13: ='26MY_CIV5D_DATA'!R$6 -> 0 | O13: ='26MY_CIV5D_DATA'!S$6 -> Sport Touring Hybride | P13: ='26MY_CIV5D_DATA'!T$6 -> Type R
B14: 26TYPER-RACE | C14: =VLOOKUP(B14,'26MY_CIV5D_DATA'!B:AS,4,FALSE) -> Ensemble de course – Type R | D14: =B14 -> 26TYPER-RACE | E14: =VLOOKUP(B14,'26MY_CIV5D_DATA'!B:AS,9,FALSE) -> 3928 | F14: =VLOOKUP(B14,'26MY_CIV5D_DATA'!B:AS,10,FALSE) -> 6431 | G14: =VLOOKUP(B14,'26MY_CIV5D_DATA'!B:AS,7,FALSE) -> 1 | H14: =VLOOKUP(B14,'26MY_CIV5D_DATA'!B:AS,11,FALSE) -> 6612 | I14: =VLOOKUP(B14,'26MY_CIV5D_DATA'!B:AS,12,FALSE) -> 0 | J14: =VLOOKUP(B14,'26MY_CIV5D_DATA'!B:AS,13,FALSE) -> 0 | K14: =VLOOKUP($B14,'26MY_CIV5D_DATA'!$B:$AS,14,FALSE) -> 0 | L14: =VLOOKUP(B14,'26MY_CIV5D_DATA'!B:AS,15,FALSE) -> N/A | M14: =VLOOKUP(B14,'26MY_CIV5D_DATA'!B:AS,16,FALSE) -> N/A | N14: =VLOOKUP($B14,'26MY_CIV5D_DATA'!$B:$AS,17,FALSE) -> 0 | O14: =VLOOKUP(B14,'26MY_CIV5D_DATA'!B:AS,18,FALSE) -> N/A | P14: =VLOOKUP(B14,'26MY_CIV5D_DATA'!B:AS,19,FALSE) -> • | Q14: =IF(VLOOKUP(B14,'26MY_CIV5D_DATA'!B:AS,21,FALSE)="","",VLOOKUP(B14,'26MY_CIV5D_DATA'!B:AS,21,FALSE))
B15: 08F02-T60-100 | C15: =VLOOKUP(B15,'26MY_CIV5D_DATA'!B:AS,4,FALSE) -> Becquet de hayon en fibre de carbone - Type R | D15: =B15 -> 08F02-T60-100
B16: 08U97-T60-110 | C16: =VLOOKUP(B16,'26MY_CIV5D_DATA'!B:AS,4,FALSE) -> Volant en Alcantara pour Type R | D16: =B16 -> 08U97-T60-110
B17: 08U92-T60-110 | C17: =VLOOKUP(B17,'26MY_CIV5D_DATA'!B:AS,4,FALSE) -> Pommeau de levier de vitesse gainé de cuir rouge | D17: =B17 -> 08U92-T60-110
B19: 25CIV-ENK-WTPK | C19: =VLOOKUP(B19,'26MY_CIV5D_DATA'!B:AS,4,FALSE) -> Ensemble de roues Enkei M52 de 16 po et de pneus Michelin X-ICE Snow | E19: =VLOOKUP(B19,'26MY_CIV5D_DATA'!B:AS,9,FALSE) -> 1596.56 | F19: =VLOOKUP(B19,'26MY_CIV5D_DATA'!B:AS,10,FALSE) -> 2028 | G19: =VLOOKUP(B19,'26MY_CIV5D_DATA'!B:AS,7,FALSE) -> 1.2 | H19: =VLOOKUP(B19,'26MY_CIV5D_DATA'!B:AS,11,FALSE) -> 2245.2 | I19: =VLOOKUP(B19,'26MY_CIV5D_DATA'!B:AS,12,FALSE) -> 0 | J19: =VLOOKUP(B19,'26MY_CIV5D_DATA'!B:AS,13,FALSE) -> 0 | K19: =VLOOKUP($B19,'26MY_CIV5D_DATA'!$B:$AS,14,FALSE) -> 0 | L19: =VLOOKUP(B19,'26MY_CIV5D_DATA'!B:AS,15,FALSE) -> • | M19: =VLOOKUP(B19,'26MY_CIV5D_DATA'!B:AS,16,FALSE) -> N/A | N19: =VLOOKUP($B19,'26MY_CIV5D_DATA'!$B:$AS,17,FALSE) -> 0 | O19: =VLOOKUP(B19,'26MY_CIV5D_DATA'!B:AS,18,FALSE) -> N/A | P19: =VLOOKUP(B19,'26MY_CIV5D_DATA'!B:AS,19,FALSE) -> N/A | Q19: =IF(VLOOKUP(B19,'26MY_CIV5D_DATA'!B:AS,21,FALSE)="","",VLOOKUP(B19,'26MY_CIV5D_DATA'!B:AS,21,FALSE)) -> Prix établi pour ensemble de 4 pneus.
B20: 480-670-6545-SP ou 480-670-6545-GB | C20: =VLOOKUP(B20,'26MY_CIV5D_DATA'!B:AS,4,FALSE) -> Roues Enkei M52 de 16 po - argent ou noir brillant | D20: =B20 -> 480-670-6545-SP ou 480-670-6545-GB
B21: 34417 | C21: =VLOOKUP(B21,'26MY_CIV5D_DATA'!B:AS,4,FALSE) -> Pneus Michelin X-ICE Snow - 215/55/16 | D21: =B21 -> 34417
B23: 25CIV-STL-WTPK | C23: =VLOOKUP(B23,'26MY_CIV5D_DATA'!B:AS,4,FALSE) -> Ensemble de roues d’hiver de 16 po en acier et de pneus Michelin X-ICE Snow | E23: =VLOOKUP(B23,'26MY_CIV5D_DATA'!B:AS,9,FALSE) -> 1150.4 | F23: =VLOOKUP(B23,'26MY_CIV5D_DATA'!B:AS,10,FALSE) -> 1522.72 | G23: =VLOOKUP(B23,'26MY_CIV5D_DATA'!B:AS,7,FALSE) -> 1.2 | H23: =VLOOKUP(B23,'26MY_CIV5D_DATA'!B:AS,11,FALSE) -> 1739.92 | I23: =VLOOKUP(B23,'26MY_CIV5D_DATA'!B:AS,12,FALSE) -> 0 | J23: =VLOOKUP(B23,'26MY_CIV5D_DATA'!B:AS,13,FALSE) -> 0 | K23: =VLOOKUP($B23,'26MY_CIV5D_DATA'!$B:$AS,14,FALSE) -> 0 | L23: =VLOOKUP(B23,'26MY_CIV5D_DATA'!B:AS,15,FALSE) -> • | M23: =VLOOKUP(B23,'26MY_CIV5D_DATA'!B:AS,16,FALSE) -> N/A | N23: =VLOOKUP($B23,'26MY_CIV5D_DATA'!$B:$AS,17,FALSE) -> 0 | O23: =VLOOKUP(B23,'26MY_CIV5D_DATA'!B:AS,18,FALSE) -> N/A | P23: =VLOOKUP(B23,'26MY_CIV5D_DATA'!B:AS,19,FALSE) -> N/A | Q23: =IF(VLOOKUP(B23,'26MY_CIV5D_DATA'!B:AS,21,FALSE)="","",VLOOKUP(B23,'26MY_CIV5D_DATA'!B:AS,21,FALSE)) -> Prix établi pour ensemble de 4 pneus.
B24: 42700-TBA-A12 | C24: =VLOOKUP(B24,'26MY_CIV5D_DATA'!B:AS,4,FALSE) -> Roues d’hiver de 16 po en acier | D24: =B24 -> 42700-TBA-A12
B25: 34417 | C25: =VLOOKUP(B25,'26MY_CIV5D_DATA'!B:AS,4,FALSE) -> Pneus Michelin X-ICE Snow - 215/55/16 | D25: =B25 -> 34417
B27: 25CIV5-ARO-PK | C27: =VLOOKUP(B27,'26MY_CIV5D_DATA'!B:AS,4,FALSE) -> Ensemble Aero | E27: =VLOOKUP(B27,'26MY_CIV5D_DATA'!B:AS,9,FALSE) -> 660.6 | F27: =VLOOKUP(B27,'26MY_CIV5D_DATA'!B:AS,10,FALSE) -> 1101.6 | G27: =VLOOKUP(B27,'26MY_CIV5D_DATA'!B:AS,7,FALSE) -> 2.2 | H27: =VLOOKUP(B27,'26MY_CIV5D_DATA'!B:AS,11,FALSE) -> 1499.8 | I27: =VLOOKUP(B27,'26MY_CIV5D_DATA'!B:AS,12,FALSE) -> 0 | J27: =VLOOKUP(B27,'26MY_CIV5D_DATA'!B:AS,13,FALSE) -> 0 | K27: =VLOOKUP($B27,'26MY_CIV5D_DATA'!$B:$AS,14,FALSE) -> 0 | L27: =VLOOKUP(B27,'26MY_CIV5D_DATA'!B:AS,15,FALSE) -> • | M27: =VLOOKUP(B27,'26MY_CIV5D_DATA'!B:AS,16,FALSE) -> • | N27: =VLOOKUP($B27,'26MY_CIV5D_DATA'!$B:$AS,17,FALSE) -> 0 | O27: =VLOOKUP(B27,'26MY_CIV5D_DATA'!B:AS,18,FALSE) -> • | P27: =VLOOKUP(B27,'26MY_CIV5D_DATA'!B:AS,19,FALSE) -> N/A | Q27: =IF(VLOOKUP(B27,'26MY_CIV5D_DATA'!B:AS,21,FALSE)="","",VLOOKUP(B27,'26MY_CIV5D_DATA'!B:AS,21,FALSE)) -> Rabais de 10 % appliqué. Comprend déflecteur de bas de caisse avant de la couleur de la carrosserie et un becquet de hayon.
B28: 25CIV-5AR-NH883 | C28: =VLOOKUP(B28,'26MY_CIV5D_DATA'!B:AS,4,FALSE) -> Blanc platine nacré (NH-883P) | D28: =B28 -> 25CIV-5AR-NH883
B29: 25CIV-5AR-NH932 | C29: =VLOOKUP(B29,'26MY_CIV5D_DATA'!B:AS,4,FALSE) -> Refl et solaire argent métallisé (NH-932M) | D29: =B29 -> 25CIV-5AR-NH932
B30: 25CIV-5AR-NH904 | C30: =VLOOKUP(B30,'26MY_CIV5D_DATA'!B:AS,4,FALSE) -> Gris météore nacré (NH-904M) | D30: =B30 -> 25CIV-5AR-NH904
B31: 25CIV-5AR-NH912 | C31: =VLOOKUP(B31,'26MY_CIV5D_DATA'!B:AS,4,FALSE) -> Gris urbain nacré (NH-912P) | D31: =B31 -> 25CIV-5AR-NH912
B32: 25CIV-5AR-NH731 | C32: =VLOOKUP(B32,'26MY_CIV5D_DATA'!B:AS,4,FALSE) -> Noir cristal nacré (NH-731P) | D32: =B32 -> 25CIV-5AR-NH731
B33: 25CIV-5AR-R513 | C33: =VLOOKUP(B33,'26MY_CIV5D_DATA'!B:AS,4,FALSE) -> Rouge rallye (R-513) | D33: =B33 -> 25CIV-5AR-R513
B34: 25CIV-5AR-B637 | C34: =VLOOKUP(B34,'26MY_CIV5D_DATA'!B:AS,4,FALSE) -> Bleu turbo nacré (B-637P) | D34: =B34 -> 25CIV-5AR-B637
B36: 22CIV-COLD-PK20 | C36: =VLOOKUP(B36,'26MY_CIV5D_DATA'!B:AS,4,FALSE) -> Ensemble de temps froid - 2,0 L | D36: =B36 -> 22CIV-COLD-PK20 | E36: =VLOOKUP(B36,'26MY_CIV5D_DATA'!B:AS,9,FALSE) -> 230.85 | F36: =VLOOKUP(B36,'26MY_CIV5D_DATA'!B:AS,10,FALSE) -> 384.75 | G36: =VLOOKUP(B36,'26MY_CIV5D_DATA'!B:AS,7,FALSE) -> 1.4 | H36: =VLOOKUP(B36,'26MY_CIV5D_DATA'!B:AS,11,FALSE) -> 638.15 | I36: =VLOOKUP(B36,'26MY_CIV5D_DATA'!B:AS,12,FALSE) -> 0 | J36: =VLOOKUP(B36,'26MY_CIV5D_DATA'!B:AS,13,FALSE) -> 0 | K36: =VLOOKUP($B36,'26MY_CIV5D_DATA'!$B:$AS,14,FALSE) -> 0 | L36: =VLOOKUP(B36,'26MY_CIV5D_DATA'!B:AS,15,FALSE) -> • | M36: =VLOOKUP(B36,'26MY_CIV5D_DATA'!B:AS,16,FALSE) -> • | N36: =VLOOKUP($B36,'26MY_CIV5D_DATA'!$B:$AS,17,FALSE) -> 0 | O36: =VLOOKUP(B36,'26MY_CIV5D_DATA'!B:AS,18,FALSE) -> • | P36: =VLOOKUP(B36,'26MY_CIV5D_DATA'!B:AS,19,FALSE) -> N/A | Q36: =IF(VLOOKUP(B36,'26MY_CIV5D_DATA'!B:AS,21,FALSE)="","",VLOOKUP(B36,'26MY_CIV5D_DATA'!B:AS,21,FALSE)) -> Rabais de 5 % appliqué.
B37: 08T44-SNA-302 | C37: =VLOOKUP(B37,'26MY_CIV5D_DATA'!B:AS,4,FALSE) -> Chauffe-moteur - 2,0 L | D37: =B37 -> 08T44-SNA-302
B38: 31670-BMS-004H | C38: =VLOOKUP(B38,'26MY_CIV5D_DATA'!B:AS,4,FALSE) -> Chargeur/mainteneur de batterie automobile 12 V Optimate | D38: =B38 -> 31670-BMS-004H
B40: 22CIV-COLD-PK20 | C40: =VLOOKUP(B40,'26MY_CIV5D_DATA'!B:AS,4,FALSE) -> Ensemble de temps froid - 2,0 L | D40: =B40 -> 22CIV-COLD-PK20 | E40: =VLOOKUP(B40,'26MY_CIV5D_DATA'!B:AS,9,FALSE) -> 230.85 | F40: =VLOOKUP(B40,'26MY_CIV5D_DATA'!B:AS,10,FALSE) -> 384.75 | G40: =VLOOKUP(B40,'26MY_CIV5D_DATA'!B:AS,7,FALSE) -> 1.4 | H40: =VLOOKUP(B40,'26MY_CIV5D_DATA'!B:AS,11,FALSE) -> 638.15 | I40: =VLOOKUP(B40,'26MY_CIV5D_DATA'!B:AS,12,FALSE) -> 0 | J40: =VLOOKUP(B40,'26MY_CIV5D_DATA'!B:AS,13,FALSE) -> 0 | K40: =VLOOKUP($B40,'26MY_CIV5D_DATA'!$B:$AS,14,FALSE) -> 0 | L40: =VLOOKUP(B40,'26MY_CIV5D_DATA'!B:AS,15,FALSE) -> • | M40: =VLOOKUP(B40,'26MY_CIV5D_DATA'!B:AS,16,FALSE) -> • | N40: =VLOOKUP($B40,'26MY_CIV5D_DATA'!$B:$AS,17,FALSE) -> 0 | O40: =VLOOKUP(B40,'26MY_CIV5D_DATA'!B:AS,18,FALSE) -> • | P40: =VLOOKUP(B40,'26MY_CIV5D_DATA'!B:AS,19,FALSE) -> N/A | Q40: =IF(VLOOKUP(B40,'26MY_CIV5D_DATA'!B:AS,21,FALSE)="","",VLOOKUP(B40,'26MY_CIV5D_DATA'!B:AS,21,FALSE)) -> Rabais de 5 % appliqué.
B41: 08T44-SNA-302 | C41: =VLOOKUP(B41,'26MY_CIV5D_DATA'!B:AS,4,FALSE) -> Chauffe-moteur - 2,0 L | D41: =B41 -> 08T44-SNA-302
B42: 31670-BMS-004H | C42: =VLOOKUP(B42,'26MY_CIV5D_DATA'!B:AS,4,FALSE) -> Chargeur/mainteneur de batterie automobile 12 V Optimate | D42: =B42 -> 31670-BMS-004H
B44: 23CIV-COLD-TR | C44: =VLOOKUP(B44,'26MY_CIV5D_DATA'!B:AS,4,FALSE) -> Ensemble de temps froid - Type R | D44: =B44 -> 23CIV-COLD-TR | E44: =VLOOKUP(B44,'26MY_CIV5D_DATA'!B:AS,9,FALSE) -> 278.35 | F44: =VLOOKUP(B44,'26MY_CIV5D_DATA'!B:AS,10,FALSE) -> 464.55 | G44: =VLOOKUP(B44,'26MY_CIV5D_DATA'!B:AS,7,FALSE) -> 1.4 | H44: =VLOOKUP(B44,'26MY_CIV5D_DATA'!B:AS,11,FALSE) -> 717.95 | I44: =VLOOKUP(B44,'26MY_CIV5D_DATA'!B:AS,12,FALSE) -> 0 | J44: =VLOOKUP(B44,'26MY_CIV5D_DATA'!B:AS,13,FALSE) -> 0 | K44: =VLOOKUP($B44,'26MY_CIV5D_DATA'!$B:$AS,14,FALSE) -> 0 | L44: =VLOOKUP(B44,'26MY_CIV5D_DATA'!B:AS,15,FALSE) -> N/A | M44: =VLOOKUP(B44,'26MY_CIV5D_DATA'!B:AS,16,FALSE) -> N/A | N44: =VLOOKUP($B44,'26MY_CIV5D_DATA'!$B:$AS,17,FALSE) -> 0 | O44: =VLOOKUP(B44,'26MY_CIV5D_DATA'!B:AS,18,FALSE) -> N/A | P44: =VLOOKUP(B44,'26MY_CIV5D_DATA'!B:AS,19,FALSE) -> • | Q44: =IF(VLOOKUP(B44,'26MY_CIV5D_DATA'!B:AS,21,FALSE)="","",VLOOKUP(B44,'26MY_CIV5D_DATA'!B:AS,21,FALSE)) -> Rabais de 5 % appliqué.
B45: 08T44-TGH-300 | C45: =VLOOKUP(B45,'26MY_CIV5D_DATA'!B:AS,4,FALSE) -> Chauffe-moteur - Type R | D45: =B45 -> 08T44-TGH-300
B46: 31670-BMS-004H | C46: =VLOOKUP(B46,'26MY_CIV5D_DATA'!B:AS,4,FALSE) -> Chargeur/mainteneur de batterie automobile 12 V Optimate | D46: =B46 -> 31670-BMS-004H
B48: 25CIV5D-PRO-PET | C48: =VLOOKUP(B48,'26MY_CIV5D_DATA'!B:AS,4,FALSE) -> Ensemble de protection - Petrol | D48: =B48 -> 25CIV5D-PRO-PET | E48: =VLOOKUP(B48,'26MY_CIV5D_DATA'!B:AS,9,FALSE) -> 297 | F48: =VLOOKUP(B48,'26MY_CIV5D_DATA'!B:AS,10,FALSE) -> 550 | G48: =VLOOKUP(B48,'26MY_CIV5D_DATA'!B:AS,7,FALSE) -> 0.6 | H48: =VLOOKUP(B48,'26MY_CIV5D_DATA'!B:AS,11,FALSE) -> 658.6 | I48: =VLOOKUP(B48,'26MY_CIV5D_DATA'!B:AS,12,FALSE) -> 0 | J48: =VLOOKUP(B48,'26MY_CIV5D_DATA'!B:AS,13,FALSE) -> 0 | K48: =VLOOKUP($B48,'26MY_CIV5D_DATA'!$B:$AS,14,FALSE) -> 0 | L48: =VLOOKUP(B48,'26MY_CIV5D_DATA'!B:AS,15,FALSE) -> • | M48: =VLOOKUP(B48,'26MY_CIV5D_DATA'!B:AS,16,FALSE) -> N/A | N48: =VLOOKUP($B48,'26MY_CIV5D_DATA'!$B:$AS,17,FALSE) -> 0 | O48: =VLOOKUP(B48,'26MY_CIV5D_DATA'!B:AS,18,FALSE) -> N/A | P48: =VLOOKUP(B48,'26MY_CIV5D_DATA'!B:AS,19,FALSE) -> N/A | Q48: =IF(VLOOKUP(B48,'26MY_CIV5D_DATA'!B:AS,21,FALSE)="","",VLOOKUP(B48,'26MY_CIV5D_DATA'!B:AS,21,FALSE))
B49: 08P17-T20-110 | C49: =VLOOKUP(B49,'26MY_CIV5D_DATA'!B:AS,4,FALSE) -> Tapis toutes saisons | D49: =B49 -> 08P17-T20-110
...

Sheet 26MY_CIV5D_SELL-EN
B3: 26MY Honda Civic Hatch
B4: 200
B6: POPULAR ACCESSORIES
B7: 20
B8: 150 | M8: #VALUE!
B10: 20 | C10: ='26MY_CIV5D_APP_EN'!$C$128 -> Floor Mats - All-Season | H10: ='26MY_CIV5D_APP_EN'!$C$131 -> Cargo Tray | M10: ='26MY_CIV5D_APP_EN'!$C$77 -> Black Emblem H-Mark
B11: 20 | C11: ='26MY_CIV5D_APP_EN'!$H$128 -> 266.1 | D11: =-PMT($D$29/52,5*52,C11) -> 1.2133891 | E11: /wk * | F11: =$C$29 -> (6.99%) | H11: ='26MY_CIV5D_APP_EN'!$H$131 -> 215.1 | I11: =-PMT($D$29/52,5*52,H11) -> 0.98083424 | J11: /wk * | K11: =$C$29 -> (6.99%) | M11: ='26MY_CIV5D_APP_EN'!$H$77 -> 249.7 | N11: =-PMT($D$29/52,5*52,M11) -> 1.1386067 | O11: /wk * | P11: =$C$29 -> (6.99%)
B13: 150
B15: 20 | C15: ='26MY_CIV5D_APP_EN'!$C$79 -> Door Visors - Black | H15: ='26MY_CIV5D_DATA'!$D$55 -> Body Side Moulding | M15: ='26MY_CIV5D_APP_EN'!$C$148 -> Illuminated Door Sill Trim | N15: Ambient Lighting, Blue | O15: Ambient Lighting, Blue | P15: Ambient Lighting, Blue
B16: 50 | C16: ='26MY_CIV5D_APP_FR'!$H$83 -> 435.5 | D16: =-PMT($D$29/52,5*52,C16) -> 1.9858359 | E16: /wk * | F16: =$C$29 -> (6.99%) | H16: ='26MY_CIV5D_DATA'!$L$55 -> 430.4 | I16: =-PMT($D$29/52,5*52,H16) -> 1.9625805 | J16: /wk * | K16: =$C$29 -> (6.99%) | M16: ='26MY_CIV5D_APP_EN'!$H$148 -> 626.1 | N16: =-PMT($D$29/52,5*52,M16) -> 2.8549527 | O16: /wk * | P16: =$C$29 -> (6.99%)
B18: 150
B20: 20 | C20: ='26MY_CIV5D_APP_EN'!$C$104 -> Tailgate Spoiler, HPD | H20: ='26MY_CIV5D_APP_EN'!$C$87 -> Roof Rack | M20: ='26MY_CIV5D_APP_EN'!$C$19 -> 16” Enkei M52 Wheels & Michelin X-ICE Snow Tire Package
B21: 50 | C21: ='26MY_CIV5D_APP_EN'!$H$105 -> 1004.2 | D21: =-PMT($D$29/52,5*52,C21) -> 4.5790504 | E21: /wk * | F21: =$C$29 -> (6.99%) | H21: ='26MY_CIV5D_APP_EN'!$H$87 -> 902.4 | I21: =-PMT($D$29/52,5*52,H21) -> 4.1148527 | J21: /wk * | K21: =$C$29 -> (6.99%) | M21: =SUM('26MY_CIV5D_APP_EN'!$H$19:$H$21) -> 2245.2 | N21: =-PMT($D$29/52,5*52,M21) -> 10.237885 | O21: /wk * | P21: =$C$29 -> (6.99%)
C23: Genuine Honda Accessories purchased with a new Honda vehicle include a 3 year / 60,000 km manufacturer's warranty.
C24: Vehicle accessories purchased after vehicle sale include a 1 year / 20,000km manufacturer's warranty.
B25: 20 | C25: *Prices shown include the cost of installation.
B26: 60 | C26: *For informational purposes only. Weekly amounts shown are estimated payments based on a 60 month finance contract at 6.99% APR (including the cost of installation). Applicable taxes and fees are extra. Accessories cannot be financed on their own and must be financed through Honda Canada Finance Inc., on approved credit, in conjunction with a Honda vehicle. Representative finance example: $350.00 financed at 6.99% APR equals $1.60 weekly for 60 months. 260 weekly payments required. Cost of borrowing is $64.80 for a total obligation of $414.80. Actual payment amounts will vary based on APR, finance contract term and cost of the applicable accessories. Conditions apply. See your Honda dealer for full details.
C27: *More customized weekly payment options & accessories can be seen on Honda.ca - Build & Price
B28: 20
B29: 18 | C29: (6.99%) | D29: 0.0699
B30: 7.5 | C30: 12 | D30: 8 | E30: 8 | F30: 10 | G30: 8.5 | H30: 12 | I30: 8 | J30: 8 | K30: 10 | L30: 8.5 | M30: 12 | N30: 8 | O30: 8 | P30: 10 | Q30: 7.5
B31: Publication Date: | C31: ='26MY_CIV5D_DATA'!$C$4 -> 46142 | D31: ='SELECT PROVINCE'!$A$23 -> All published prices, trim specifications, and availability are subject to change without prior notice. | P31: Province | Q31: ='SELECT PROVINCE'!$F$12 -> YT

Sheet 26MY_CIV5D_SELL-FR
B3: 26MY Honda Civic à Hayon
B4: 200
B6: ACCESSOIRES POPULAIRES
B7: 20
B8: 150 | M8: #VALUE!
B10: 20 | C10: ='26MY_CIV5D_APP_FR'!$C$131 -> Tapis toutes saisons | H10: ='26MY_CIV5D_APP_FR'!$C$134 -> Plateau de coffre | M10: ='26MY_CIV5D_APP_FR'!$C$81 -> Emblèmes « H » noirs
B11: 20 | C11: ='26MY_CIV5D_APP_FR'!$H$131 -> 266.1 | D11: =-PMT($D$29/52,5*52,C11) -> 1.2133891 | E11: /wk * | F11: =$C$29 -> (6.99%) | H11: ='26MY_CIV5D_APP_FR'!$H$134 -> 215.1 | I11: =-PMT($D$29/52,5*52,H11) -> 0.98083424 | J11: /wk * | K11: =$C$29 -> (6.99%) | M11: ='26MY_CIV5D_APP_FR'!$H$81 -> 249.7 | N11: =-PMT($D$29/52,5*52,M11) -> 1.1386067 | O11: /wk * | P11: =$C$29 -> (6.99%)
B13: 150
B15: 20 | C15: ='26MY_CIV5D_APP_FR'!$C$83 -> Déflecteurs de portières - noir | H15: ='26MY_CIV5D_DATA'!$E$55 -> Moulure latérale | M15: ='26MY_CIV5D_APP_FR'!$C$151 -> Garniture de seuil de portière illuminée | N15: Ambient Lighting, Blue | O15: Ambient Lighting, Blue | P15: Ambient Lighting, Blue
B16: 50 | C16: ='26MY_CIV5D_APP_FR'!$H$83 -> 435.5 | D16: =-PMT($D$29/52,5*52,C16) -> 1.9858359 | E16: /wk * | F16: =$C$29 -> (6.99%) | H16: ='26MY_CIV5D_DATA'!$L$55 -> 430.4 | I16: =-PMT($D$29/52,5*52,H16) -> 1.9625805 | J16: /wk * | K16: =$C$29 -> (6.99%) | M16: ='26MY_CIV5D_APP_FR'!$H$151 -> 626.1 | N16: =-PMT($D$29/52,5*52,M16) -> 2.8549527 | O16: /wk * | P16: =$C$29 -> (6.99%)
B18: 150
B20: 20 | C20: ='26MY_CIV5D_APP_FR'!$C$106 -> Déflecteur de hayon - HPD | H20: ='26MY_CIV5D_APP_FR'!$C$89 -> Porte-bagages de toit | M20: ='26MY_CIV5D_DATA'!$E$8 -> Ensemble de roues Enkei M52 de 16 po et de pneus Michelin X-ICE Snow
B21: 50 | C21: ='26MY_CIV5D_APP_FR'!$H$107 -> 1004.2 | D21: =-PMT($D$29/52,5*52,C21) -> 4.5790504 | E21: /wk * | F21: =$C$29 -> (6.99%) | H21: ='26MY_CIV5D_APP_FR'!$H$89 -> 902.4 | I21: =-PMT($D$29/52,5*52,H21) -> 4.1148527 | J21: /wk * | K21: =$C$29 -> (6.99%) | M21: =SUM('26MY_CIV5D_APP_EN'!$H$19:$H$21) -> 2245.2 | N21: =-PMT($D$29/52,5*52,M21) -> 10.237885 | O21: /wk * | P21: =$C$29 -> (6.99%)
C23: Les accessoires Honda d’origine achetés avec un véhicule Honda neuf incluent une garantie du fabricant de 3 ans ou 60 000 km.
C24: Les accessoires de véhicule achetés après la vente du véhicule incluent une garantie du fabricant de 1 an ou 20 000 km.
B25: 20 | C25: *Les prix indiqués incluent le coût d'installation.
B26: 60 | C26: *À titre d’information seulement. Les montants hebdomadaires indiqués sont des paiements estimés basés sur un contrat de financement de 60 mois à un taux annuel en pourcentage (TAP) de 6,99 % (coût d’installation compris). Taxes et frais applicables en sus. Les accessoires ne peuvent être financés seuls et doivent être financés par l’entremise de Honda Canada Finance Inc., sur approbation de crédit, conjointement avec un véhicule Honda. Exemple de financement représentatif : Un montant de 350,00 $ financé à un TAP de 6,99 % équivaut à un paiement hebdomadaire de 1,60 $ pendant 60 mois. 260 paiements hebdomadaires sont requis. Le coût d’emprunt est de 64,80 $, pour une obligation totale de 414,80 $. Le montant réel des paiements variera en fonction du TAP, de la période du contrat de financement et du coût des accessoires applicables. Certaines conditions s’appliquent. Veuillez visiter votre concessionnaire Honda pour obtenir tous les détails.
C27: *Vous pouvez voir d’autres options de paiements hebdomadaires personnalisés ainsi que des accessoires sur le site Honda.ca – Configuration et prix.
B28: 20
B29: 18 | C29: (6.99%) | D29: 0.0699
B30: 7.5 | C30: 12 | D30: 8 | E30: 8 | F30: 10 | G30: 8.5 | H30: 12 | I30: 8 | J30: 8 | K30: 10 | L30: 8.5 | M30: 12 | N30: 8 | O30: 8 | P30: 10 | Q30: 7.5
B31: Date de publication: | C31: ='26MY_CIV5D_DATA'!$C$4 -> 46142 | D31: Tout prix, spécifications de versions et disponibilté d'accessoires publiés sont sujets à changer sans pré-avis. | P31: Province | Q31: ='26MY_CIV5D_APP_FR'!$H$11 -> YT
