Workbook
Name prov_cd: 'SELECT PROVINCE'!$B$1
Name province_codes: 'SELECT PROVINCE'!$B$6:$B$16
Name rate_table: 'SELECT PROVINCE'!$B$6:$C$16

Sheet 26MY_ACCORD_DATA
B1: 1 | C1: 2 | D1: 3 | E1: 4 | F1: 5 | G1: 6 | H1: 23 | I1: 24 | J1: 25 | K1: 26 | L1: 27 | M1: 28 | O1: 29 | P1: 30 | Q1: 31 | R1: 32 | T1: 33 | U1: 34 | V1: 35 | W1: 9 | X1: 7 | Y1: 8 | Z1: 8 | AA1: 8 | AB1: 8 | AC1: 8 | AD1: 8 | AE1: 8 | AF1: 8 | AG1: 10 | AH1: 11 | AI1: 12 | AJ1: 13 | AK1: 14 | AL1: 15 | AM1: 16 | AN1: 17 | AO1: 18 | AP1: 19 | AQ1: 20 | AR1: 21 | AS1: 22
B2: Model Name | C2: Accord | M2: = | P2: N/A | Q2: S | R2: E | T2: T | X2: Yes
B3: Model Year | C3: 2026
B4: Publication Date | C4: 46113 | D4: yyyy/mm/dd | M4: * if it's "N/A" or "S" do not show on trim
M5: Trim Application*
B6: PARTS | C6: HAC | L6: =prov_cd -> QC | O6: SE | Q6: Sport -L Hybride | R6: Touring Hybride | X6: Images | AG6: Wheels | AH6: Charging | AI6: Featured | AJ6: Included | AK6: Accessories
B7: Part Number / Kit Part Number | C7: Part Number | D7: Item Name English | E7: Item Name French | F7: Description English | G7: Description French | H7: FRT | I7: Residual-ized $ | J7: Dealer Net | K7: List Price | L7: Install Price | O7: SE | Q7: Sport -L Hybrid | R7: Touring Hybrid | U7: Comments English | V7: Comments French | W7: Display Order | X7: SiteCore | Y7: Overlay 1 | Z7: Overlay 2 | AA7: Overlay 3 | AB7: Overlay 4 | AC7: Overlay 5 | AD7: Overlay 6 | AE7: Overlay 7 | AF7: Overlay 8 | AK7: Safety & Exterior Protection | AL7: Winter Season | AM7: Exterior & Interior Utility | AN7: Interior Styling | AO7: Exterior Styling | AP7: Misc-ellaneous | AR7: Dependancies | AS7: Exclusions
B8: 23ACC-PRO-PK | C8: =B8 -> 23ACC-PRO-PK | D8: Protection Package | E8: Ensemble de protection | F8: Package includes: All-Season Floor Mats and Trunk Tray. | G8: L’ensemble inclut : Tapis toutes saisons et plateau de coffre. | H8: =H69+H70 -> 0.2 | J8: =(J69+J70)*0.9 -> 273.6 | K8: =K69+K70 -> 507 | L8: =K8+(H8*VLOOKUP(prov_cd,rate_table,2,FALSE)) -> 537.4 | O8: • | Q8: • | R8: • | W8: 1 | X8: Yes | AI8: • | AM8: • | AS8: 23ACC-PRO-PKA Protection Package Advance 08P17-30A-110 All Season Floor Mats 08U45-30A-100 Trunk Tray
B9: 23ACC-PRO-PKA | C9: =B9 -> 23ACC-PRO-PKA | D9: Protection Package Advance | E9: Ensemble de protection avancée | F9: Keep your car protected from the elements, inside and out. Includes All Season Floor Mats, Trunk Tray, Rear Splash Guards and Cargo Net. Packaged together with a 10% discount. | G9: Protégez votre voiture contre les intempéries, à l’intérieur comme à l’extérieur. Comprend les tapis toutes saisons, le plateau de coffre, les garde-boue arrière et le filet de cargaison. Offerts en ensemble avec une réduction de 10 %. | H9: =H69+H70+H40+H72 -> 1 | J9: =(J69+J70+J40+J72)*0.9 -> 342.891 | K9: =(K69+K70+K40+K72)*0.9 -> 583.2 | L9: =K9+(H9*VLOOKUP(prov_cd,rate_table,2,FALSE)) -> 735.2 | O9: • | Q9: • | R9: N/A | U9: 10% Discount Applied. | V9: Rabais de 10 % appliqué. | W9: 2 | X9: Yes | AI9: • | AM9: • | AS9: 23ACC-PRO-PK Protection Package 08P17-30A-110 All Season Floor Mats 08U45-30A-100 Trunk Tray 08L96-TVA-300 Cargo Net 08P09-30A-300 Rear Splash Gaurds
A10: NEW | B10: 26ACC-BLK-EMB | C10: =B10 -> 26ACC-BLK-EMB | D10: Black Emblem Set - Touring | E10: Ensemble d’emblèmes noirs – Touring | F10: Includes Rear "H" mark, "Accord," "Hybrid" and "Touring" black emblems. Packaged together with a 5% discount. | G10: Comprend les emblèmes noirs « H » arrière, « Accord » , « Hybride » et « Touring ». Offerts en ensemble avec une réduction de 5%. | H10: =SUM(H24:H27) -> 0.9 | J10: =(J24+J25+J26+J27)*0.95 -> 155.8 | K10: =(K24+K25+K26+K27)*0.95 -> 260.3 | L10: =K10+(H10*VLOOKUP(prov_cd,rate_table,2,FALSE)) -> 397.1 | O10: N/A | Q10: N/A | R10: • | U10: 5% Discount Applied. | V10: Rabais de 5 % appliqué. | W10: 3 | X10: Yes | AI10: • | AO10: • | AS10: 08F20-30A-100CBlack Emblem Rear "H" mark 08F20-30A-100DBlack Emblem, Accord 08F20-3A0-100CBlack Emblem, Touring 08F20-T20-100B Black Emblem, Hybrid
B11: 23ACC-ARO-EX | C11: =B11 -> 23ACC-ARO-EX | D11: Aero Kit - SE Trim | E11: Ensemble Aero – Version SE | F11: The Areo Kit adds a sporty and custom look to your Accord. Includes: Side Underbody Spoiler, Front & Rear Aero Bumpers, Door Mirror Cover, Lower Intake Accents and Black Decklid Spoiler. Packaged togther with a 10% discount. Requires the Front Splash Guards to be removed. | G11: L’ensemble Aero confère une allure sport et personnalisée à votre Accord. Inclus : Déflecteur latéral de bas de caisse, déflecteurs Aero de pare-chocs avant et arrière, couvercle de rétroviseur de portière, éléments visuels d’admission d’air et déflecteur de coffre noir. Offerts en ensemble avec une réduction de 10 %. Nécessite le retrait des garde-boue avant. | H11: =H31+H32+H33+H63+H34 -> 3.5 | J11: =(J31+J32+J33+J63+J34)*0.9 -> 1555.2 | K11: =(K31+K32+K33+K63+K34)*0.9 -> 2591.1 | L11: =K11+(H11*VLOOKUP(prov_cd,rate_table,2,FALSE)) -> 3123.1 | O11: • | Q11: N/A | R11: N/A | U11: 10% Discount Applied Decklid Spoiler - Crystal Black Pearl (NH-731P) colour | V11: Rabais de 10 % est appliqué Déflecteur arrière de coffre - Noir cristal nacré couleur (NH-731P) | W11: 4 | X11: Yes | AI11: • | AO11: • | AS11: 08F04-30A-1F0 Side Underbody Spoiler 08P98-30A-1F0 Front Aero Bumper 08P99-30A-1F0 Rear Aero Bumper 08R06-30A-110 Door Mirror Covers & Lower Intake Accents 08F10-30A-110 Decklid Spoiler
B12: 23ACC-ARO-SPHY | C12: =B12 -> 23ACC-ARO-SPHY | D12: Aero Kit - Sport Trim | E12: Ensemble Aero – Version Sport | F12: The Areo Kit adds a sporty and custom look to your Accord. Includes: Side Underbody Spoiler, Front & Rear Aero Bumpers, Door Mirror Cover and Lower Intake Accents. Packaged togther with a 10% discount. Requires the Front Splash Guards to be removed. | G12: L’ensemble Aero confère une allure sport et personnalisée à votre Accord. Inclus : Déflecteur latéral de bas de caisse, déflecteurs Aero de pare-chocs avant et arrière, couvercle de rétroviseur de portière et éléments visuels d’admission d’air. Offerts en ensemble avec une réduction de 10 %. Nécessite le retrait des garde-boue avant. | H12: =H31+H32+H33 -> 1.8 | J12: =(J31+J32+J33)*0.9 -> 1018.8 | K12: =(K31+K32+K33)*0.9 -> 1697.4 | L12: =K12+(H12*VLOOKUP(prov_cd,rate_table,2,FALSE)) -> 1971 | O12: N/A | Q12: • | R12: N/A | U12: 10% Discount Applied Sport Trim already comes standard with Decklid Spoiler | V12: Rabais de 10 % est appliqué Version Sport Hybride est livrée de série avec le becquet de bas de caisse, arrière | W12: 5 | X12: Yes | AI12: • | AO12: • | AS12: 08F04-30A-1F0 Side Underbody Spoiler 08P98-30A-1F0 Front Aero Bumper 08P99-30A-1F0 Rear Aero Bumper 08R06-30A-110 Door Mirror Covers & Lower Intake Accents
B13: 23ACC-ARO-TRHY | C13: =B13 -> 23ACC-ARO-TRHY | D13: Aero Kit - Touring Trim | E13: Ensemble Aero – Version Touring | F13: The Areo Kit adds a sporty and custom look to your Accord. Includes: Side Underbody Spoiler, Front & Rear Aero Bumpers, Door Mirror Cover, Lower Intake Accents and Black Decklid Spoiler. Packaged togther with a 10% discount. Requires the Front Splash Guards to be removed. | G13: L’ensemble Aero confère une allure sport et personnalisée à votre Accord. Inclus : Déflecteur latéral de bas de caisse, déflecteurs Aero de pare-chocs avant et arrière, couvercle de rétroviseur de portière, éléments visuels d’admission d’air et déflecteur de coffre noir. Offerts en ensemble avec une réduction de 10 %. Nécessite le retrait des garde-boue avant. | H13: =H31+H32+H33+H63+H35 -> 3.5 | J13: =(J31+J32+J33+J63+J35)*0.9 -> 1555.2 | K13: =(K31+K32+K33+K63+K35)*0.9 -> 2591.1 | L13: =K13+(H13*VLOOKUP(prov_cd,rate_table,2,FALSE)) -> 3123.1 | O13: N/A | Q13: N/A | R13: • | U13: 10% Discount Applied Decklid Spoiler - Crystal Black Pearl (NH-731P) colour | V13: Rabais de 10 % est appliqué Déflecteur arrière de coffre - Noir cristal nacré couleur (NH-731P) | W13: 6 | X13: Yes | AI13: • | AO13: • | AS13: 08F04-30A-1F0 Side Underbody Spoiler 08P98-30A-1F0 Front Aero Bumper 08P99-30A-1F0 Rear Aero Bumper 08R06-30A-110A Door Mirror Covers & Lower Intake Accents 08F10-30A-110 Decklid Spoiler
B14: 23ACC-COLD-PKP | C14: =B14 -> 23ACC-COLD-PKP | D14: Cold Weather Package | E14: Ensemble de temps froid | F14: Package includes: Engine Block Heater and Auto Battery Charger/Maintainer. Packaged together with a 5% discount. | G14: L’ensemble inclut : Chauffe-moteur et chargeur/mainteneur automatique de batterie de 12 V Optimate. Offerts en ensemble avec une remise de 5 %. | H14: =H82+H83 -> 1.2 | J14: =(J81+J83)*0.95 -> 226.1 | K14: =(K81+K83)*0.95 -> 377.15 | L14: =K14+(H14*VLOOKUP(prov_cd,rate_table,2,FALSE)) -> 559.55 | O14: • | Q14: N/A | R14: N/A | U14: 5% Discount Applied. | V14: Rabais de 5 % appliqué. | W14: 7 | X14: Yes | AI14: • | AL14: • | AS14: 08T44-30B-300A Engine Block Heater 31670-BMS-004H Optimate 12V Auto Battery Charger/Maintainer
B15: 23ACC-COLD-PKH | C15: =B15 -> 23ACC-COLD-PKH | D15: Cold Weather Package | E15: Ensemble de temps froid | F15: Package includes: Engine Block Heater and Auto Battery Charger/Maintainer. Packaged together with a 5% discount. | G15: L’ensemble inclut : Chauffe-moteur et chargeur/mainteneur automatique de batterie de 12 V Optimate. Offerts en ensemble avec une remise de 5 %. | H15: =H81+H83 -> 1.2 | J15: =(J82+J83)*0.95 -> 251.75 | K15: =(K82+K83)*0.95 -> 419.9 | L15: =K15+(H15*VLOOKUP(prov_cd,rate_table,2,FALSE)) -> 602.3 | O15: N/A | Q15: • | R15: • | U15: 5% Discount Applied. | V15: Rabais de 5 % appliqué. | W15: 8 | X15: Yes | AI15: • | AL15: • | AS15: 08T44-30A-300A Engine Block Heater 31670-BMS-004H Optimate 12V Auto Battery Charger/Maintainer
B18: 08W17-PC4-300 | C18: =B18 -> 08W17-PC4-300 | D18: 17" Steel Wheels | E18: 17 po en acier de roues | F18: Steel wheels offer great value and allow you to save your factory wheels from our harsh Canadian winters. Price listed excludes winter tires and installation. Set of 4. | G18: Des roues en acier offrent un excellent rapport qualité-prix et vous permettent de préserver les roues d’origine de votre véhicule de nos rigoureux hivers canadiens. Le prix indiqué exclut les pneus d'hiver et l'installation. Ensemble de quatre. | H18: 1.6 | J18: =VLOOKUP(B18,'[1]MASTER PART LIST'!$B:$C,2,FALSE)*4 -> 376.4 | K18: =VLOOKUP(B18,'[1]MASTER PART LIST'!$B:$D,3,FALSE)*4 -> 627.28 | L18: =K18+(H18*VLOOKUP(prov_cd,rate_table,2,FALSE)) -> 870.48 | O18: T | Q18: T | R18: T | U18: Priced as a set of 4 wheels. Tires sold separately. | V18: Prix pour un ensemble de 4 roues. Pneus vendus séparément. | W18: 10 | AG18: •
B19: 08W19-30A-300 | C19: =B19 -> 08W19-30A-300 | D19: 19" HPD Alloy Wheels, Black | E19: Jantes de 19 pouces HPD en alliage noir | F19: Attract even more attention with these stunning 19" HPD Black Alloy Wheels structurally matched to the original vehicle design so that handling remains undisturbed. Priced as a set of 4. Recommended tires sold separately. | G19: Attirez encore plus l’attention avec ces superbes jantes HPD de 19 pouces en alliage noir dont la structure est adaptée à la conception originale du véhicule afin que la maniabilité reste inchangée. Prix pour ensemble de 4. Pneus recommandés vendus séparément. | H19: 1.6 | J19: =VLOOKUP(B19,'[1]MASTER PART LIST'!$B:$C,2,FALSE)*4 -> 2628 | K19: =VLOOKUP(B19,'[1]MASTER PART LIST'!$B:$D,3,FALSE)*4 -> 3756 | L19: =K19+(H19*VLOOKUP(prov_cd,rate_table,2,FALSE)) -> 3999.2 | O19: E | Q19: E | R19: E | U19: Priced as a set of 4 wheels. Tires sold separately. | V19: Prix pour un ensemble de 4 roues. Pneus vendus séparément. | W19: 9 | AG19: •
B20: 08W42-S2A-101 | C20: =B20 -> 08W42-S2A-101 | D20: Wheel Locks - Black | E20: Écrous de roue antivols - Noirs | F20: A great way to help ensure that your wheels stay on your vehicle where they belong. | G20: Un excellent moyen de vous assurer que les roues demeurent sur votre véhicule là où elles devraient se trouver. | H20: 0.2 | J20: =VLOOKUP(B20,'[1]MASTER PART LIST'!$B:$C,2,FALSE) -> 61 | K20: =VLOOKUP(B20,'[1]MASTER PART LIST'!$B:$D,3,FALSE) -> 102 | L20: =K20+(H20*VLOOKUP(prov_cd,rate_table,2,FALSE)) -> 132.4 | O20: • | Q20: • | R20: • | W20: 11 | AK20: • | AS20: 08W42-SCV-302 Wheel Locks - Chrome
B21: 08W42-SCV-302 | C21: =B21 -> 08W42-SCV-302 | D21: Wheel Locks - Chrome | E21: Écrous de roue antivols - Chromés | F21: A great way to help ensure that your wheels stay on your vehicle where they belong. Chrome-plated triple-nickel finish for a brilliant shine and corrosion prevention | G21: Un excellent moyen de vous assurer que les roues demeurent sur votre véhicule, où elles devraient se trouver. La finition chromée triple nickel procure un éclat brillant et une prévention contre la corrosion. | H21: 0.2 | J21: =VLOOKUP(B21,'[1]MASTER PART LIST'!$B:$C,2,FALSE) -> 54 | K21: =VLOOKUP(B21,'[1]MASTER PART LIST'!$B:$D,3,FALSE) -> 90 | L21: =K21+(H21*VLOOKUP(prov_cd,rate_table,2,FALSE)) -> 120.4 | O21: • | Q21: • | R21: • | W21: 12 | AK21: • | AS21: 08W42-S2A-101 Wheel Locks - Black
B22: 08W42-PL4-100 | C22: =B22 -> 08W42-PL4-100 | D22: Wheel Lug Nuts - Black | E22: Écrous de roue - Noir | F22: Create a different look with a set of black lug nuts. Each package has a quantity of 20 lugs. | G22: Créez un aspect différent grâce à cet ensemble d’écrous de roue noirs qui complète les roues en alliage du véhicule. Chaque paquet contient 20 écrous de roue. | H22: 0.2 | J22: =VLOOKUP(B22,'[1]MASTER PART LIST'!$B:$C,2,FALSE) -> 170 | K22: =VLOOKUP(B22,'[1]MASTER PART LIST'!$B:$D,3,FALSE) -> 283 | L22: =K22+(H22*VLOOKUP(prov_cd,rate_table,2,FALSE)) -> 313.4 | O22: • | Q22: • | R22: • | U22: set of 20 lug nuts | V22: lot de 20 écrous de roue | W22: 14 | AO22: •
B23: 08W42-SNA-301 | C23: =B23 -> 08W42-SNA-301 | D23: Wheel Locks, Chrome - Exposed | E23: Écrous de roue antivol, chromée - exposés | F23: A great way to help ensure that your wheels stay on your vehicle where they belong. Chrome-plated triple-nickel finish for a brilliant shine and corrosion prevention | G23: Un excellent moyen de vous assurer que les roues demeurent sur votre véhicule, où elles devraient se trouver. La finition chromée triple nickel procure un éclat brillant et une prévention contre la corrosion. | H23: 0.2 | J23: =VLOOKUP(B23,'[1]MASTER PART LIST'!$B:$C,2,FALSE) -> 44 | K23: =VLOOKUP(B23,'[1]MASTER PART LIST'!$B:$D,3,FALSE) -> 73 | L23: =K23+(H23*VLOOKUP(prov_cd,rate_table,2,FALSE)) -> 103.4 | O23: • | Q23: • | R23: • | W23: 13 | AG23: •
A24: New | B24: 08F20-30A-100C | C24: =B24 -> 08F20-30A-100C | D24: Black Emblem Rear "H" mark | E24: Emblème, noirs lustré arrière « H » mark | F24: Add a unique and bold style with these gloss black emblems. Pair up with H-Mark, Accord, and Touring emblems to complete the look - sold separately. | G24: Donnez un style unique et audacieux avec ces emblèmes noir lustré. Jumelez-les aux emblèmes « H », Accord et Touring pour compléter l’apparence (vendus séparément). | H24: 0.2 | J24: =VLOOKUP(B24,'[1]MASTER PART LIST'!$B:$C,2,FALSE) -> 37 | K24: =VLOOKUP(B24,'[1]MASTER PART LIST'!$B:$D,3,FALSE) -> 62 | L24: =K24+(H24*VLOOKUP(prov_cd,rate_table,2,FALSE)) -> 92.4 | O24: • | Q24: • | R24: • | U24: Rear H-Mark Logo. | V24: Logo H-Mark l'arrière. | W24: 25 | AO24: • | AS24: 26ACC-BLK-EMB Black Emblem Set - Touring
A25: New | B25: 08F20-30A-100D | C25: =B25 -> 08F20-30A-100D | D25: Black Emblem, Accord | E25: Emblème, noirs lustré arrière « Accord » | F25: Add a unique and bold style with these gloss black emblems. Pair up with H-Mark, Accord, and Touring emblems to complete the look - sold separately. | G25: Donnez un style unique et audacieux avec ces emblèmes noir lustré. Jumelez-les aux emblèmes « H », Accord et Touring pour compléter l’apparence (vendus séparément). | H25: 0.3 | J25: =VLOOKUP(B25,'[1]MASTER PART LIST'!$B:$C,2,FALSE) -> 37 | K25: =VLOOKUP(B25,'[1]MASTER PART LIST'!$B:$D,3,FALSE) -> 62 | L25: =K25+(H25*VLOOKUP(prov_cd,rate_table,2,FALSE)) -> 107.6 | O25: • | Q25: N/A | R25: • | W25: 26 | AO25: • | AS25: 26ACC-BLK-EMB Black Emblem Set - Touring
A26: New | B26: 08F20-3A0-100C | C26: =B26 -> 08F20-3A0-100C | D26: Black Emblem, Touring | E26: Emblème, noirs lustré « Touring » | F26: Add a unique and bold style with these gloss black emblems. Pair up with H-Mark, Accord, and Touring emblems to complete the look - sold separately. | G26: Donnez un style unique et audacieux avec ces emblèmes noir lustré. Jumelez-les aux emblèmes « H », Accord et Touring pour compléter l’apparence (vendus séparément). | H26: 0.2 | J26: =VLOOKUP(B26,'[1]MASTER PART LIST'!$B:$C,2,FALSE) -> 44 | K26: =VLOOKUP(B26,'[1]MASTER PART LIST'!$B:$D,3,FALSE) -> 73 | L26: =K26+(H26*VLOOKUP(prov_cd,rate_table,2,FALSE)) -> 103.4 | O26: N/A | Q26: N/A | R26: • | W26: 27 | AO26: • | AS26: 26ACC-BLK-EMB Black Emblem Set - Touring
A27: New | B27: 08F20-T20-100B | C27: =B27 -> 08F20-T20-100B | D27: Black Emblem, Hybrid | E27: Emblème, noirs lustré « Hybride » | F27: Add a unique and bold style with these gloss black emblems. Pair up with H-Mark, Accord, and Touring emblems to complete the look - sold separately. | G27: Donnez un style unique et audacieux avec ces emblèmes noir lustré. Jumelez-les aux emblèmes « H », Accord et Touring pour compléter l’apparence (vendus séparément). | H27: 0.2 | J27: =VLOOKUP(B27,'[1]MASTER PART LIST'!$B:$C,2,FALSE) -> 46 | K27: =VLOOKUP(B27,'[1]MASTER PART LIST'!$B:$D,3,FALSE) -> 77 | L27: =K27+(H27*VLOOKUP(prov_cd,rate_table,2,FALSE)) -> 107.4 | O27: N/A | Q27: N/A | R27: • | W27: 28 | AO27: • | AS27: 26ACC-BLK-EMB Black Emblem Set - Touring
B29: 08F20-30A-100B | C29: =B29 -> 08F20-30A-100B | D29: HPD Badge | E29: Emblème HPD | F29: HPD - Honda Performance Development emblem with gloss black finish. A sporty, black HPD emblem finishes off the look of the other available HPD accessories. | G29: HPD – Emblème Honda Performance Development avec fini noir brillant. L'emblème HPD noir, d’allure sport, vient parfaire l'apparence des autres accessoires HPD disponibles. | H29: 0.1 | J29: =VLOOKUP(B29,'[1]MASTER PART LIST'!$B:$C,2,FALSE) -> 71 | K29: =VLOOKUP(B29,'[1]MASTER PART LIST'!$B:$D,3,FALSE) -> 118 | L29: =K29+(H29*VLOOKUP(prov_cd,rate_table,2,FALSE)) -> 133.2 | O29: • | Q29: • | R29: • | W29: 29 | AO29: •
B30: 08F59-30A-100 | C30: =B30 -> 08F59-30A-100 | D30: Fender Emblem | E30: Emblème d’aile | F30: If attention to detail is important to you, then you’re sure to love the look of the Fender Emblems. Their bold feature not only completes your Accord’s original unique exterior style, but also accentuates it. | G30: Si l’attention aux détails est importante pour vous, alors vous aimerez certainement l’allure des emblèmes d’ailes. Leurs lignes audacieuses complètent non seulement le style extérieur original et unique de votre Accord, mais le mettent également en valeur. | H30: 0.2 | J30: =VLOOKUP(B30,'[1]MASTER PART LIST'!$B:$C,2,FALSE) -> 94 | K30: =VLOOKUP(B30,'[1]MASTER PART LIST'!$B:$D,3,FALSE) -> 157 | L30: =K30+(H30*VLOOKUP(prov_cd,rate_table,2,FALSE)) -> 187.4 | O30: • | Q30: • | R30: • | W30: 30 | AO30: •
B31: 08F04-30A-1F0 | C31: =B31 -> 08F04-30A-1F0 | D31: Side Underbody Spoiler | E31: Becquet de bas de caisse, latéral | F31: The Side Underbody Spoiler adds a sporty, low-profile custom look that creates an accentuated aerodynamic style. Requires the Front Splash Guards to be removed. | G31: Le becquet de bas de caisse latéral confère une allure sportive et un profil abaissé personnalisé qui accentue le style aérodynamique. Nécessite le retrait des garde-boue avant. | H31: 0.6 | J31: =VLOOKUP(B31,'[1]MASTER PART LIST'!$B:$C,2,FALSE) -> 432 | K31: =VLOOKUP(B31,'[1]MASTER PART LIST'!$B:$D,3,FALSE) -> 720 | L31: =K31+(H31*VLOOKUP(prov_cd,rate_table,2,FALSE)) -> 811.2 | O31: • | Q31: • | R31: • | W31: 17 | AO31: • | AS31: 23ACC-ARO-EX Aeto Kit - EX Trim 23ACC-ARO-SPHY Aero Kit - Sport Trim 23ACC-ARO-TRHY Aero Kit - Touring Trim
B32: 08P98-30A-1F0 | C32: =B32 -> 08P98-30A-1F0 | D32: Front Aero Bumper | E32: Becquet de bas de caisse, avant | F32: The Front Underbody Spoiler adds a sporty, low-profile custom look that creates an accentuated aerodynamic style. | G32: Le becquet de bas de caisse avant confère une allure sportive et un profil abaissé personnalisé qui accentue le style aérodynamique. | H32: 0.6 | J32: =VLOOKUP(B32,'[1]MASTER PART LIST'!$B:$C,2,FALSE) -> 350 | K32: =VLOOKUP(B32,'[1]MASTER PART LIST'!$B:$D,3,FALSE) -> 583 | L32: =K32+(H32*VLOOKUP(prov_cd,rate_table,2,FALSE)) -> 674.2 | O32: • | Q32: • | R32: • | W32: 15 | AO32: • | AS32: 23ACC-ARO-EX Aeto Kit - EX Trim 23ACC-ARO-SPHY Aero Kit - Sport Trim 23ACC-ARO-TRHY Aero Kit - Touring Trim
B33: 08P99-30A-1F0 | C33: =B33 -> 08P99-30A-1F0 | D33: Rear Aero Bumper | E33: Becquet de bas de caisse, arrière | F33: The Rear Underbody Spoiler adds a sporty, low-profile custom look that creates an accentuated aerodynamic style. Cannot be combined with Rear Splash Guards. | G33: Le becquet de bas de caisse arrière confère une allure sportive et un profil abaissé personnalisé qui accentue le style aérodynamique. Ne peut être combiné aux garde-boue arrière. | H33: 0.6 | J33: =VLOOKUP(B33,'[1]MASTER PART LIST'!$B:$C,2,FALSE) -> 350 | K33: =VLOOKUP(B33,'[1]MASTER PART LIST'!$B:$D,3,FALSE) -> 583 | L33: =K33+(H33*VLOOKUP(prov_cd,rate_table,2,FALSE)) -> 674.2 | O33: • | Q33: • | R33: • | W33: 16 | AO33: • | AS33: 23ACC-ARO-EX Aeto Kit - EX Trim 23ACC-ARO-SPHY Aero Kit - Sport Trim 23ACC-ARO-TRHY Aero Kit - Touring Trim
B34: 08R06-30A-110 | C34: =B34 -> 08R06-30A-110 | D34: Door Mirror Covers & Lower Intake Accents | E34: Couvercle de rétroviseur de portière et élément inférieur d’admission d’air | F34: Promotional Priced Item offered for a limited time only. Item availability and price are subject to change without prior notice. Contact your local Honda Dealer for more information. Enhance the look of your car with these black Door Mirror Covers and Lower Intake Accents. Designed and engineered by Honda for a precise fit | G34: Article à prix promotionnel offert pour une durée limitée seulement. La disponibilité et le prix de l’article peuvent être modifiés sans préavis. Communiquez avec votre concessionnaire Honda pour plus d’information. Rehaussez l’apparence de votre voiture avec ces couvercles de rétroviseurs de portières noirs et éléments visuels d’admission d’air. Conçus et fabriqués par Honda pour un ajustement précis. | H34: 1.1 | J34: =VLOOKUP(B34,'[1]MASTER PART LIST'!$B:$C,2,FALSE) -> 210 | K34: =VLOOKUP(B34,'[1]MASTER PART LIST'!$B:$D,3,FALSE) -> 350 | L34: =K34+(H34*VLOOKUP(prov_cd,rate_table,2,FALSE)) -> 517.2 | O34: • | Q34: N/A | R34: N/A | W34: 18 | AO34: • | AS34: 23ACC-ARO-EX Aeto Kit - EX Trim 23ACC-ARO-SPHY Aero Kit - Sport Trim
B35: 08R06-30A-110A | C35: =B35 -> 08R06-30A-110A | D35: Door Mirror Covers & Lower Intake Accents | E35: Couvercle de rétroviseur de portière et élément inférieur d’admission d’air | F35: Enhance the look of your car with these black Door Mirror Covers and Lower Intake Accents. Designed and engineered by Honda for a precise fit | G35: Rehaussez l’apparence de votre voiture avec ces couvercles de rétroviseurs de portières noirs et éléments visuels d’admission d’air. Conçus et fabriqués par Honda pour un ajustement précis. | H35: 1.1 | J35: =VLOOKUP(B35,'[1]MASTER PART LIST'!$B:$C,2,FALSE) -> 210 | K35: =VLOOKUP(B35,'[1]MASTER PART LIST'!$B:$D,3,FALSE) -> 350 | L35: =K35+(H35*VLOOKUP(prov_cd,rate_table,2,FALSE)) -> 517.2 | O35: N/A | Q35: N/A | R35: • | W35: 19 | AO35: • | AS35: 23ACC-ARO-TRHY Aero Kit - Touring Trim
B36: 08P48-30A-100 | C36: =B36 -> 08P48-30A-100 | D36: Film Set - Door Handle & Rear Bumper Film | E36: Ensemble de pellicule – Pellicule de poignée de portière et de pare-chocs arrière | F36: Transparent urethane film in the well of the door handle helps safeguard the paint finish from unsightly scratches from nails, jewelry, and keys combined with The Rear Bumper Applique provides extra protection when loading and unloading the trunk. | G36: La pellicule transparente en uréthane dans le puits de la poignée de portière aide à protéger la peinture des rayures disgracieuses causées par les ongles, les bijoux et les clés. S’ajoute à celle-ci la pellicule du pare-chocs arrière pour procurer une protection supplémentaire lors du chargement et du déchargement du coffre. | H36: 0.7 | J36: =VLOOKUP(B36,'[1]MASTER PART LIST'!$B:$C,2,FALSE) -> 131 | K36: =VLOOKUP(B36,'[1]MASTER PART LIST'!$B:$D,3,FALSE) -> 218 | L36: =K36+(H36*VLOOKUP(prov_cd,rate_table,2,FALSE)) -> 324.4 | O36: • | Q36: • | R36: • | W36: 38 | X36: Yes | AM36: •
B37: 08P20-30A-100A | C37: =B37 -> 08P20-30A-100A | D37: Door Edge Film | E37: Pellicule pour rebord de portière | F37: Help protect against unsightly nicks and scrapes around your door edges. | G37: La pellicule aide à protéger les surfaces des rebords de portières contre des égratignures et éraflures inesthétiques. | H37: 0.5 | J37: =VLOOKUP(B37,'[1]MASTER PART LIST'!$B:$C,2,FALSE) -> 71 | K37: =VLOOKUP(B37,'[1]MASTER PART LIST'!$B:$D,3,FALSE) -> 118 | L37: =K37+(H37*VLOOKUP(prov_cd,rate_table,2,FALSE)) -> 194 | O37: • | Q37: • | R37: • | U37: Cannot be installed with Door Edge Guards | V37: Ne peut être installé simultanément avec protecteurs de bordure de porte. | W37: 37 | X37: Yes | AM37: • | AS37: 08P20-30A-110 Door Edge Guards
B38: 08R04-TVA-101 | C38: =B38 -> 08R04-TVA-101 | D38: Door Visors | E38: Déflecteurs de portières | F38: This tinted Door Visor helps to protect you and your passengers from sun glare and minimizes outside noise when the windows are partially open. | G38: Cet ensemble de déflecteur de portière teinté aide à réduire les reflets du soleil ainsi que le bruit provenant de l'extérieur quand les glaces sont partiellement ouvertes. Image si dessous est un ancient model | H38: 0.5 | J38: =VLOOKUP(B38,'[1]MASTER PART LIST'!$B:$C,2,FALSE) -> 200 | K38: =VLOOKUP(B38,'[1]MASTER PART LIST'!$B:$D,3,FALSE) -> 333 | L38: =K38+(H38*VLOOKUP(prov_cd,rate_table,2,FALSE)) -> 409 | O38: • | Q38: • | R38: • | W38: 21 | X38: Yes | AM38: •
B39: 08R01-30A-300 | C39: =B39 -> 08R01-30A-300 | D39: Moonroof Visor | E39: Déflecteur de toit ouvrant | F39: The Moonroof Visor helps reduce wind noise and glare for a more comfortable and enjoyable driving experience. | G39: Le déflecteur de toit contribue à réduire le bruit du vent et l'éblouissement pour une expérience de conduite plus confortable et plus agréable. | H39: 0.3 | J39: =VLOOKUP(B39,'[1]MASTER PART LIST'!$B:$C,2,FALSE) -> 200 | K39: =VLOOKUP(B39,'[1]MASTER PART LIST'!$B:$D,3,FALSE) -> 333 | L39: =K39+(H39*VLOOKUP(prov_cd,rate_table,2,FALSE)) -> 378.6 | O39: • | Q39: • | R39: • | W39: 22 | X39: Yes | AM39: •
B40: 08P09-30A-300 | C40: =B40 -> 08P09-30A-300 | D40: Rear Splash Guards | E40: Garde-boue arrière | F40: Rear Splash Guards are a nice finishing touch. They give your Accord a great look and help protect your paint from chips and stains. | G40: Les garde-boue arrière ajoutent une touche finale soignée. Les garde-boue procurent une belle apparence à votre Accord et contribuent à protéger la peinture contre les éclats et les taches. | H40: 0.4 | J40: =VLOOKUP(B40,'[1]MASTER PART LIST'!$B:$C,2,FALSE) -> 50 | K40: =VLOOKUP(B40,'[1]MASTER PART LIST'!$B:$D,3,FALSE) -> 83 | L40: =K40+(H40*VLOOKUP(prov_cd,rate_table,2,FALSE)) -> 143.8 | O40: • | Q40: • | R40: • | W40: 44 | X40: Yes | AM40: • | AS40: 23ACC-PRO-PKA Protection Package Advance
A41: no image | B41: 08P20-30A-XXXX | C41: =B42 -> 08P20-30A-110 | D41: Door Edge Guards | E41: Déflecteur de bas de caisse avant | F41: Door Edge Guards help protect your doors from nicks and scrapes that can be expensive to repair. | G41: Les protecteurs de rebords de portières aident à protéger les portières de votre véhicule contre les égratignures et éraflures dont la réparation serait coûteuse. | H41: =H42 -> 0.4 | J41: =J42 -> 176 | K41: =K42 -> 293 | L41: =K41+(H41*VLOOKUP(prov_cd,rate_table,2,FALSE)) -> 353.8 | O41: • | Q41: • | R41: • | W41: 39 | AM41: • | AS41: 08P20-30A-100A Door Edge Film
B42: 08P20-30A-110 | C42: N/A | D42: Platinum White Pearl (NH-883P) | E42: Blanc platine nacré (NH-883P) | H42: 0.4 | J42: =VLOOKUP(B42,'[1]MASTER PART LIST'!$B:$C,2,FALSE) -> 176 | K42: =VLOOKUP(B42,'[1]MASTER PART LIST'!$B:$D,3,FALSE) -> 293 | L42: =K42+(H42*VLOOKUP(prov_cd,rate_table,2,FALSE)) -> 353.8 | O42: • | Q42: • | R42: •
B43: 08P20-30A-140 | C43: N/A | D43: Meteoroid Gray Pearl (NH-904M) | E43: Gris météore nacré (NH-904M) | H43: 0.4 | J43: =VLOOKUP(B43,'[1]MASTER PART LIST'!$B:$C,2,FALSE) -> 176 | K43: =VLOOKUP(B43,'[1]MASTER PART LIST'!$B:$D,3,FALSE) -> 293 | L43: =K43+(H43*VLOOKUP(prov_cd,rate_table,2,FALSE)) -> 353.8 | O43: N/A | Q43: • | R43: N/A
...

Sheet SELECT PROVINCE
A1: Select Province: Choissisez votre province: | B1: QC
B4: Current Labor Rates
B5: Taux de main d'oeuvre en cours
B6: AB | C6: 171
B7: BC | C7: 181
B8: MB | C8: 164
B9: NB | C9: 142
B10: NL | C10: 142
B11: NS | C11: 142
B12: ON | C12: 160 | F12: =prov_cd -> QC
B13: PEI | C13: 134
B14: QC | C14: 152
B15: SK | C15: 164
B16: YT | C16: 181
A23: All published prices, trim specifications, and availability are subject to change without prior notice.
A24: Tout prix, spécifications de versions et disponibilté d'accessoires publiés sont sujets à changer sans pré-avis.

Sheet 26MY_ACCORD_APP_EN
C2: Honda Accessories
C3: Model Name | D3: ='26MY_ACCORD_DATA'!$C$2 -> Accord
C4: Model Year | D4: ='26MY_ACCORD_DATA'!$C$3 -> 2026
C5: S = Standard (accessory comes standard on this trim)
C6: T = Tire Size Change (the size of the accessory wheel is smaller/larger than the OE Wheel. Customer will require new tires to fit these wheels.)
C7: E = Exchange Standard Equipment (the size of the accessory wheel is the same size as the OE wheel and therefore they can use the OE tire.)
C8: N/A = Not Applicable (accessory cannot be applied to this trim)
H10: Province
C11: 1.0 Packages and Kits | H11: =prov_cd -> QC
C12: Description | D12: Part Number | E12: Dealer Net | F12: List Price | G12: FRT | H12: Installed Price | J12: Application | Q12: Comments
I13: ='26MY_ACCORD_DATA'!$M$7 -> 0 | J13: ='26MY_ACCORD_DATA'!$M$7 -> 0 | K13: ='26MY_ACCORD_DATA'!$O$7 -> SE | L13: ='26MY_ACCORD_DATA'!$P$7 -> 0 | M13: ='26MY_ACCORD_DATA'!$Q$7 -> Sport -L Hybrid | N13: ='26MY_ACCORD_DATA'!$R$7 -> Touring Hybrid | O13: ='26MY_ACCORD_DATA'!$T$7 -> 0 | P13: ='26MY_ACCORD_DATA'!$T$7 -> 0
B14: 23ACC-PRO-PK | C14: =VLOOKUP(B14,'26MY_ACCORD_DATA'!B:AS,3,FALSE) -> Protection Package | D14: =B14 -> 23ACC-PRO-PK | E14: =VLOOKUP(B14,'26MY_ACCORD_DATA'!B:AS,9,FALSE) -> 273.6 | F14: =VLOOKUP(B14,'26MY_ACCORD_DATA'!B:AS,10,FALSE) -> 507 | G14: =VLOOKUP(B14,'26MY_ACCORD_DATA'!B:AS,7,FALSE) -> 0.2 | H14: =VLOOKUP(B14,'26MY_ACCORD_DATA'!B:AS,11,FALSE) -> 537.4 | I14: =VLOOKUP($B14,'26MY_ACCORD_DATA'!$B:$AS,12,FALSE) -> 0 | J14: =VLOOKUP($B14,'26MY_ACCORD_DATA'!$B:$AS,13,FALSE) -> 0 | K14: =VLOOKUP(B14,'26MY_ACCORD_DATA'!B:AS,14,FALSE) -> • | L14: =VLOOKUP(B14,'26MY_ACCORD_DATA'!B:AS,15,FALSE) -> 0 | M14: =VLOOKUP(B14,'26MY_ACCORD_DATA'!B:AS,16,FALSE) -> • | N14: =VLOOKUP(B14,'26MY_ACCORD_DATA'!B:AS,17,FALSE) -> • | O14: =VLOOKUP($B14,'26MY_ACCORD_DATA'!$B:$AS,18,FALSE) -> 0 | P14: =VLOOKUP(B14,'26MY_ACCORD_DATA'!B:AS,19,FALSE) -> 0 | Q14: =IF(VLOOKUP(B14,'26MY_ACCORD_DATA'!B:AS,20,FALSE)="","",VLOOKUP(B14,'26MY_ACCORD_DATA'!B:AS,20,FALSE))
B15: 08P17-30A-110 | C15: =VLOOKUP(B15,'26MY_ACCORD_DATA'!B:AS,3,FALSE) -> All Season Floor Mats | D15: =B15 -> 08P17-30A-110
B16: 08U45-30A-100 | C16: =VLOOKUP(B16,'26MY_ACCORD_DATA'!B:AS,3,FALSE) -> Trunk Tray | D16: =B16 -> 08U45-30A-100
B18: 23ACC-PRO-PKA | C18: =VLOOKUP(B18,'26MY_ACCORD_DATA'!B:AS,3,FALSE) -> Protection Package Advance | D18: =B18 -> 23ACC-PRO-PKA | E18: =VLOOKUP(B18,'26MY_ACCORD_DATA'!B:AS,9,FALSE) -> 342.891 | F18: =VLOOKUP(B18,'26MY_ACCORD_DATA'!B:AS,10,FALSE) -> 583.2 | G18: =VLOOKUP(B18,'26MY_ACCORD_DATA'!B:AS,7,FALSE) -> 1 | H18: =VLOOKUP(B18,'26MY_ACCORD_DATA'!B:AS,11,FALSE) -> 735.2 | I18: =VLOOKUP(B18,'26MY_ACCORD_DATA'!B:AS,12,FALSE) -> 0 | J18: =VLOOKUP(B18,'26MY_ACCORD_DATA'!B:AS,13,FALSE) -> 0 | K18: =VLOOKUP(B18,'26MY_ACCORD_DATA'!B:AS,14,FALSE) -> • | L18: =VLOOKUP(B18,'26MY_ACCORD_DATA'!B:AS,15,FALSE) -> 0 | M18: =VLOOKUP(B18,'26MY_ACCORD_DATA'!B:AS,16,FALSE) -> • | N18: =VLOOKUP(B18,'26MY_ACCORD_DATA'!B:AS,17,FALSE) -> N/A | O18: =VLOOKUP(B18,'26MY_ACCORD_DATA'!B:AS,18,FALSE) -> 0 | P18: =VLOOKUP(B18,'26MY_ACCORD_DATA'!B:AS,19,FALSE) -> 0 | Q18: =IF(VLOOKUP(B18,'26MY_ACCORD_DATA'!B:AS,20,FALSE)="","",VLOOKUP(B18,'26MY_ACCORD_DATA'!B:AS,20,FALSE)) -> 10% Discount Applied.
B19: 08P17-30A-110 | C19: =VLOOKUP(B19,'26MY_ACCORD_DATA'!B:AS,3,FALSE) -> All Season Floor Mats | D19: =B19 -> 08P17-30A-110
B20: 08U45-30A-100 | C20: =VLOOKUP(B20,'26MY_ACCORD_DATA'!B:AS,3,FALSE) -> Trunk Tray | D20: =B20 -> 08U45-30A-100
B21: 08P09-30A-300 | C21: =VLOOKUP(B21,'26MY_ACCORD_DATA'!B:AS,3,FALSE) -> Rear Splash Guards | D21: =B21 -> 08P09-30A-300
B22: 08L96-TVA-300 | C22: =VLOOKUP(B22,'26MY_ACCORD_DATA'!B:AS,3,FALSE) -> Cargo Net | D22: =B22 -> 08L96-TVA-300
B24: 26ACC-BLK-EMB | C24: =VLOOKUP(B24,'26MY_ACCORD_DATA'!B:AS,3,FALSE) -> Black Emblem Set - Touring | D24: =B24 -> 26ACC-BLK-EMB | E24: =VLOOKUP(B24,'26MY_ACCORD_DATA'!B:AS,9,FALSE) -> 155.8 | F24: =VLOOKUP(B24,'26MY_ACCORD_DATA'!B:AS,10,FALSE) -> 260.3 | G24: =VLOOKUP(B24,'26MY_ACCORD_DATA'!B:AS,7,FALSE) -> 0.9 | H24: =VLOOKUP(B24,'26MY_ACCORD_DATA'!B:AS,11,FALSE) -> 397.1 | I24: =VLOOKUP($B24,'26MY_ACCORD_DATA'!$B:$AS,12,FALSE) -> 0 | J24: =VLOOKUP($B24,'26MY_ACCORD_DATA'!$B:$AS,13,FALSE) -> 0 | K24: =VLOOKUP(B24,'26MY_ACCORD_DATA'!B:AS,14,FALSE) -> N/A | L24: =VLOOKUP(B24,'26MY_ACCORD_DATA'!B:AS,15,FALSE) -> 0 | M24: =VLOOKUP(B24,'26MY_ACCORD_DATA'!B:AS,16,FALSE) -> N/A | N24: =VLOOKUP(B24,'26MY_ACCORD_DATA'!B:AS,17,FALSE) -> • | O24: =VLOOKUP($B24,'26MY_ACCORD_DATA'!$B:$AS,18,FALSE) -> 0 | P24: =VLOOKUP(B24,'26MY_ACCORD_DATA'!B:AS,19,FALSE) -> 0 | Q24: =IF(VLOOKUP(B24,'26MY_ACCORD_DATA'!B:AS,20,FALSE)="","",VLOOKUP(B24,'26MY_ACCORD_DATA'!B:AS,20,FALSE)) -> 5% Discount Applied.
B25: 08F20-30A-100C | C25: =VLOOKUP(B25,'26MY_ACCORD_DATA'!B:AS,3,FALSE) -> Black Emblem Rear "H" mark | D25: =B25 -> 08F20-30A-100C
B26: 08F20-30A-100D | C26: =VLOOKUP(B26,'26MY_ACCORD_DATA'!B:AS,3,FALSE) -> Black Emblem, Accord | D26: =B26 -> 08F20-30A-100D
B27: 08F20-3A0-100C | C27: =VLOOKUP(B27,'26MY_ACCORD_DATA'!B:AS,3,FALSE) -> Black Emblem, Touring | D27: =B27 -> 08F20-3A0-100C
B28: 08F20-T20-100B | C28: =VLOOKUP(B28,'26MY_ACCORD_DATA'!B:AS,3,FALSE) -> Black Emblem, Hybrid | D28: =B28 -> 08F20-T20-100B
B30: 23ACC-ARO-EX | C30: =VLOOKUP(B30,'26MY_ACCORD_DATA'!B:AS,3,FALSE) -> Aero Kit - SE Trim | D30: =B30 -> 23ACC-ARO-EX | E30: =VLOOKUP(B30,'26MY_ACCORD_DATA'!B:AS,9,FALSE) -> 1555.2 | F30: =VLOOKUP(B30,'26MY_ACCORD_DATA'!B:AS,10,FALSE) -> 2591.1 | G30: =VLOOKUP(B30,'26MY_ACCORD_DATA'!B:AS,7,FALSE) -> 3.5 | H30: =VLOOKUP(B30,'26MY_ACCORD_DATA'!B:AS,11,FALSE) -> 3123.1 | I30: =VLOOKUP(B30,'26MY_ACCORD_DATA'!B:AS,12,FALSE) -> 0 | J30: =VLOOKUP(B30,'26MY_ACCORD_DATA'!B:AS,13,FALSE) -> 0 | K30: =VLOOKUP(B30,'26MY_ACCORD_DATA'!B:AS,14,FALSE) -> • | L30: =VLOOKUP(B30,'26MY_ACCORD_DATA'!B:AS,15,FALSE) -> 0 | M30: =VLOOKUP(B30,'26MY_ACCORD_DATA'!B:AS,16,FALSE) -> N/A | N30: =VLOOKUP(B30,'26MY_ACCORD_DATA'!B:AS,17,FALSE) -> N/A | O30: =VLOOKUP(B30,'26MY_ACCORD_DATA'!B:AS,18,FALSE) -> 0 | P30: =VLOOKUP(B30,'26MY_ACCORD_DATA'!B:AS,19,FALSE) -> 0 | Q30: =IF(VLOOKUP(B30,'26MY_ACCORD_DATA'!B:AS,20,FALSE)="","",VLOOKUP(B30,'26MY_ACCORD_DATA'!B:AS,20,FALSE)) -> 10% Discount Applied Decklid Spoiler - Crystal Black Pearl (NH-731P) colour
B31: 08F04-30A-1F0 | C31: =VLOOKUP(B31,'26MY_ACCORD_DATA'!B:AS,3,FALSE) -> Side Underbody Spoiler | D31: =B31 -> 08F04-30A-1F0
B32: 08P98-30A-1F0 | C32: =VLOOKUP(B32,'26MY_ACCORD_DATA'!B:AS,3,FALSE) -> Front Aero Bumper | D32: =B32 -> 08P98-30A-1F0
B33: 08P99-30A-1F0 | C33: =VLOOKUP(B33,'26MY_ACCORD_DATA'!B:AS,3,FALSE) -> Rear Aero Bumper | D33: =B33 -> 08P99-30A-1F0
B34: 08F10-30A-170 | C34: =VLOOKUP(B34,'26MY_ACCORD_DATA'!B:AS,3,FALSE) -> Crystal Black Pearl (NH-731P) | D34: =B34 -> 08F10-30A-170
B35: 08R06-30A-110 | C35: =VLOOKUP(B35,'26MY_ACCORD_DATA'!B:AS,3,FALSE) -> Door Mirror Covers & Lower Intake Accents | D35: =B35 -> 08R06-30A-110
B37: 23ACC-ARO-SPHY | C37: =VLOOKUP(B37,'26MY_ACCORD_DATA'!B:AS,3,FALSE) -> Aero Kit - Sport Trim | D37: =B37 -> 23ACC-ARO-SPHY | E37: =VLOOKUP(B37,'26MY_ACCORD_DATA'!B:AS,9,FALSE) -> 1018.8 | F37: =VLOOKUP(B37,'26MY_ACCORD_DATA'!B:AS,10,FALSE) -> 1697.4 | G37: =VLOOKUP(B37,'26MY_ACCORD_DATA'!B:AS,7,FALSE) -> 1.8 | H37: =VLOOKUP(B37,'26MY_ACCORD_DATA'!B:AS,11,FALSE) -> 1971 | I37: =VLOOKUP(B37,'26MY_ACCORD_DATA'!B:AS,12,FALSE) -> 0 | J37: =VLOOKUP(B37,'26MY_ACCORD_DATA'!B:AS,13,FALSE) -> 0 | K37: =VLOOKUP(B37,'26MY_ACCORD_DATA'!B:AS,14,FALSE) -> N/A | L37: =VLOOKUP(B37,'26MY_ACCORD_DATA'!B:AS,15,FALSE) -> 0 | M37: =VLOOKUP(B37,'26MY_ACCORD_DATA'!B:AS,16,FALSE) -> • | N37: =VLOOKUP(B37,'26MY_ACCORD_DATA'!B:AS,17,FALSE) -> N/A | O37: =VLOOKUP(B37,'26MY_ACCORD_DATA'!B:AS,18,FALSE) -> 0 | P37: =VLOOKUP(B37,'26MY_ACCORD_DATA'!B:AS,19,FALSE) -> 0 | Q37: =IF(VLOOKUP(B37,'26MY_ACCORD_DATA'!B:AS,20,FALSE)="","",VLOOKUP(B37,'26MY_ACCORD_DATA'!B:AS,20,FALSE)) -> 10% Discount Applied Sport Trim already comes standard with Decklid Spoiler
B38: 08F04-30A-1F0 | C38: =VLOOKUP(B38,'26MY_ACCORD_DATA'!B:AS,3,FALSE) -> Side Underbody Spoiler | D38: =B38 -> 08F04-30A-1F0
B39: 08P98-30A-1F0 | C39: =VLOOKUP(B39,'26MY_ACCORD_DATA'!B:AS,3,FALSE) -> Front Aero Bumper | D39: =B39 -> 08P98-30A-1F0
B40: 08P99-30A-1F0 | C40: =VLOOKUP(B40,'26MY_ACCORD_DATA'!B:AS,3,FALSE) -> Rear Aero Bumper | D40: =B40 -> 08P99-30A-1F0
B42: 23ACC-ARO-TRHY | C42: =VLOOKUP(B42,'26MY_ACCORD_DATA'!B:AS,3,FALSE) -> Aero Kit - Touring Trim | D42: =B42 -> 23ACC-ARO-TRHY | E42: =VLOOKUP(B42,'26MY_ACCORD_DATA'!B:AS,9,FALSE) -> 1555.2 | F42: =VLOOKUP(B42,'26MY_ACCORD_DATA'!B:AS,10,FALSE) -> 2591.1 | G42: =VLOOKUP(B42,'26MY_ACCORD_DATA'!B:AS,7,FALSE) -> 3.5 | H42: =VLOOKUP(B42,'26MY_ACCORD_DATA'!B:AS,11,FALSE) -> 3123.1 | I42: =VLOOKUP(B42,'26MY_ACCORD_DATA'!B:AS,12,FALSE) -> 0 | J42: =VLOOKUP(B42,'26MY_ACCORD_DATA'!B:AS,13,FALSE) -> 0 | K42: =VLOOKUP(B42,'26MY_ACCORD_DATA'!B:AS,14,FALSE) -> N/A | L42: =VLOOKUP(B42,'26MY_ACCORD_DATA'!B:AS,15,FALSE) -> 0 | M42: =VLOOKUP(B42,'26MY_ACCORD_DATA'!B:AS,16,FALSE) -> N/A | N42: =VLOOKUP(B42,'26MY_ACCORD_DATA'!B:AS,17,FALSE) -> • | O42: =VLOOKUP(B42,'26MY_ACCORD_DATA'!B:AS,18,FALSE) -> 0 | P42: =VLOOKUP(B42,'26MY_ACCORD_DATA'!B:AS,19,FALSE) -> 0 | Q42: =IF(VLOOKUP(B42,'26MY_ACCORD_DATA'!B:AS,20,FALSE)="","",VLOOKUP(B42,'26MY_ACCORD_DATA'!B:AS,20,FALSE)) -> 10% Discount Applied Decklid Spoiler - Crystal Black Pearl (NH-731P) colour
B43: 08F04-30A-1F0 | C43: =VLOOKUP(B43,'26MY_ACCORD_DATA'!B:AS,3,FALSE) -> Side Underbody Spoiler | D43: =B43 -> 08F04-30A-1F0
B44: 08P98-30A-1F0 | C44: =VLOOKUP(B44,'26MY_ACCORD_DATA'!B:AS,3,FALSE) -> Front Aero Bumper | D44: =B44 -> 08P98-30A-1F0
B45: 08P99-30A-1F0 | C45: =VLOOKUP(B45,'26MY_ACCORD_DATA'!B:AS,3,FALSE) -> Rear Aero Bumper | D45: =B45 -> 08P99-30A-1F0
B46: 08F10-30A-170 | C46: =VLOOKUP(B46,'26MY_ACCORD_DATA'!B:AS,3,FALSE) -> Crystal Black Pearl (NH-731P) | D46: =B46 -> 08F10-30A-170
B47: 08R06-30A-110A | C47: =VLOOKUP(B47,'26MY_ACCORD_DATA'!B:AS,3,FALSE) -> Door Mirror Covers & Lower Intake Accents | D47: =B47 -> 08R06-30A-110A
...

Sheet 26MY_ACCORD_APP_FR
B2: Honda Internal | C2: Accessoires Honda
C3: Nom du modèle | D3: ='26MY_ACCORD_DATA'!$C$2 -> Accord
C4: Année modèle | D4: ='26MY_ACCORD_DATA'!$C$3 -> 2026
C5: S = De série (accessoire de série sur cette version).
C6: T = Taille des pneus (la taille de la jante accessoire diffère de la jante d’origine. Le client aura besoin de nouveaux pneus pour ces jantes).
C7: E = Échange d’équipement de série (la taille de la jante accessoire est la même que celle de la jante d’origine. Le client peut utiliser les pneus d’origine).
C8: N/A = Sans objet (l’accessoire ne peut être utilisé pour cette version).
H10: Province
C11: 1.0 Groupes et ensembles | H11: =prov_cd -> QC
C12: La description | D12: Numéro de pièce | E12: Prix net | F12: Prix de liste | G12: T.F.F. | H12: Prix installé | I12: Application | Q12: Commentaires
I13: ='26MY_ACCORD_DATA'!$M$6 -> 0 | J13: ='26MY_ACCORD_DATA'!$M$6 -> 0 | K13: ='26MY_ACCORD_DATA'!$O$6 -> SE | L13: ='26MY_ACCORD_DATA'!$P$6 -> 0 | M13: ='26MY_ACCORD_DATA'!$Q$6 -> Sport -L Hybride | N13: ='26MY_ACCORD_DATA'!$R$6 -> Touring Hybride | O13: ='26MY_ACCORD_DATA'!$T$6 -> 0 | P13: ='26MY_ACCORD_DATA'!$T$6 -> 0
B14: 23ACC-PRO-PK | C14: =VLOOKUP(B14,'26MY_ACCORD_DATA'!B:AS,4,FALSE) -> Ensemble de protection | D14: =B14 -> 23ACC-PRO-PK | E14: =VLOOKUP(B14,'26MY_ACCORD_DATA'!B:AS,9,FALSE) -> 273.6 | F14: =VLOOKUP(B14,'26MY_ACCORD_DATA'!B:AS,10,FALSE) -> 507 | G14: =VLOOKUP(B14,'26MY_ACCORD_DATA'!B:AS,7,FALSE) -> 0.2 | H14: =VLOOKUP(B14,'26MY_ACCORD_DATA'!B:AS,11,FALSE) -> 537.4 | I14: =VLOOKUP($B14,'26MY_ACCORD_DATA'!$B:$AS,12,FALSE) -> 0 | J14: =VLOOKUP($B14,'26MY_ACCORD_DATA'!$B:$AS,13,FALSE) -> 0 | K14: =VLOOKUP(B14,'26MY_ACCORD_DATA'!B:AS,14,FALSE) -> • | L14: =VLOOKUP(B14,'26MY_ACCORD_DATA'!B:AS,15,FALSE) -> 0 | M14: =VLOOKUP(B14,'26MY_ACCORD_DATA'!B:AS,16,FALSE) -> • | N14: =VLOOKUP(B14,'26MY_ACCORD_DATA'!B:AS,17,FALSE) -> • | O14: =VLOOKUP($B14,'26MY_ACCORD_DATA'!$B:$AS,18,FALSE) -> 0 | P14: =VLOOKUP(B14,'26MY_ACCORD_DATA'!B:AS,19,FALSE) -> 0 | Q14: =IF(VLOOKUP(B14,'26MY_ACCORD_DATA'!B:AS,21,FALSE)="","",VLOOKUP(B14,'26MY_ACCORD_DATA'!B:AS,21,FALSE))
B15: 08P17-30A-110 | C15: =VLOOKUP(B15,'26MY_ACCORD_DATA'!B:AS,4,FALSE) -> Protège-tapis toutes saisons | D15: =B15 -> 08P17-30A-110
B16: 08U45-30A-100 | C16: =VLOOKUP(B16,'26MY_ACCORD_DATA'!B:AS,4,FALSE) -> Plateau de coffre | D16: =B16 -> 08U45-30A-100
B18: 23ACC-PRO-PKA | C18: =VLOOKUP(B18,'26MY_ACCORD_DATA'!B:AS,4,FALSE) -> Ensemble de protection avancée | D18: =B18 -> 23ACC-PRO-PKA | E18: =VLOOKUP(B18,'26MY_ACCORD_DATA'!B:AS,9,FALSE) -> 342.891 | F18: =VLOOKUP(B18,'26MY_ACCORD_DATA'!B:AS,10,FALSE) -> 583.2 | G18: =VLOOKUP(B18,'26MY_ACCORD_DATA'!B:AS,7,FALSE) -> 1 | H18: =VLOOKUP(B18,'26MY_ACCORD_DATA'!B:AS,11,FALSE) -> 735.2 | I18: =VLOOKUP(B18,'26MY_ACCORD_DATA'!B:AS,12,FALSE) -> 0 | J18: =VLOOKUP(B18,'26MY_ACCORD_DATA'!B:AS,13,FALSE) -> 0 | K18: =VLOOKUP(B18,'26MY_ACCORD_DATA'!B:AS,14,FALSE) -> • | L18: =VLOOKUP(B18,'26MY_ACCORD_DATA'!B:AS,15,FALSE) -> 0 | M18: =VLOOKUP(B18,'26MY_ACCORD_DATA'!B:AS,16,FALSE) -> • | N18: =VLOOKUP(B18,'26MY_ACCORD_DATA'!B:AS,17,FALSE) -> N/A | O18: =VLOOKUP(B18,'26MY_ACCORD_DATA'!B:AS,18,FALSE) -> 0 | P18: =VLOOKUP(B18,'26MY_ACCORD_DATA'!B:AS,19,FALSE) -> 0 | Q18: =IF(VLOOKUP(B18,'26MY_ACCORD_DATA'!B:AS,21,FALSE)="","",VLOOKUP(B18,'26MY_ACCORD_DATA'!B:AS,21,FALSE)) -> Rabais de 10 % appliqué.
B19: 08P17-30A-110 | C19: =VLOOKUP(B19,'26MY_ACCORD_DATA'!B:AS,4,FALSE) -> Protège-tapis toutes saisons | D19: =B19 -> 08P17-30A-110
B20: 08U45-30A-100 | C20: =VLOOKUP(B20,'26MY_ACCORD_DATA'!B:AS,4,FALSE) -> Plateau de coffre | D20: =B20 -> 08U45-30A-100
B21: 08P09-30A-300 | C21: =VLOOKUP(B21,'26MY_ACCORD_DATA'!B:AS,4,FALSE) -> Garde-boue arrière | D21: =B21 -> 08P09-30A-300
B22: 08L96-TVA-300 | C22: =VLOOKUP(B22,'26MY_ACCORD_DATA'!B:AS,4,FALSE) -> Filet de cargaison | D22: =B22 -> 08L96-TVA-300
B24: 26ACC-BLK-EMB | C24: =VLOOKUP(B24,'26MY_ACCORD_DATA'!B:AS,4,FALSE) -> Ensemble d’emblèmes noirs – Touring | D24: =B24 -> 26ACC-BLK-EMB | E24: =VLOOKUP(B24,'26MY_ACCORD_DATA'!B:AS,9,FALSE) -> 155.8 | F24: =VLOOKUP(B24,'26MY_ACCORD_DATA'!B:AS,10,FALSE) -> 260.3 | G24: =VLOOKUP(B24,'26MY_ACCORD_DATA'!B:AS,7,FALSE) -> 0.9 | H24: =VLOOKUP(B24,'26MY_ACCORD_DATA'!B:AS,11,FALSE) -> 397.1 | I24: =VLOOKUP($B24,'26MY_ACCORD_DATA'!$B:$AS,12,FALSE) -> 0 | J24: =VLOOKUP($B24,'26MY_ACCORD_DATA'!$B:$AS,13,FALSE) -> 0 | K24: =VLOOKUP(B24,'26MY_ACCORD_DATA'!B:AS,14,FALSE) -> N/A | L24: =VLOOKUP(B24,'26MY_ACCORD_DATA'!B:AS,15,FALSE) -> 0 | M24: =VLOOKUP(B24,'26MY_ACCORD_DATA'!B:AS,16,FALSE) -> N/A | N24: =VLOOKUP(B24,'26MY_ACCORD_DATA'!B:AS,17,FALSE) -> • | O24: =VLOOKUP($B24,'26MY_ACCORD_DATA'!$B:$AS,18,FALSE) -> 0 | P24: =VLOOKUP(B24,'26MY_ACCORD_DATA'!B:AS,19,FALSE) -> 0 | Q24: =IF(VLOOKUP(B24,'26MY_ACCORD_DATA'!B:AS,21,FALSE)="","",VLOOKUP(B24,'26MY_ACCORD_DATA'!B:AS,21,FALSE)) -> Rabais de 5 % appliqué.
B25: 08F20-30A-100C | C25: =VLOOKUP(B25,'26MY_ACCORD_DATA'!B:AS,4,FALSE) -> Emblème, noirs lustré arrière « H » mark | D25: =B25 -> 08F20-30A-100C
B26: 08F20-30A-100D | C26: =VLOOKUP(B26,'26MY_ACCORD_DATA'!B:AS,4,FALSE) -> Emblème, noirs lustré arrière « Accord » | D26: =B26 -> 08F20-30A-100D
B27: 08F20-3A0-100C | C27: =VLOOKUP(B27,'26MY_ACCORD_DATA'!B:AS,4,FALSE) -> Emblème, noirs lustré « Touring » | D27: =B27 -> 08F20-3A0-100C
B28: 08F20-T20-100B | C28: =VLOOKUP(B28,'26MY_ACCORD_DATA'!B:AS,4,FALSE) -> Emblème, noirs lustré « Hybride » | D28: =B28 -> 08F20-T20-100B
B30: 23ACC-ARO-EX | C30: =VLOOKUP(B30,'26MY_ACCORD_DATA'!B:AS,4,FALSE) -> Ensemble Aero – Version SE | D30: =B30 -> 23ACC-ARO-EX | E30: =VLOOKUP(B30,'26MY_ACCORD_DATA'!B:AS,9,FALSE) -> 1555.2 | F30: =VLOOKUP(B30,'26MY_ACCORD_DATA'!B:AS,10,FALSE) -> 2591.1 | G30: =VLOOKUP(B30,'26MY_ACCORD_DATA'!B:AS,7,FALSE) -> 3.5 | H30: =VLOOKUP(B30,'26MY_ACCORD_DATA'!B:AS,11,FALSE) -> 3123.1 | I30: =VLOOKUP(B30,'26MY_ACCORD_DATA'!B:AS,12,FALSE) -> 0 | J30: =VLOOKUP(B30,'26MY_ACCORD_DATA'!B:AS,13,FALSE) -> 0 | K30: =VLOOKUP(B30,'26MY_ACCORD_DATA'!B:AS,14,FALSE) -> • | L30: =VLOOKUP(B30,'26MY_ACCORD_DATA'!B:AS,15,FALSE) -> 0 | M30: =VLOOKUP(B30,'26MY_ACCORD_DATA'!B:AS,16,FALSE) -> N/A | N30: =VLOOKUP(B30,'26MY_ACCORD_DATA'!B:AS,17,FALSE) -> N/A | O30: =VLOOKUP(B30,'26MY_ACCORD_DATA'!B:AS,18,FALSE) -> 0 | P30: =VLOOKUP(B30,'26MY_ACCORD_DATA'!B:AS,19,FALSE) -> 0 | Q30: =IF(VLOOKUP(B30,'26MY_ACCORD_DATA'!B:AS,21,FALSE)="","",VLOOKUP(B30,'26MY_ACCORD_DATA'!B:AS,21,FALSE)) -> Rabais de 10 % est appliqué Déflecteur arrière de coffre - Noir cristal nacré couleur (NH-731P)
B31: 08F04-30A-1F0 | C31: =VLOOKUP(B31,'26MY_ACCORD_DATA'!B:AS,4,FALSE) -> Becquet de bas de caisse, latéral | D31: =B31 -> 08F04-30A-1F0
B32: 08P98-30A-1F0 | C32: =VLOOKUP(B32,'26MY_ACCORD_DATA'!B:AS,4,FALSE) -> Becquet de bas de caisse, avant | D32: =B32 -> 08P98-30A-1F0
B33: 08P99-30A-1F0 | C33: =VLOOKUP(B33,'26MY_ACCORD_DATA'!B:AS,4,FALSE) -> Becquet de bas de caisse, arrière | D33: =B33 -> 08P99-30A-1F0
B34: 08F10-30A-170 | C34: =VLOOKUP(B34,'26MY_ACCORD_DATA'!B:AS,4,FALSE) -> Noir cristal nacré (NH-731P) | D34: =B34 -> 08F10-30A-170
B35: 08R06-30A-110 | C35: =VLOOKUP(B35,'26MY_ACCORD_DATA'!B:AS,4,FALSE) -> Couvercle de rétroviseur de portière et élément inférieur d’admission d’air | D35: =B35 -> 08R06-30A-110
B37: 23ACC-ARO-SPHY | C37: =VLOOKUP(B37,'26MY_ACCORD_DATA'!B:AS,4,FALSE) -> Ensemble Aero – Version Sport | D37: =B37 -> 23ACC-ARO-SPHY | E37: =VLOOKUP(B37,'26MY_ACCORD_DATA'!B:AS,9,FALSE) -> 1018.8 | F37: =VLOOKUP(B37,'26MY_ACCORD_DATA'!B:AS,10,FALSE) -> 1697.4 | G37: =VLOOKUP(B37,'26MY_ACCORD_DATA'!B:AS,7,FALSE) -> 1.8 | H37: =VLOOKUP(B37,'26MY_ACCORD_DATA'!B:AS,11,FALSE) -> 1971 | I37: =VLOOKUP(B37,'26MY_ACCORD_DATA'!B:AS,12,FALSE) -> 0 | J37: =VLOOKUP(B37,'26MY_ACCORD_DATA'!B:AS,13,FALSE) -> 0 | K37: =VLOOKUP(B37,'26MY_ACCORD_DATA'!B:AS,14,FALSE) -> N/A | L37: =VLOOKUP(B37,'26MY_ACCORD_DATA'!B:AS,15,FALSE) -> 0 | M37: =VLOOKUP(B37,'26MY_ACCORD_DATA'!B:AS,16,FALSE) -> • | N37: =VLOOKUP(B37,'26MY_ACCORD_DATA'!B:AS,17,FALSE) -> N/A | O37: =VLOOKUP(B37,'26MY_ACCORD_DATA'!B:AS,18,FALSE) -> 0 | P37: =VLOOKUP(B37,'26MY_ACCORD_DATA'!B:AS,19,FALSE) -> 0 | Q37: =IF(VLOOKUP(B37,'26MY_ACCORD_DATA'!B:AS,21,FALSE)="","",VLOOKUP(B37,'26MY_ACCORD_DATA'!B:AS,21,FALSE)) -> Rabais de 10 % est appliqué Version Sport Hybride est livrée de série avec le becquet de bas de caisse, arrière
B38: 08F04-30A-1F0 | C38: =VLOOKUP(B38,'26MY_ACCORD_DATA'!B:AS,4,FALSE) -> Becquet de bas de caisse, latéral | D38: =B38 -> 08F04-30A-1F0
B39: 08P98-30A-1F0 | C39: =VLOOKUP(B39,'26MY_ACCORD_DATA'!B:AS,4,FALSE) -> Becquet de bas de caisse, avant | D39: =B39 -> 08P98-30A-1F0
B40: 08P99-30A-1F0 | C40: =VLOOKUP(B40,'26MY_ACCORD_DATA'!B:AS,4,FALSE) -> Becquet de bas de caisse, arrière | D40: =B40 -> 08P99-30A-1F0
B42: 23ACC-ARO-TRHY | C42: =VLOOKUP(B42,'26MY_ACCORD_DATA'!B:AS,4,FALSE) -> Ensemble Aero – Version Touring | D42: =B42 -> 23ACC-ARO-TRHY | E42: =VLOOKUP(B42,'26MY_ACCORD_DATA'!B:AS,9,FALSE) -> 1555.2 | F42: =VLOOKUP(B42,'26MY_ACCORD_DATA'!B:AS,10,FALSE) -> 2591.1 | G42: =VLOOKUP(B42,'26MY_ACCORD_DATA'!B:AS,7,FALSE) -> 3.5 | H42: =VLOOKUP(B42,'26MY_ACCORD_DATA'!B:AS,11,FALSE) -> 3123.1 | I42: =VLOOKUP(B42,'26MY_ACCORD_DATA'!B:AS,12,FALSE) -> 0 | J42: =VLOOKUP(B42,'26MY_ACCORD_DATA'!B:AS,13,FALSE) -> 0 | K42: =VLOOKUP(B42,'26MY_ACCORD_DATA'!B:AS,14,FALSE) -> N/A | L42: =VLOOKUP(B42,'26MY_ACCORD_DATA'!B:AS,15,FALSE) -> 0 | M42: =VLOOKUP(B42,'26MY_ACCORD_DATA'!B:AS,16,FALSE) -> N/A | N42: =VLOOKUP(B42,'26MY_ACCORD_DATA'!B:AS,17,FALSE) -> • | O42: =VLOOKUP(B42,'26MY_ACCORD_DATA'!B:AS,18,FALSE) -> 0 | P42: =VLOOKUP(B42,'26MY_ACCORD_DATA'!B:AS,19,FALSE) -> 0 | Q42: =IF(VLOOKUP(B42,'26MY_ACCORD_DATA'!B:AS,21,FALSE)="","",VLOOKUP(B42,'26MY_ACCORD_DATA'!B:AS,21,FALSE)) -> Rabais de 10 % est appliqué Déflecteur arrière de coffre - Noir cristal nacré couleur (NH-731P)
B43: 08F04-30A-1F0 | C43: =VLOOKUP(B43,'26MY_ACCORD_DATA'!B:AS,4,FALSE) -> Becquet de bas de caisse, latéral | D43: =B43 -> 08F04-30A-1F0
B44: 08P98-30A-1F0 | C44: =VLOOKUP(B44,'26MY_ACCORD_DATA'!B:AS,4,FALSE) -> Becquet de bas de caisse, avant | D44: =B44 -> 08P98-30A-1F0
B45: 08P99-30A-1F0 | C45: =VLOOKUP(B45,'26MY_ACCORD_DATA'!B:AS,4,FALSE) -> Becquet de bas de caisse, arrière | D45: =B45 -> 08P99-30A-1F0
B46: 08F10-30A-170 | C46: =VLOOKUP(B46,'26MY_ACCORD_DATA'!B:AS,4,FALSE) -> Noir cristal nacré (NH-731P) | D46: =B46 -> 08F10-30A-170
B47: 08R06-30A-110A | C47: =VLOOKUP(B47,'26MY_ACCORD_DATA'!B:AS,4,FALSE) -> Couvercle de rétroviseur de portière et élément inférieur d’admission d’air | D47: =B47 -> 08R06-30A-110A
...

Sheet 26MY_ACCORD_SELL_EN
B3: 26MY Honda Accord
B4: 200
B6: POPULAR ACCESSORIES
B7: 20
B8: 150
B10: 20 | C10: ='26MY_ACCORD_APP_EN'!$C$117 -> All Season Floor Mats | H10: ='26MY_ACCORD_APP_EN'!$C$118 -> Trunk Tray | M10: ='26MY_ACCORD_APP_EN'!$C$130 -> Auto Day/Night Mirror with Home Link
B11: 20 | C11: ='26MY_ACCORD_APP_EN'!$H$117 -> 307.2 | D11: =-PMT($D$29/52,5*52,C11) -> 1.4008009 | E11: /wk * | F11: =$C$29 -> (6.99%) | H11: ='26MY_ACCORD_APP_EN'!$H$118 -> 230.2 | I11: =-PMT($D$29/52,5*52,H11) -> 1.0496887 | J11: /wk * | K11: =$C$29 -> (6.99%) | M11: ='26MY_ACCORD_APP_EN'!$H$130+'26MY_ACCORD_APP_EN'!$H$131 -> 701.6 | N11: =-PMT($D$29/52,5*52,M11) -> 3.199225 | O11: /wk * | P11: =$C$29 -> (6.99%)
B13: 150
B15: 20 | C15: ='26MY_ACCORD_APP_EN'!$C$82 -> Door Visors | H15: ='26MY_ACCORD_APP_EN'!$C$61 -> 19" HPD Alloy Wheels, Black | M15: ='26MY_ACCORD_APP_EN'!$C$75 -> Black Emblem Rear "H" mark | N15: Ambient Lighting, Blue | O15: Ambient Lighting, Blue | P15: Ambient Lighting, Blue
B16: 50 | C16: ='26MY_ACCORD_APP_EN'!$H$82 -> 409 | D16: =-PMT($D$29/52,5*52,C16) -> 1.8649986 | E16: /wk * | F16: =$C$29 -> (6.99%) | H16: ='26MY_ACCORD_APP_EN'!$H$61 -> 3999.2 | I16: =-PMT($D$29/52,5*52,H16) -> 18.235947 | J16: /wk * | K16: =$C$29 -> (6.99%) | M16: ='26MY_ACCORD_APP_EN'!$H$75 -> 92.4 | N16: =-PMT($D$29/52,5*52,M16) -> 0.42133465 | O16: /wk * | P16: =$C$29 -> (6.99%)
B18: 150
B20: 20 | C20: ='26MY_ACCORD_APP_EN'!$C$95 -> Body Side Moulding | H20: ='26MY_ACCORD_APP_EN'!$C$132 -> Engine Block Heater | M20: ='26MY_ACCORD_APP_EN'!$C$42 -> Aero Kit - Touring Trim
B21: 50 | C21: ='26MY_ACCORD_APP_EN'!$H$96 -> 447.8 | D21: =-PMT($D$29/52,5*52,C21) -> 2.0419227 | E21: /wk * | F21: =$C$29 -> (6.99%) | H21: ='26MY_ACCORD_APP_EN'!$H$132 -> 422.4 | I21: =-PMT($D$29/52,5*52,H21) -> 1.9261013 | J21: /wk * | K21: =$C$29 -> (6.99%) | M21: =SUM('26MY_ACCORD_APP_EN'!$H$42:$H$47) -> 3123.1 | N21: =-PMT($D$29/52,5*52,M21) -> 14.24102 | O21: /wk * | P21: =$C$29 -> (6.99%)
C23: Genuine Honda Accessories purchased with a new Honda vehicle include a 3 year / 60,000 km manufacturer's warranty.
C24: Vehicle accessories purchased after vehicle sale include a 1 year / 20,000km manufacturer's warranty.
B25: 20 | C25: *Prices shown include the cost of installation.
B26: 60 | C26: *For informational purposes only. Weekly amounts shown are estimated payments based on a 60 month finance contract at 6.99% APR (including the cost of installation). Applicable taxes and fees are extra. Accessories cannot be financed on their own and must be financed through Honda Canada Finance Inc., on approved credit, in conjunction with a Honda vehicle. Representative finance example: $350.00 financed at 6.99% APR equals $1.60 weekly for 60 months. 260 weekly payments required. Cost of borrowing is $64.80 for a total obligation of $414.80. Actual payment amounts will vary based on APR, finance contract term and cost of the applicable accessories. Conditions apply. See your Honda dealer for full details.
C27: *More customized weekly payment options & accessories can be seen on Honda.ca - Build & Price
B28: 20
B29: 18 | C29: (6.99%) | D29: 0.0699
B30: 7.5 | C30: 12 | D30: 8 | E30: 8 | F30: 10 | G30: 8.5 | H30: 12 | I30: 8 | J30: 8 | K30: 10 | L30: 8.5 | M30: 12 | N30: 8 | O30: 8 | P30: 10 | Q30: 7.5
B31: Publication Date: | C31: ='26MY_ACCORD_DATA'!$C$4 -> 46113 | D31: ='SELECT PROVINCE'!$A$23 -> All published prices, trim specifications, and availability are subject to change without prior notice. | P31: Province | Q31: ='26MY_ACCORD_DATA'!L6 -> QC

Sheet 26MY_ACCORD_SELL_FR
B3: 26MY Accord
B4: 200
B6: ACCESSOIRES POPULAIRES
B7: 20
B8: 150
B10: 20 | C10: ='26MY_ACCORD_APP_FR'!$C$117 -> Protège-tapis toutes saisons | H10: ='26MY_ACCORD_APP_FR'!$C$120 -> Filet de cargaison | M10: ='26MY_ACCORD_APP_FR'!$C$130 -> Rétroviseur automatique jour/nuit avec HomeLink
B11: 20 | C11: ='26MY_ACCORD_APP_FR'!$H$117 -> 307.2 | D11: =-PMT($D$29/52,5*52,C11) -> 1.4008009 | E11: /wk * | F11: =$C$29 -> (6.99%) | H11: ='26MY_ACCORD_APP_FR'!$H$120 -> 118.8 | I11: =-PMT($D$29/52,5*52,H11) -> 0.54171598 | J11: /wk * | K11: =$C$29 -> (6.99%) | M11: =('26MY_ACCORD_APP_FR'!H130+'26MY_ACCORD_APP_FR'!H131) -> 701.6 | N11: =-PMT($D$29/52,5*52,M11) -> 3.199225 | O11: /wk * | P11: =$C$29 -> (6.99%)
B13: 150
B15: 20 | C15: ='26MY_ACCORD_APP_FR'!$C$82 -> Déflecteurs de portières | H15: ='26MY_ACCORD_APP_FR'!$C$61 -> Jantes de 19 pouces HPD en alliage noir | M15: ='26MY_ACCORD_APP_FR'!$C$75 -> Emblème, noirs lustré arrière « H » mark | N15: Ambient Lighting, Blue | O15: Ambient Lighting, Blue | P15: Ambient Lighting, Blue
B16: 50 | C16: ='26MY_ACCORD_APP_FR'!$H$82 -> 409 | D16: =-PMT($D$29/52,5*52,C16) -> 1.8649986 | E16: /wk * | F16: =$C$29 -> (6.99%) | H16: ='26MY_ACCORD_APP_FR'!$H$61 -> 3999.2 | I16: =-PMT($D$29/52,5*52,H16) -> 18.235947 | J16: /wk * | K16: =$C$29 -> (6.99%) | M16: ='26MY_ACCORD_APP_FR'!$H$75 -> 92.4 | N16: =-PMT($D$29/52,5*52,M16) -> 0.42133465 | O16: /wk * | P16: =$C$29 -> (6.99%)
B18: 150
B20: 20 | C20: ='26MY_ACCORD_APP_FR'!$C$95 -> Moulure latérale | H20: ='26MY_ACCORD_APP_FR'!$C$132 -> Chauffe-moteur | M20: ='26MY_ACCORD_APP_FR'!$C$42 -> Ensemble Aero – Version Touring
B21: 50 | C21: ='26MY_ACCORD_APP_FR'!H96+'26MY_ACCORD_APP_FR'!$H$96 -> 895.6 | D21: =-PMT($D$29/52,5*52,C21) -> 4.0838454 | E21: /wk * | F21: =$C$29 -> (6.99%) | H21: ='26MY_ACCORD_APP_FR'!$H$132 -> 422.4 | I21: =-PMT($D$29/52,5*52,H21) -> 1.9261013 | J21: /wk * | K21: =$C$29 -> (6.99%) | M21: =SUM('26MY_ACCORD_APP_FR'!$H$42:$H$47) -> 3123.1 | N21: =-PMT($D$29/52,5*52,M21) -> 14.24102 | O21: /wk * | P21: =$C$29 -> (6.99%)
C23: Les accessoires Honda d’origine achetés avec un véhicule Honda neuf incluent une garantie du fabricant de 3 ans ou 60 000 km.
C24: Les accessoires de véhicule achetés après la vente du véhicule incluent une garantie du fabricant de 1 an ou 20 000 km.
B25: 20 | C25: *Les prix indiqués incluent le coût d'installation.
B26: 60 | C26: *À titre d’information seulement. Les montants hebdomadaires indiqués sont des paiements estimés basés sur un contrat de financement de 60 mois à un taux annuel en pourcentage (TAP) de 6,99 % (coût d’installation compris). Taxes et frais applicables en sus. Les accessoires ne peuvent être financés seuls et doivent être financés par l’entremise de Honda Canada Finance Inc., sur approbation de crédit, conjointement avec un véhicule Honda. Exemple de financement représentatif : Un montant de 350,00 $ financé à un TAP de 6,99 % équivaut à un paiement hebdomadaire de 1,60 $ pendant 60 mois. 260 paiements hebdomadaires sont requis. Le coût d’emprunt est de 64,80 $, pour une obligation totale de 414,80 $. Le montant réel des paiements variera en fonction du TAP, de la période du contrat de financement et du coût des accessoires applicables. Certaines conditions s’appliquent. Veuillez visiter votre concessionnaire Honda pour obtenir tous les détails.
C27: *Vous pouvez voir d’autres options de paiements hebdomadaires personnalisés ainsi que des accessoires sur le site Honda.ca – Configuration et prix.
B28: 20
B29: 18 | C29: (6.99%) | D29: 0.0699
B30: 7.5 | C30: 12 | D30: 8 | E30: 8 | F30: 10 | G30: 8.5 | H30: 12 | I30: 8 | J30: 8 | K30: 10 | L30: 8.5 | M30: 12 | N30: 8 | O30: 8 | P30: 10 | Q30: 7.5
B31: Date de publication: | C31: ='26MY_ACCORD_DATA'!$C$4 -> 46113 | D31: Tout prix, spécifications de versions et disponibilté d'accessoires publiés sont sujets à changer sans pré-avis. | P31: Province | Q31: ='26MY_ACCORD_DATA'!L6 -> QC
