Workbook
Name prov_cd: 'SELECT PROVINCE'!$B$1
Name province_codes: 'SELECT PROVINCE'!$B$6:$B$16
Name rate_table: 'SELECT PROVINCE'!$B$6:$C$16

Sheet SELECT PROVINCE
A1: Select Province: Choissisez votre province: | B1: YT
B4: Current Labor Rates
B5: Taux de main d'oeuvre en cours
B6: AB | C6: 162
B7: BC | C7: 168
B8: MB | C8: 155
B9: NB | C9: 130
B10: NL | C10: 130
B11: NS | C11: 130
B12: ON | C12: 150 | F12: =prov_cd -> YT
B13: PEI | C13: 125
B14: QC | C14: 140
B15: SK | C15: 155
B16: YT | C16: 168
A23: All published prices, trim specifications, and availability are subject to change without prior notice.
A24: Tout prix, spécifications de versions et disponibilté d'accessoires publiés sont sujets à changer sans pré-avis.

Sheet 26MY_CIV5D_APP_EN
B2: Honda Internal | C2: Honda Accessories
C3: Model Name | D3: ='[1]26MY_CIV5D_DATA'!C2 -> Civic Hatch
C4: Model Year | D4: ='[1]26MY_CIV5D_DATA'!$C$3 -> 2026
C5: S = Standard (accessory comes standard on this trim)
C6: T = Tire Size Change (the size of the accessory wheel is smaller/larger than the OE Wheel. Customer will require new tires to fit these wheels.)
C7: E = Exchange Standard Equipment (the size of the accessory wheel is the same size as the OE wheel and therefore they can use the OE tire.)
C8: N/A = Not Applicable (accessory cannot be applied to this trim)
H10: Province
C11: 1.0 Packages and Kits | H11: =prov_cd -> YT
C12: Description | D12: Part Number | E12: Dealer Net | F12: List Price | G12: FRT | H12: Installed Price | I12: Application | Q12: Comments
I13: ='[1]26MY_CIV5D_DATA'!M$7 -> 0 | J13: ='[1]26MY_CIV5D_DATA'!N$7 -> 0 | K13: ='[1]26MY_CIV5D_DATA'!O$7 -> 0 | L13: ='[1]26MY_CIV5D_DATA'!P$7 -> SPORT | M13: ='[1]26MY_CIV5D_DATA'!Q$7 -> SPORT Hybrid | N13: ='[1]26MY_CIV5D_DATA'!R$7 -> 0 | O13: ='[1]26MY_CIV5D_DATA'!S$7 -> Sport Touring Hybrid | P13: ='[1]26MY_CIV5D_DATA'!T$7 -> Type R
B14: 25CIV-ENK-WTPK | C14: =VLOOKUP(B14,'[1]26MY_CIV5D_DATA'!B:AS,3,FALSE) -> 16” Enkei M52 Wheels & Michelin X-ICE Snow Tire Package | E14: =VLOOKUP(B14,'[1]26MY_CIV5D_DATA'!B:AS,9,FALSE) -> 1556.88 | F14: =VLOOKUP(B14,'[1]26MY_CIV5D_DATA'!B:AS,10,FALSE) -> 1980 | G14: =VLOOKUP(B14,'[1]26MY_CIV5D_DATA'!B:AS,7,FALSE) -> 1.2 | H14: =VLOOKUP(B14,'[1]26MY_CIV5D_DATA'!B:AS,11,FALSE) -> 2181.6 | I14: =VLOOKUP(B14,'[1]26MY_CIV5D_DATA'!B:AS,12,FALSE) -> 0 | J14: =VLOOKUP(B14,'[1]26MY_CIV5D_DATA'!B:AS,13,FALSE) -> 0 | K14: =VLOOKUP($B14,'[1]26MY_CIV5D_DATA'!$B:$AS,14,FALSE) -> 0 | L14: =VLOOKUP(B14,'[1]26MY_CIV5D_DATA'!B:AS,15,FALSE) -> • | M14: =VLOOKUP(B14,'[1]26MY_CIV5D_DATA'!B:AS,16,FALSE) -> N/A | N14: =VLOOKUP($B14,'[1]26MY_CIV5D_DATA'!$B:$AS,17,FALSE) -> 0 | O14: =VLOOKUP(B14,'[1]26MY_CIV5D_DATA'!B:AS,18,FALSE) -> N/A | P14: =VLOOKUP(B14,'[1]26MY_CIV5D_DATA'!B:AS,19,FALSE) -> N/A | Q14: =IF(VLOOKUP(B14,'[1]26MY_CIV5D_DATA'!B:AS,20,FALSE)="","",VLOOKUP(B14,'[1]26MY_CIV5D_DATA'!B:AS,20,FALSE)) -> Priced as a set of 4 wheels.
B15: 480-670-6545-SP or 480-670-6545-GB | C15: =VLOOKUP(B15,'[1]26MY_CIV5D_DATA'!B:AS,3,FALSE) -> 16" Enkei M52 Wheels - Silver or Gloss Black | D15: =B15 -> 480-670-6545-SP or 480-670-6545-GB
B16: 34417 | C16: =VLOOKUP(B16,'[1]26MY_CIV5D_DATA'!B:AS,3,FALSE) -> Michelin X-ICE Snow Tires - 215/55/16 | D16: =B16 -> 34417
B18: 25CIV-STL-WTPK | C18: =VLOOKUP(B18,'[1]26MY_CIV5D_DATA'!B:AS,3,FALSE) -> 16” Winter Steel Wheels & Michelin X-ICE Snow Tire Package | E18: =VLOOKUP(B18,'[1]26MY_CIV5D_DATA'!B:AS,9,FALSE) -> 1124.48 | F18: =VLOOKUP(B18,'[1]26MY_CIV5D_DATA'!B:AS,10,FALSE) -> 1492.48 | G18: =VLOOKUP(B18,'[1]26MY_CIV5D_DATA'!B:AS,7,FALSE) -> 1.2 | H18: =VLOOKUP(B18,'[1]26MY_CIV5D_DATA'!B:AS,11,FALSE) -> 1694.08 | I18: =VLOOKUP(B18,'[1]26MY_CIV5D_DATA'!B:AS,12,FALSE) -> 0 | J18: =VLOOKUP(B18,'[1]26MY_CIV5D_DATA'!B:AS,13,FALSE) -> 0 | K18: =VLOOKUP($B18,'[1]26MY_CIV5D_DATA'!$B:$AS,14,FALSE) -> 0 | L18: =VLOOKUP(B18,'[1]26MY_CIV5D_DATA'!B:AS,15,FALSE) -> • | M18: =VLOOKUP(B18,'[1]26MY_CIV5D_DATA'!B:AS,16,FALSE) -> N/A | N18: =VLOOKUP($B18,'[1]26MY_CIV5D_DATA'!$B:$AS,17,FALSE) -> 0 | O18: =VLOOKUP(B18,'[1]26MY_CIV5D_DATA'!B:AS,18,FALSE) -> N/A | P18: =VLOOKUP(B18,'[1]26MY_CIV5D_DATA'!B:AS,19,FALSE) -> N/A | Q18: =IF(VLOOKUP(B18,'[1]26MY_CIV5D_DATA'!B:AS,20,FALSE)="","",VLOOKUP(B18,'[1]26MY_CIV5D_DATA'!B:AS,20,FALSE)) -> Priced as a set of 4 wheels.
B19: 42700-TBA-A12 | C19: =VLOOKUP(B19,'[1]26MY_CIV5D_DATA'!B:AS,3,FALSE) -> 16” Winter Steel Wheels | D19: =B19 -> 42700-TBA-A12
B20: 34417 | C20: =VLOOKUP(B20,'[1]26MY_CIV5D_DATA'!B:AS,3,FALSE) -> Michelin X-ICE Snow Tires - 215/55/16 | D20: =B20 -> 34417
B22: 25CIV5-ARO-PK | C22: =VLOOKUP(B22,'[1]26MY_CIV5D_DATA'!B:AS,3,FALSE) -> Aero Kit | E22: =VLOOKUP(B22,'[1]26MY_CIV5D_DATA'!B:AS,9,FALSE) -> 643.5 | F22: =VLOOKUP(B22,'[1]26MY_CIV5D_DATA'!B:AS,10,FALSE) -> 1072.8 | G22: =VLOOKUP(B22,'[1]26MY_CIV5D_DATA'!B:AS,7,FALSE) -> 2.2 | H22: =VLOOKUP(B22,'[1]26MY_CIV5D_DATA'!B:AS,11,FALSE) -> 1442.4 | I22: =VLOOKUP(B22,'[1]26MY_CIV5D_DATA'!B:AS,12,FALSE) -> 0 | J22: =VLOOKUP(B22,'[1]26MY_CIV5D_DATA'!B:AS,13,FALSE) -> 0 | K22: =VLOOKUP($B22,'[1]26MY_CIV5D_DATA'!$B:$AS,14,FALSE) -> 0 | L22: =VLOOKUP(B22,'[1]26MY_CIV5D_DATA'!B:AS,15,FALSE) -> • | M22: =VLOOKUP(B22,'[1]26MY_CIV5D_DATA'!B:AS,16,FALSE) -> • | N22: =VLOOKUP($B22,'[1]26MY_CIV5D_DATA'!$B:$AS,17,FALSE) -> 0 | O22: =VLOOKUP(B22,'[1]26MY_CIV5D_DATA'!B:AS,18,FALSE) -> • | P22: =VLOOKUP(B22,'[1]26MY_CIV5D_DATA'!B:AS,19,FALSE) -> N/A | Q22: =IF(VLOOKUP(B22,'[1]26MY_CIV5D_DATA'!B:AS,20,FALSE)="","",VLOOKUP(B22,'[1]26MY_CIV5D_DATA'!B:AS,20,FALSE)) -> 10% Discount Applied. Includes body coloured front underbody spoiler and tailgate spoiler.
B23: 25CIV-5AR-NH883 | C23: =VLOOKUP(B23,'[1]26MY_CIV5D_DATA'!B:AS,3,FALSE) -> Platinum White Pearl (NH-883P) | D23: =B23 -> 25CIV-5AR-NH883
B24: 25CIV-5AR-NH932 | C24: =VLOOKUP(B24,'[1]26MY_CIV5D_DATA'!B:AS,3,FALSE) -> Solar Reflection Silver (NH-932M) | D24: =B24 -> 25CIV-5AR-NH932
B25: 25CIV-5AR-NH904 | C25: =VLOOKUP(B25,'[1]26MY_CIV5D_DATA'!B:AS,3,FALSE) -> Meteoroid Gray Pearl (NH-904M) | D25: =B25 -> 25CIV-5AR-NH904
B26: 25CIV-5AR-NH912 | C26: =VLOOKUP(B26,'[1]26MY_CIV5D_DATA'!B:AS,3,FALSE) -> Urban Grey Pearl (NH-912P) | D26: =B26 -> 25CIV-5AR-NH912
B27: 25CIV-5AR-NH731 | C27: =VLOOKUP(B27,'[1]26MY_CIV5D_DATA'!B:AS,3,FALSE) -> Crystal Black Pearl (NH-731P) | D27: =B27 -> 25CIV-5AR-NH731
B28: 25CIV-5AR-R513 | C28: =VLOOKUP(B28,'[1]26MY_CIV5D_DATA'!B:AS,3,FALSE) -> Rallye Red (R-513) | D28: =B28 -> 25CIV-5AR-R513
B29: 25CIV-5AR-B637 | C29: =VLOOKUP(B29,'[1]26MY_CIV5D_DATA'!B:AS,3,FALSE) -> Boost Blue Pearl (B-637P) | D29: =B29 -> 25CIV-5AR-B637
B31: 22CIV-COLD-PK20 | C31: =VLOOKUP(B31,'[1]26MY_CIV5D_DATA'!B:AS,3,FALSE) -> Cold Weather Package - 2.0L | D31: =B31 -> 22CIV-COLD-PK20 | E31: =VLOOKUP(B31,'[1]26MY_CIV5D_DATA'!B:AS,9,FALSE) -> 224.2 | F31: =VLOOKUP(B31,'[1]26MY_CIV5D_DATA'!B:AS,10,FALSE) -> 374.3 | G31: =VLOOKUP(B31,'[1]26MY_CIV5D_DATA'!B:AS,7,FALSE) -> 1.4 | H31: =VLOOKUP(B31,'[1]26MY_CIV5D_DATA'!B:AS,11,FALSE) -> 609.5 | I31: =VLOOKUP(B31,'[1]26MY_CIV5D_DATA'!B:AS,12,FALSE) -> 0 | J31: =VLOOKUP(B31,'[1]26MY_CIV5D_DATA'!B:AS,13,FALSE) -> 0 | K31: =VLOOKUP($B31,'[1]26MY_CIV5D_DATA'!$B:$AS,14,FALSE) -> 0 | L31: =VLOOKUP(B31,'[1]26MY_CIV5D_DATA'!B:AS,15,FALSE) -> • | M31: =VLOOKUP(B31,'[1]26MY_CIV5D_DATA'!B:AS,16,FALSE) -> • | N31: =VLOOKUP($B31,'[1]26MY_CIV5D_DATA'!$B:$AS,17,FALSE) -> 0 | O31: =VLOOKUP(B31,'[1]26MY_CIV5D_DATA'!B:AS,18,FALSE) -> • | P31: =VLOOKUP(B31,'[1]26MY_CIV5D_DATA'!B:AS,19,FALSE) -> N/A | Q31: =IF(VLOOKUP(B31,'[1]26MY_CIV5D_DATA'!B:AS,20,FALSE)="","",VLOOKUP(B31,'[1]26MY_CIV5D_DATA'!B:AS,20,FALSE)) -> 5% Discount Applied.
B32: 08T44-SNA-302 | C32: =VLOOKUP(B32,'[1]26MY_CIV5D_DATA'!B:AS,3,FALSE) -> Engine Block Heater - 2.0L | D32: =B32 -> 08T44-SNA-302
B33: 31670-BMS-004H | C33: =VLOOKUP(B33,'[1]26MY_CIV5D_DATA'!B:AS,3,FALSE) -> Optimate 12V Auto Battery Charger/Maintainer | D33: =B33 -> 31670-BMS-004H
B35: 25CIV5D-PRO-PET | C35: =VLOOKUP(B35,'[1]26MY_CIV5D_DATA'!B:AS,3,FALSE) -> Protection Package - Petrol | D35: =B35 -> 25CIV5D-PRO-PET | E35: =VLOOKUP(B35,'[1]26MY_CIV5D_DATA'!B:AS,9,FALSE) -> 288.9 | F35: =VLOOKUP(B35,'[1]26MY_CIV5D_DATA'!B:AS,10,FALSE) -> 536 | G35: =VLOOKUP(B35,'[1]26MY_CIV5D_DATA'!B:AS,7,FALSE) -> 0.6 | H35: =VLOOKUP(B35,'[1]26MY_CIV5D_DATA'!B:AS,11,FALSE) -> 636.8 | I35: =VLOOKUP(B35,'[1]26MY_CIV5D_DATA'!B:AS,12,FALSE) -> 0 | J35: =VLOOKUP(B35,'[1]26MY_CIV5D_DATA'!B:AS,13,FALSE) -> 0 | K35: =VLOOKUP($B35,'[1]26MY_CIV5D_DATA'!$B:$AS,14,FALSE) -> 0 | L35: =VLOOKUP(B35,'[1]26MY_CIV5D_DATA'!B:AS,15,FALSE) -> • | M35: =VLOOKUP(B35,'[1]26MY_CIV5D_DATA'!B:AS,16,FALSE) -> N/A | N35: =VLOOKUP($B35,'[1]26MY_CIV5D_DATA'!$B:$AS,17,FALSE) -> 0 | O35: =VLOOKUP(B35,'[1]26MY_CIV5D_DATA'!B:AS,18,FALSE) -> N/A | P35: =VLOOKUP(B35,'[1]26MY_CIV5D_DATA'!B:AS,19,FALSE) -> N/A | Q35: =IF(VLOOKUP(B35,'[1]26MY_CIV5D_DATA'!B:AS,20,FALSE)="","",VLOOKUP(B35,'[1]26MY_CIV5D_DATA'!B:AS,20,FALSE))
B36: 08P17-T20-110 | C36: =VLOOKUP(B36,'[1]26MY_CIV5D_DATA'!B:AS,3,FALSE) -> Floor Mats - All-Season | D36: =B36 -> 08P17-T20-110
B37: 08U45-T47-100B | C37: =VLOOKUP(B37,'[1]26MY_CIV5D_DATA'!B:AS,3,FALSE) -> Cargo Tray | D37: =B37 -> 08U45-T47-100B
B38: 08P09-T47-300 | C38: =VLOOKUP(B38,'[1]26MY_CIV5D_DATA'!B:AS,3,FALSE) -> Splash Guards - Rear | D38: =B38 -> 08P09-T47-300
B40: 25CIV5-PRO-HYB | C40: =VLOOKUP(B40,'[1]26MY_CIV5D_DATA'!B:AS,3,FALSE) -> Protection Package - Hybrid | D40: =B40 -> 25CIV5-PRO-HYB | E40: =VLOOKUP(B40,'[1]26MY_CIV5D_DATA'!B:AS,9,FALSE) -> 288.9 | F40: =VLOOKUP(B40,'[1]26MY_CIV5D_DATA'!B:AS,10,FALSE) -> 536 | G40: =VLOOKUP(B40,'[1]26MY_CIV5D_DATA'!B:AS,7,FALSE) -> 0.6 | H40: 602 | I40: =VLOOKUP(B40,'[1]26MY_CIV5D_DATA'!B:AS,12,FALSE) -> 0 | J40: =VLOOKUP(B40,'[1]26MY_CIV5D_DATA'!B:AS,13,FALSE) -> 0 | K40: =VLOOKUP($B40,'[1]26MY_CIV5D_DATA'!$B:$AS,14,FALSE) -> 0 | L40: =VLOOKUP(B40,'[1]26MY_CIV5D_DATA'!B:AS,15,FALSE) -> N/A | M40: =VLOOKUP(B40,'[1]26MY_CIV5D_DATA'!B:AS,16,FALSE) -> • | N40: =VLOOKUP($B40,'[1]26MY_CIV5D_DATA'!$B:$AS,17,FALSE) -> 0 | O40: =VLOOKUP(B40,'[1]26MY_CIV5D_DATA'!B:AS,18,FALSE) -> • | P40: =VLOOKUP(B40,'[1]26MY_CIV5D_DATA'!B:AS,19,FALSE) -> N/A | Q40: =IF(VLOOKUP(B40,'[1]26MY_CIV5D_DATA'!B:AS,20,FALSE)="","",VLOOKUP(B40,'[1]26MY_CIV5D_DATA'!B:AS,20,FALSE))
B41: 08P17-T20-110A | C41: =VLOOKUP(B41,'[1]26MY_CIV5D_DATA'!B:AS,3,FALSE) -> Floor Mats Hybrid - All-Season | D41: =B41 -> 08P17-T20-110A
B42: 08U45-T47-100B | C42: =VLOOKUP(B42,'[1]26MY_CIV5D_DATA'!B:AS,3,FALSE) -> Cargo Tray | D42: =B42 -> 08U45-T47-100B
B43: 08P09-T47-300 | C43: =VLOOKUP(B43,'[1]26MY_CIV5D_DATA'!B:AS,3,FALSE) -> Splash Guards - Rear | D43: =B43 -> 08P09-T47-300
B45: 25CIV5-PRO-FLM | C45: =VLOOKUP(B45,'[1]26MY_CIV5D_DATA'!B:AS,3,FALSE) -> Protection Package - Film | D45: =B45 -> 25CIV5-PRO-FLM | E45: =VLOOKUP(B45,'[1]26MY_CIV5D_DATA'!B:AS,9,FALSE) -> 198.9 | F45: =VLOOKUP(B45,'[1]26MY_CIV5D_DATA'!B:AS,10,FALSE) -> 319.5 | G45: =VLOOKUP(B45,'[1]26MY_CIV5D_DATA'!B:AS,7,FALSE) -> 1 | H45: =VLOOKUP(B45,'[1]26MY_CIV5D_DATA'!B:AS,11,FALSE) -> 487.5 | I45: =VLOOKUP(B45,'[1]26MY_CIV5D_DATA'!B:AS,12,FALSE) -> 0 | J45: =VLOOKUP(B45,'[1]26MY_CIV5D_DATA'!B:AS,13,FALSE) -> 0 | K45: =VLOOKUP($B45,'[1]26MY_CIV5D_DATA'!$B:$AS,14,FALSE) -> 0 | L45: =VLOOKUP(B45,'[1]26MY_CIV5D_DATA'!B:AS,15,FALSE) -> • | M45: =VLOOKUP(B45,'[1]26MY_CIV5D_DATA'!B:AS,16,FALSE) -> • | N45: =VLOOKUP($B45,'[1]26MY_CIV5D_DATA'!$B:$AS,17,FALSE) -> 0 | O45: =VLOOKUP(B45,'[1]26MY_CIV5D_DATA'!B:AS,18,FALSE) -> • | P45: =VLOOKUP(B45,'[1]26MY_CIV5D_DATA'!B:AS,19,FALSE) -> N/A | Q45: =IF(VLOOKUP(B45,'[1]26MY_CIV5D_DATA'!B:AS,20,FALSE)="","",VLOOKUP(B45,'[1]26MY_CIV5D_DATA'!B:AS,20,FALSE)) -> 10% Discount Applied. Cannot be installed with Door Edge Guards
B46: 08P04-T20-100 | C46: =VLOOKUP(B46,'[1]26MY_CIV5D_DATA'!B:AS,3,FALSE) -> Door Sill Protection Film | D46: =B46 -> 08P04-T20-100
B47: 08P20-T20-100A | C47: =VLOOKUP(B47,'[1]26MY_CIV5D_DATA'!B:AS,3,FALSE) -> Door Edge Film | D47: =B47 -> 08P20-T20-100A
B48: 08P01-T47-100 | C48: =VLOOKUP(B48,'[1]26MY_CIV5D_DATA'!B:AS,3,FALSE) -> Rear Bumper Protector | D48: =B48 -> 08P01-T47-100
...

Sheet 26MY_CIV5D_APP_FR
B2: Honda Internal | C2: Accessoires Honda
C3: Nom du modèle | D3: ='[1]26MY_CIV5D_DATA'!$D$2 -> Civic à Hayon
C4: Année modèle | D4: ='[1]26MY_CIV5D_DATA'!$C$3 -> 2026
C5: S = De série (accessoire de série sur cette version).
C6: T = Taille des pneus (la taille de la jante accessoire diffère de la jante d’origine. Le client aura besoin de nouveaux pneus pour ces jantes).
C7: E = Échange d’équipement de série (la taille de la jante accessoire est la même que celle de la jante d’origine. Le client peut utiliser les pneus d’origine).
C8: N/A = Sans objet (l’accessoire ne peut être utilisé pour cette version).
H10: Province
C11: 1.0 Groupes et ensembles | H11: =prov_cd -> YT
C12: La description | D12: Numéro de pièce | E12: Prix net | F12: Prix de liste | G12: T.F.F. | H12: Prix installé | I12: Application | Q12: Commentaires
I13: ='[1]26MY_CIV5D_DATA'!M$6 -> 0 | J13: ='[1]26MY_CIV5D_DATA'!N$6 -> 0 | K13: ='[1]26MY_CIV5D_DATA'!O$6 -> 0 | L13: ='[1]26MY_CIV5D_DATA'!P$6 -> SPORT | M13: ='[1]26MY_CIV5D_DATA'!Q$6 -> SPORT Hybride | N13: ='[1]26MY_CIV5D_DATA'!R$6 -> 0 | O13: ='[1]26MY_CIV5D_DATA'!S$6 -> Sport Touring Hybride | P13: ='[1]26MY_CIV5D_DATA'!T$6 -> Type R
B14: 25CIV-ENK-WTPK | C14: =VLOOKUP(B14,'[1]26MY_CIV5D_DATA'!B:AS,4,FALSE) -> Ensemble de roues Enkei M52 de 16 po et de pneus Michelin X-ICE Snow | E14: =VLOOKUP(B14,'[1]26MY_CIV5D_DATA'!B:AS,9,FALSE) -> 1556.88 | F14: =VLOOKUP(B14,'[1]26MY_CIV5D_DATA'!B:AS,10,FALSE) -> 1980 | G14: =VLOOKUP(B14,'[1]26MY_CIV5D_DATA'!B:AS,7,FALSE) -> 1.2 | H14: =VLOOKUP(B14,'[1]26MY_CIV5D_DATA'!B:AS,11,FALSE) -> 2181.6 | I14: =VLOOKUP(B14,'[1]26MY_CIV5D_DATA'!B:AS,12,FALSE) -> 0 | J14: =VLOOKUP(B14,'[1]26MY_CIV5D_DATA'!B:AS,13,FALSE) -> 0 | K14: =VLOOKUP($B14,'[1]26MY_CIV5D_DATA'!$B:$AS,14,FALSE) -> 0 | L14: =VLOOKUP(B14,'[1]26MY_CIV5D_DATA'!B:AS,15,FALSE) -> • | M14: =VLOOKUP(B14,'[1]26MY_CIV5D_DATA'!B:AS,16,FALSE) -> N/A | N14: =VLOOKUP($B14,'[1]26MY_CIV5D_DATA'!$B:$AS,17,FALSE) -> 0 | O14: =VLOOKUP(B14,'[1]26MY_CIV5D_DATA'!B:AS,18,FALSE) -> N/A | P14: =VLOOKUP(B14,'[1]26MY_CIV5D_DATA'!B:AS,19,FALSE) -> N/A | Q14: =IF(VLOOKUP(B14,'[1]26MY_CIV5D_DATA'!B:AS,21,FALSE)="","",VLOOKUP(B14,'[1]26MY_CIV5D_DATA'!B:AS,21,FALSE)) -> Prix établi pour ensemble de 4 pneus.
B15: 480-670-6545-SP ou 480-670-6545-GB | C15: =VLOOKUP(B15,'[1]26MY_CIV5D_DATA'!B:AS,4,FALSE) -> Roues Enkei M52 de 16 po - argent ou noir brillant | D15: =B15 -> 480-670-6545-SP ou 480-670-6545-GB
B16: 34417 | C16: =VLOOKUP(B16,'[1]26MY_CIV5D_DATA'!B:AS,4,FALSE) -> Pneus Michelin X-ICE Snow - 215/55/16 | D16: =B16 -> 34417
B18: 25CIV-STL-WTPK | C18: =VLOOKUP(B18,'[1]26MY_CIV5D_DATA'!B:AS,4,FALSE) -> Ensemble de roues d’hiver de 16 po en acier et de pneus Michelin X-ICE Snow | E18: =VLOOKUP(B18,'[1]26MY_CIV5D_DATA'!B:AS,9,FALSE) -> 1124.48 | F18: =VLOOKUP(B18,'[1]26MY_CIV5D_DATA'!B:AS,10,FALSE) -> 1492.48 | G18: =VLOOKUP(B18,'[1]26MY_CIV5D_DATA'!B:AS,7,FALSE) -> 1.2 | H18: =VLOOKUP(B18,'[1]26MY_CIV5D_DATA'!B:AS,11,FALSE) -> 1694.08 | I18: =VLOOKUP(B18,'[1]26MY_CIV5D_DATA'!B:AS,12,FALSE) -> 0 | J18: =VLOOKUP(B18,'[1]26MY_CIV5D_DATA'!B:AS,13,FALSE) -> 0 | K18: =VLOOKUP($B18,'[1]26MY_CIV5D_DATA'!$B:$AS,14,FALSE) -> 0 | L18: =VLOOKUP(B18,'[1]26MY_CIV5D_DATA'!B:AS,15,FALSE) -> • | M18: =VLOOKUP(B18,'[1]26MY_CIV5D_DATA'!B:AS,16,FALSE) -> N/A | N18: =VLOOKUP($B18,'[1]26MY_CIV5D_DATA'!$B:$AS,17,FALSE) -> 0 | O18: =VLOOKUP(B18,'[1]26MY_CIV5D_DATA'!B:AS,18,FALSE) -> N/A | P18: =VLOOKUP(B18,'[1]26MY_CIV5D_DATA'!B:AS,19,FALSE) -> N/A | Q18: =IF(VLOOKUP(B18,'[1]26MY_CIV5D_DATA'!B:AS,21,FALSE)="","",VLOOKUP(B18,'[1]26MY_CIV5D_DATA'!B:AS,21,FALSE)) -> Prix établi pour ensemble de 4 pneus.
B19: 42700-TBA-A12 | C19: =VLOOKUP(B19,'[1]26MY_CIV5D_DATA'!B:AS,4,FALSE) -> Roues d’hiver de 16 po en acier | D19: =B19 -> 42700-TBA-A12
B20: 34417 | C20: =VLOOKUP(B20,'[1]26MY_CIV5D_DATA'!B:AS,4,FALSE) -> Pneus Michelin X-ICE Snow - 215/55/16 | D20: =B20 -> 34417
B22: 25CIV5-ARO-PK | C22: =VLOOKUP(B22,'[1]26MY_CIV5D_DATA'!B:AS,4,FALSE) -> Ensemble Aero | E22: =VLOOKUP(B22,'[1]26MY_CIV5D_DATA'!B:AS,9,FALSE) -> 643.5 | F22: =VLOOKUP(B22,'[1]26MY_CIV5D_DATA'!B:AS,10,FALSE) -> 1072.8 | G22: =VLOOKUP(B22,'[1]26MY_CIV5D_DATA'!B:AS,7,FALSE) -> 2.2 | H22: =VLOOKUP(B22,'[1]26MY_CIV5D_DATA'!B:AS,11,FALSE) -> 1442.4 | I22: =VLOOKUP(B22,'[1]26MY_CIV5D_DATA'!B:AS,12,FALSE) -> 0 | J22: =VLOOKUP(B22,'[1]26MY_CIV5D_DATA'!B:AS,13,FALSE) -> 0 | K22: =VLOOKUP($B22,'[1]26MY_CIV5D_DATA'!$B:$AS,14,FALSE) -> 0 | L22: =VLOOKUP(B22,'[1]26MY_CIV5D_DATA'!B:AS,15,FALSE) -> • | M22: =VLOOKUP(B22,'[1]26MY_CIV5D_DATA'!B:AS,16,FALSE) -> • | N22: =VLOOKUP($B22,'[1]26MY_CIV5D_DATA'!$B:$AS,17,FALSE) -> 0 | O22: =VLOOKUP(B22,'[1]26MY_CIV5D_DATA'!B:AS,18,FALSE) -> • | P22: =VLOOKUP(B22,'[1]26MY_CIV5D_DATA'!B:AS,19,FALSE) -> N/A | Q22: =IF(VLOOKUP(B22,'[1]26MY_CIV5D_DATA'!B:AS,21,FALSE)="","",VLOOKUP(B22,'[1]26MY_CIV5D_DATA'!B:AS,21,FALSE)) -> Rabais de 10 % appliqué. Comprend déflecteur de bas de caisse avant de la couleur de la carrosserie et un becquet de hayon.
B23: 25CIV-5AR-NH883 | C23: =VLOOKUP(B23,'[1]26MY_CIV5D_DATA'!B:AS,4,FALSE) -> Blanc platine nacré (NH-883P) | D23: =B23 -> 25CIV-5AR-NH883
B24: 25CIV-5AR-NH932 | C24: =VLOOKUP(B24,'[1]26MY_CIV5D_DATA'!B:AS,4,FALSE) -> Refl et solaire argent métallisé (NH-932M) | D24: =B24 -> 25CIV-5AR-NH932
B25: 25CIV-5AR-NH904 | C25: =VLOOKUP(B25,'[1]26MY_CIV5D_DATA'!B:AS,4,FALSE) -> Gris météore nacré (NH-904M) | D25: =B25 -> 25CIV-5AR-NH904
B26: 25CIV-5AR-NH912 | C26: =VLOOKUP(B26,'[1]26MY_CIV5D_DATA'!B:AS,4,FALSE) -> Gris urbain nacré (NH-912P) | D26: =B26 -> 25CIV-5AR-NH912
B27: 25CIV-5AR-NH731 | C27: =VLOOKUP(B27,'[1]26MY_CIV5D_DATA'!B:AS,4,FALSE) -> Noir cristal nacré (NH-731P) | D27: =B27 -> 25CIV-5AR-NH731
B28: 25CIV-5AR-R513 | C28: =VLOOKUP(B28,'[1]26MY_CIV5D_DATA'!B:AS,4,FALSE) -> Rouge rallye (R-513) | D28: =B28 -> 25CIV-5AR-R513
B29: 25CIV-5AR-B637 | C29: =VLOOKUP(B29,'[1]26MY_CIV5D_DATA'!B:AS,4,FALSE) -> Bleu turbo nacré (B-637P) | D29: =B29 -> 25CIV-5AR-B637
B31: 22CIV-COLD-PK20 | C31: =VLOOKUP(B31,'[1]26MY_CIV5D_DATA'!B:AS,4,FALSE) -> Ensemble de temps froid - 2,0 L | D31: =B31 -> 22CIV-COLD-PK20 | E31: =VLOOKUP(B31,'[1]26MY_CIV5D_DATA'!B:AS,9,FALSE) -> 224.2 | F31: =VLOOKUP(B31,'[1]26MY_CIV5D_DATA'!B:AS,10,FALSE) -> 374.3 | G31: =VLOOKUP(B31,'[1]26MY_CIV5D_DATA'!B:AS,7,FALSE) -> 1.4 | H31: =VLOOKUP(B31,'[1]26MY_CIV5D_DATA'!B:AS,11,FALSE) -> 609.5 | I31: =VLOOKUP(B31,'[1]26MY_CIV5D_DATA'!B:AS,12,FALSE) -> 0 | J31: =VLOOKUP(B31,'[1]26MY_CIV5D_DATA'!B:AS,13,FALSE) -> 0 | K31: =VLOOKUP($B31,'[1]26MY_CIV5D_DATA'!$B:$AS,14,FALSE) -> 0 | L31: =VLOOKUP(B31,'[1]26MY_CIV5D_DATA'!B:AS,15,FALSE) -> • | M31: =VLOOKUP(B31,'[1]26MY_CIV5D_DATA'!B:AS,16,FALSE) -> • | N31: =VLOOKUP($B31,'[1]26MY_CIV5D_DATA'!$B:$AS,17,FALSE) -> 0 | O31: =VLOOKUP(B31,'[1]26MY_CIV5D_DATA'!B:AS,18,FALSE) -> • | P31: =VLOOKUP(B31,'[1]26MY_CIV5D_DATA'!B:AS,19,FALSE) -> N/A | Q31: =IF(VLOOKUP(B31,'[1]26MY_CIV5D_DATA'!B:AS,21,FALSE)="","",VLOOKUP(B31,'[1]26MY_CIV5D_DATA'!B:AS,21,FALSE)) -> Rabais de 5 % appliqué.
B32: 08T44-SNA-302 | C32: =VLOOKUP(B32,'[1]26MY_CIV5D_DATA'!B:AS,4,FALSE) -> Chauffe-moteur - 2,0 L | D32: =B32 -> 08T44-SNA-302
B33: 31670-BMS-004H | C33: =VLOOKUP(B33,'[1]26MY_CIV5D_DATA'!B:AS,4,FALSE) -> Chargeur/mainteneur de batterie automobile 12 V Optimate | D33: =B33 -> 31670-BMS-004H
B35: 25CIV5D-PRO-PET | C35: =VLOOKUP(B35,'[1]26MY_CIV5D_DATA'!B:AS,4,FALSE) -> Ensemble de protection - Petrol | D35: =B35 -> 25CIV5D-PRO-PET | E35: =VLOOKUP(B35,'[1]26MY_CIV5D_DATA'!B:AS,9,FALSE) -> 288.9 | F35: =VLOOKUP(B35,'[1]26MY_CIV5D_DATA'!B:AS,10,FALSE) -> 536 | G35: =VLOOKUP(B35,'[1]26MY_CIV5D_DATA'!B:AS,7,FALSE) -> 0.6 | H35: =VLOOKUP(B35,'[1]26MY_CIV5D_DATA'!B:AS,11,FALSE) -> 636.8 | I35: =VLOOKUP(B35,'[1]26MY_CIV5D_DATA'!B:AS,12,FALSE) -> 0 | J35: =VLOOKUP(B35,'[1]26MY_CIV5D_DATA'!B:AS,13,FALSE) -> 0 | K35: =VLOOKUP($B35,'[1]26MY_CIV5D_DATA'!$B:$AS,14,FALSE) -> 0 | L35: =VLOOKUP(B35,'[1]26MY_CIV5D_DATA'!B:AS,15,FALSE) -> • | M35: =VLOOKUP(B35,'[1]26MY_CIV5D_DATA'!B:AS,16,FALSE) -> N/A | N35: =VLOOKUP($B35,'[1]26MY_CIV5D_DATA'!$B:$AS,17,FALSE) -> 0 | O35: =VLOOKUP(B35,'[1]26MY_CIV5D_DATA'!B:AS,18,FALSE) -> N/A | P35: =VLOOKUP(B35,'[1]26MY_CIV5D_DATA'!B:AS,19,FALSE) -> N/A | Q35: =IF(VLOOKUP(B35,'[1]26MY_CIV5D_DATA'!B:AS,21,FALSE)="","",VLOOKUP(B35,'[1]26MY_CIV5D_DATA'!B:AS,21,FALSE))
B36: 08P17-T20-110 | C36: =VLOOKUP(B36,'[1]26MY_CIV5D_DATA'!B:AS,4,FALSE) -> Tapis toutes saisons | D36: =B36 -> 08P17-T20-110
B37: 08U45-T47-100B | C37: =VLOOKUP(B37,'[1]26MY_CIV5D_DATA'!B:AS,4,FALSE) -> Plateau de coffre | D37: =B37 -> 08U45-T47-100B
B38: 08P09-T47-300 | C38: =VLOOKUP(B38,'[1]26MY_CIV5D_DATA'!B:AS,4,FALSE) -> Garde-boue arrière | D38: =B38 -> 08P09-T47-300
B40: 25CIV5-PRO-HYB | C40: =VLOOKUP(B40,'[1]26MY_CIV5D_DATA'!B:AS,4,FALSE) -> Ensemble de protection - Hybrid | D40: =B40 -> 25CIV5-PRO-HYB | E40: =VLOOKUP(B40,'[1]26MY_CIV5D_DATA'!B:AS,9,FALSE) -> 288.9 | F40: =VLOOKUP(B40,'[1]26MY_CIV5D_DATA'!B:AS,10,FALSE) -> 536 | G40: =VLOOKUP(B40,'[1]26MY_CIV5D_DATA'!B:AS,7,FALSE) -> 0.6 | H40: =VLOOKUP(B40,'[1]26MY_CIV5D_DATA'!B:AS,11,FALSE) -> 636.8 | I40: =VLOOKUP(B40,'[1]26MY_CIV5D_DATA'!B:AS,12,FALSE) -> 0 | J40: =VLOOKUP(B40,'[1]26MY_CIV5D_DATA'!B:AS,13,FALSE) -> 0 | K40: =VLOOKUP($B40,'[1]26MY_CIV5D_DATA'!$B:$AS,14,FALSE) -> 0 | L40: =VLOOKUP(B40,'[1]26MY_CIV5D_DATA'!B:AS,15,FALSE) -> N/A | M40: =VLOOKUP(B40,'[1]26MY_CIV5D_DATA'!B:AS,16,FALSE) -> • | N40: =VLOOKUP($B40,'[1]26MY_CIV5D_DATA'!$B:$AS,17,FALSE) -> 0 | O40: =VLOOKUP(B40,'[1]26MY_CIV5D_DATA'!B:AS,18,FALSE) -> • | P40: =VLOOKUP(B40,'[1]26MY_CIV5D_DATA'!B:AS,19,FALSE) -> N/A | Q40: =IF(VLOOKUP(B40,'[1]26MY_CIV5D_DATA'!B:AS,21,FALSE)="","",VLOOKUP(B40,'[1]26MY_CIV5D_DATA'!B:AS,21,FALSE))
B41: 08P17-T20-110A | C41: =VLOOKUP(B41,'[1]26MY_CIV5D_DATA'!B:AS,4,FALSE) -> Tapis toutes saisons - Hybrid | D41: =B41 -> 08P17-T20-110A
B42: 08U45-T47-100B | C42: =VLOOKUP(B42,'[1]26MY_CIV5D_DATA'!B:AS,4,FALSE) -> Plateau de coffre | D42: =B42 -> 08U45-T47-100B
B43: 08P09-T47-300 | C43: =VLOOKUP(B43,'[1]26MY_CIV5D_DATA'!B:AS,4,FALSE) -> Garde-boue arrière | D43: =B43 -> 08P09-T47-300
B45: 25CIV5-PRO-FLM | C45: =VLOOKUP(B45,'[1]26MY_CIV5D_DATA'!B:AS,4,FALSE) -> Ensemble de protection - Film | D45: =B45 -> 25CIV5-PRO-FLM | E45: =VLOOKUP(B45,'[1]26MY_CIV5D_DATA'!B:AS,9,FALSE) -> 198.9 | F45: =VLOOKUP(B45,'[1]26MY_CIV5D_DATA'!B:AS,10,FALSE) -> 319.5 | G45: =VLOOKUP(B45,'[1]26MY_CIV5D_DATA'!B:AS,7,FALSE) -> 1 | H45: =VLOOKUP(B45,'[1]26MY_CIV5D_DATA'!B:AS,11,FALSE) -> 487.5 | I45: =VLOOKUP(B45,'[1]26MY_CIV5D_DATA'!B:AS,12,FALSE) -> 0 | J45: =VLOOKUP(B45,'[1]26MY_CIV5D_DATA'!B:AS,13,FALSE) -> 0 | K45: =VLOOKUP($B45,'[1]26MY_CIV5D_DATA'!$B:$AS,14,FALSE) -> 0 | L45: =VLOOKUP(B45,'[1]26MY_CIV5D_DATA'!B:AS,15,FALSE) -> • | M45: =VLOOKUP(B45,'[1]26MY_CIV5D_DATA'!B:AS,16,FALSE) -> • | N45: =VLOOKUP($B45,'[1]26MY_CIV5D_DATA'!$B:$AS,17,FALSE) -> 0 | O45: =VLOOKUP(B45,'[1]26MY_CIV5D_DATA'!B:AS,18,FALSE) -> • | P45: =VLOOKUP(B45,'[1]26MY_CIV5D_DATA'!B:AS,19,FALSE) -> N/A | Q45: =IF(VLOOKUP(B45,'[1]26MY_CIV5D_DATA'!B:AS,21,FALSE)="","",VLOOKUP(B45,'[1]26MY_CIV5D_DATA'!B:AS,21,FALSE)) -> Rabais de 10 % appliqué. Ne peut être installé simultanément avec protecteurs de bordure de porte.
B46: 08P04-T20-100 | C46: =VLOOKUP(B46,'[1]26MY_CIV5D_DATA'!B:AS,4,FALSE) -> Pellicule de protection de seuil de portière | D46: =B46 -> 08P04-T20-100
B47: 08P20-T20-100A | C47: =VLOOKUP(B47,'[1]26MY_CIV5D_DATA'!B:AS,4,FALSE) -> Pellicule pour rebord de portière | D47: =B47 -> 08P20-T20-100A
B48: 08P01-T47-100 | C48: =VLOOKUP(B48,'[1]26MY_CIV5D_DATA'!B:AS,4,FALSE) -> Protection de pare-chocs arrière | D48: =B48 -> 08P01-T47-100
...

Sheet 26MY_CIV5D_SELL-EN
B3: 26MY Honda Civic Hatch
B4: 200
B6: POPULAR ACCESSORIES
B7: 20
B8: 150 | M8: #VALUE!
B10: 20 | C10: ='26MY_CIV5D_APP_EN'!$C$114 -> Floor Mats - All-Season | H10: ='26MY_CIV5D_APP_EN'!$C$117 -> Cargo Tray | M10: ='26MY_CIV5D_APP_EN'!$C$66 -> Black Emblem H-Mark
B11: 20 | C11: ='26MY_CIV5D_APP_EN'!$H$114 -> 258.8 | D11: =-PMT($D$29/52,5*52,C11) -> 1.1801018 | E11: /wk * | F11: =$C$29 -> (6.99%) | H11: ='26MY_CIV5D_APP_EN'!$H$117 -> 208.8 | I11: =-PMT($D$29/52,5*52,H11) -> 0.95210688 | J11: /wk * | K11: =$C$29 -> (6.99%) | M11: ='26MY_CIV5D_APP_EN'!$H$66 -> 117.6 | N11: =-PMT($D$29/52,5*52,M11) -> 0.5362441 | O11: /wk * | P11: =$C$29 -> (6.99%)
B13: 150
B15: 20 | C15: ='26MY_CIV5D_APP_EN'!$C$68 -> Door Visors - Black | H15: ='[1]26MY_CIV5D_DATA'!$D$52 -> Body Side Moulding | M15: ='26MY_CIV5D_APP_EN'!$C$128 -> Illuminated Door Sill Trim | N15: Ambient Lighting, Blue | O15: Ambient Lighting, Blue | P15: Ambient Lighting, Blue
B16: 50 | C16: ='26MY_CIV5D_APP_FR'!$H$68 -> 419 | D16: =-PMT($D$29/52,5*52,C16) -> 1.9105976 | E16: /wk * | F16: =$C$29 -> (6.99%) | H16: ='[1]26MY_CIV5D_DATA'!$L$52 -> 415.2 | I16: =-PMT($D$29/52,5*52,H16) -> 1.89327 | J16: /wk * | K16: =$C$29 -> (6.99%) | M16: ='26MY_CIV5D_APP_EN'!$H$128 -> 599.8 | N16: =-PMT($D$29/52,5*52,M16) -> 2.7350273 | O16: /wk * | P16: =$C$29 -> (6.99%)
B18: 150
B20: 20 | C20: ='26MY_CIV5D_APP_EN'!$C$90 -> Tailgate Spoiler, HPD | H20: ='26MY_CIV5D_APP_EN'!$C$73 -> Roof Rack | M20: ='26MY_CIV5D_APP_EN'!$C$14 -> 16” Enkei M52 Wheels & Michelin X-ICE Snow Tire Package
B21: 50 | C21: ='26MY_CIV5D_APP_EN'!$H$91 -> 968.6 | D21: =-PMT($D$29/52,5*52,C21) -> 4.416718 | E21: /wk * | F21: =$C$29 -> (6.99%) | H21: ='26MY_CIV5D_APP_EN'!$H$73 -> 875.2 | I21: =-PMT($D$29/52,5*52,H21) -> 3.9908235 | J21: /wk * | K21: =$C$29 -> (6.99%) | M21: =SUM('26MY_CIV5D_APP_EN'!$H$14:$H$16) -> 2181.6 | N21: =-PMT($D$29/52,5*52,M21) -> 9.9478753 | O21: /wk * | P21: =$C$29 -> (6.99%)
C23: Genuine Honda Accessories purchased with a new Honda vehicle include a 3 year / 60,000 km manufacturer's warranty.
C24: Vehicle accessories purchased after vehicle sale include a 1 year / 20,000km manufacturer's warranty.
B25: 20 | C25: *Prices shown include the cost of installation.
B26: 60 | C26: *For informational purposes only. Weekly amounts shown are estimated payments based on a 60 month finance contract at 6.99% APR (including the cost of installation). Applicable taxes and fees are extra. Accessories cannot be financed on their own and must be financed through Honda Canada Finance Inc., on approved credit, in conjunction with a Honda vehicle. Representative finance example: $350.00 financed at 6.99% APR equals $1.60 weekly for 60 months. 260 weekly payments required. Cost of borrowing is $64.80 for a total obligation of $414.80. Actual payment amounts will vary based on APR, finance contract term and cost of the applicable accessories. Conditions apply. See your Honda dealer for full details.
C27: *More customized weekly payment options & accessories can be seen on Honda.ca - Build & Price
B28: 20
B29: 18 | C29: (6.99%) | D29: 0.0699
B30: 7.5 | C30: 12 | D30: 8 | E30: 8 | F30: 10 | G30: 8.5 | H30: 12 | I30: 8 | J30: 8 | K30: 10 | L30: 8.5 | M30: 12 | N30: 8 | O30: 8 | P30: 10 | Q30: 7.5
B31: Publication Date: | C31: ='[1]26MY_CIV5D_DATA'!$C$4 -> 45859 | D31: ='SELECT PROVINCE'!$A$23 -> All published prices, trim specifications, and availability are subject to change without prior notice. | P31: Province | Q31: ='SELECT PROVINCE'!$F$12 -> YT

Sheet 26MY_CIV5D_SELL-FR
B3: 26MY Honda Civic à Hayon
B4: 200
B6: ACCESSOIRES POPULAIRES
B7: 20
B8: 150 | M8: #VALUE!
B10: 20 | C10: ='26MY_CIV5D_APP_FR'!$C$115 -> Tapis toutes saisons | H10: ='26MY_CIV5D_APP_FR'!$C$118 -> Plateau de coffre | M10: ='26MY_CIV5D_APP_FR'!$C$66 -> Emblèmes « H » noirs
B11: 20 | C11: ='26MY_CIV5D_APP_FR'!$H$115 -> 258.8 | D11: =-PMT($D$29/52,5*52,C11) -> 1.1801018 | E11: /wk * | F11: =$C$29 -> (6.99%) | H11: ='26MY_CIV5D_APP_FR'!$H$118 -> 208.8 | I11: =-PMT($D$29/52,5*52,H11) -> 0.95210688 | J11: /wk * | K11: =$C$29 -> (6.99%) | M11: ='26MY_CIV5D_APP_FR'!$H$66 -> 117.6 | N11: =-PMT($D$29/52,5*52,M11) -> 0.5362441 | O11: /wk * | P11: =$C$29 -> (6.99%)
B13: 150
B15: 20 | C15: ='26MY_CIV5D_APP_FR'!$C$68 -> Déflecteurs de portières - noir | H15: ='[1]26MY_CIV5D_DATA'!$E$52 -> Moulure latérale | M15: ='26MY_CIV5D_APP_FR'!$C$129 -> Garniture de seuil de portière illuminée | N15: Ambient Lighting, Blue | O15: Ambient Lighting, Blue | P15: Ambient Lighting, Blue
B16: 50 | C16: ='26MY_CIV5D_APP_FR'!$H$68 -> 419 | D16: =-PMT($D$29/52,5*52,C16) -> 1.9105976 | E16: /wk * | F16: =$C$29 -> (6.99%) | H16: ='[1]26MY_CIV5D_DATA'!$L$52 -> 415.2 | I16: =-PMT($D$29/52,5*52,H16) -> 1.89327 | J16: /wk * | K16: =$C$29 -> (6.99%) | M16: ='26MY_CIV5D_APP_FR'!$H$129 -> 599.8 | N16: =-PMT($D$29/52,5*52,M16) -> 2.7350273 | O16: /wk * | P16: =$C$29 -> (6.99%)
B18: 150
B20: 20 | C20: ='26MY_CIV5D_APP_FR'!$C$90 -> Déflecteur de hayon - HPD | H20: ='26MY_CIV5D_APP_FR'!$C$73 -> Porte-bagages de toit | M20: ='[1]26MY_CIV5D_DATA'!$E$8 -> Ensemble de roues Enkei M52 de 16 po et de pneus Michelin X-ICE Snow
B21: 50 | C21: ='26MY_CIV5D_APP_FR'!$H$91 -> 968.6 | D21: =-PMT($D$29/52,5*52,C21) -> 4.416718 | E21: /wk * | F21: =$C$29 -> (6.99%) | H21: ='26MY_CIV5D_APP_FR'!$H$73 -> 875.2 | I21: =-PMT($D$29/52,5*52,H21) -> 3.9908235 | J21: /wk * | K21: =$C$29 -> (6.99%) | M21: =SUM('26MY_CIV5D_APP_EN'!$H$14:$H$16) -> 2181.6 | N21: =-PMT($D$29/52,5*52,M21) -> 9.9478753 | O21: /wk * | P21: =$C$29 -> (6.99%)
C23: Les accessoires Honda d’origine achetés avec un véhicule Honda neuf incluent une garantie du fabricant de 3 ans ou 60 000 km.
C24: Les accessoires de véhicule achetés après la vente du véhicule incluent une garantie du fabricant de 1 an ou 20 000 km.
B25: 20 | C25: *Les prix indiqués incluent le coût d'installation.
B26: 60 | C26: *À titre d’information seulement. Les montants hebdomadaires indiqués sont des paiements estimés basés sur un contrat de financement de 60 mois à un taux annuel en pourcentage (TAP) de 6,99 % (coût d’installation compris). Taxes et frais applicables en sus. Les accessoires ne peuvent être financés seuls et doivent être financés par l’entremise de Honda Canada Finance Inc., sur approbation de crédit, conjointement avec un véhicule Honda. Exemple de financement représentatif : Un montant de 350,00 $ financé à un TAP de 6,99 % équivaut à un paiement hebdomadaire de 1,60 $ pendant 60 mois. 260 paiements hebdomadaires sont requis. Le coût d’emprunt est de 64,80 $, pour une obligation totale de 414,80 $. Le montant réel des paiements variera en fonction du TAP, de la période du contrat de financement et du coût des accessoires applicables. Certaines conditions s’appliquent. Veuillez visiter votre concessionnaire Honda pour obtenir tous les détails.
C27: *Vous pouvez voir d’autres options de paiements hebdomadaires personnalisés ainsi que des accessoires sur le site Honda.ca – Configuration et prix.
B28: 20
B29: 18 | C29: (6.99%) | D29: 0.0699
B30: 7.5 | C30: 12 | D30: 8 | E30: 8 | F30: 10 | G30: 8.5 | H30: 12 | I30: 8 | J30: 8 | K30: 10 | L30: 8.5 | M30: 12 | N30: 8 | O30: 8 | P30: 10 | Q30: 7.5
B31: Date de publication: | C31: ='[1]26MY_CIV5D_DATA'!$C$4 -> 45859 | D31: Tout prix, spécifications de versions et disponibilté d'accessoires publiés sont sujets à changer sans pré-avis. | P31: Province | Q31: ='26MY_CIV5D_APP_FR'!$H$11 -> YT
