Workbook
Name HighlightSel: [2]EVL!$F$5
Name prov_cd: 'SELECT PROVINCE'!$B$1
Name province_codes: 'SELECT PROVINCE'!$B$6:$B$16
Name rate_table: 'SELECT PROVINCE'!$B$6:$C$16
Name SelColLBound: [2]EVL!$E$6
Name SelColUBound: [2]EVL!$F$6
Name SelRowLBound: [2]EVL!$E$7
Name SelRowUBound: [2]EVL!$F$7

Sheet SELECT PROVINCE
A1: Select Province: Choissisez votre province: | B1: YT
B4: Current Labor Rates
B5: Taux de main d'oeuvre en cours
B6: AB | C6: 162
B7: BC | C7: 168
B8: MB | C8: 155
B9: NB | C9: 130
B10: NL | C10: 130
B11: NS | C11: 130
B12: ON | C12: 150 | F12: =prov_cd -> YT
B13: PEI | C13: 125
B14: QC | C14: 140
B15: SK | C15: 155
B16: YT | C16: 168
A23: All published prices, trim specifications, and availability are subject to change without prior notice.
A24: Tout prix, spécifications de versions et disponibilté d'accessoires publiés sont sujets à changer sans pré-avis.
AF37: N/A

Sheet 26MY_ODYSSEY_APP_EN
B2: Honda Internal | C2: Honda Accessories
C3: Model Name | D3: ='[1]26MY_ODYSSEY_DATA'!C1 -> Odyssey
C4: Model Year | D4: ='[1]26MY_ODYSSEY_DATA'!C2 -> 2026
C5: S = Standard (accessory comes standard on this trim)
C6: T = Tire Size Change (the size of the accessory wheel is smaller/larger than the OE Wheel. Customer will require new tires to fit these wheels.)
C7: E = Exchange Standard Equipment (the size of the accessory wheel is the same size as the OE wheel and therefore they can use the OE tire.)
C8: N/A = Not Applicable (accessory cannot be applied to this trim)
H10: Province
C11: 1.0 Packages and Kits | H11: =prov_cd -> YT
C12: Description | D12: Part Number | E12: Dealer Net | F12: List Price | G12: FRT | H12: Installed Price | I12: Application | Q12: Comments
I13: ='[1]26MY_ODYSSEY_DATA'!M$6 -> 0 | J13: ='[1]26MY_ODYSSEY_DATA'!N$6 -> Sport | K13: ='[1]26MY_ODYSSEY_DATA'!O$6 -> Sport-L | L13: ='[1]26MY_ODYSSEY_DATA'!P$6 -> Touring | M13: ='[1]26MY_ODYSSEY_DATA'!Q$6 -> Black Edition | N13: ='[1]26MY_ODYSSEY_DATA'!R$6 -> 0 | O13: ='[1]26MY_ODYSSEY_DATA'!S$6 -> 0 | P13: ='[1]26MY_ODYSSEY_DATA'!T$6 -> 0
B14: 25ODY-PRO-PKG1 | C14: =VLOOKUP(B14,'[1]26MY_ODYSSEY_DATA'!B:AR,3,FALSE) -> Protection Package 1 | D14: =B14 -> 25ODY-PRO-PKG1 | E14: =VLOOKUP(B14,'[1]26MY_ODYSSEY_DATA'!B:AR,9,FALSE) -> 375.3 | F14: =VLOOKUP(B14,'[1]26MY_ODYSSEY_DATA'!B:AR,10,FALSE) -> 695 | G14: =VLOOKUP(B14,'[1]26MY_ODYSSEY_DATA'!B:AR,7,FALSE) -> 0.6 | H14: =VLOOKUP(B14,'[1]26MY_ODYSSEY_DATA'!B:AR,11,FALSE) -> 795.8 | I14: =VLOOKUP(B14,'[1]26MY_ODYSSEY_DATA'!B:AR,12,FALSE) -> 0 | J14: =VLOOKUP(B14,'[1]26MY_ODYSSEY_DATA'!B:AR,13,FALSE) -> • | K14: =VLOOKUP(B14,'[1]26MY_ODYSSEY_DATA'!B:AR,14,FALSE) -> • | L14: =VLOOKUP(B14,'[1]26MY_ODYSSEY_DATA'!B:AR,15,FALSE) -> • | M14: =VLOOKUP(B14,'[1]26MY_ODYSSEY_DATA'!B:AR,16,FALSE) -> • | N14: =VLOOKUP($B14,'[1]26MY_ODYSSEY_DATA'!$B:$AR,17,FALSE) -> 0 | O14: =VLOOKUP($B14,'[1]26MY_ODYSSEY_DATA'!$B:$AR,18,FALSE) -> 0 | P14: =VLOOKUP($B14,'[1]26MY_ODYSSEY_DATA'!$B:$AR,19,FALSE) -> 0 | Q14: =IF(VLOOKUP(B14,'[1]26MY_ODYSSEY_DATA'!B:AR,20,FALSE)="","",VLOOKUP(B14,'[1]26MY_ODYSSEY_DATA'!B:AR,20,FALSE)) -> White 'ODYSSEY' lettering on Floor Mats. Cargo Tray - Deep.
B15: 08P17-THR-110A | C15: =VLOOKUP(B15,'[1]26MY_ODYSSEY_DATA'!B:AR,3,FALSE) -> All-Season Floor Mats - White Logo | D15: =B15 -> 08P17-THR-110A
B16: 08U45-THR-100A | C16: =VLOOKUP(B16,'[1]26MY_ODYSSEY_DATA'!B:AR,3,FALSE) -> Cargo Tray - Deep | D16: =B16 -> 08U45-THR-100A
B17: 08P09-THR-300A | C17: =VLOOKUP(B17,'[1]26MY_ODYSSEY_DATA'!B:AR,3,FALSE) -> Rear Splash Guards | D17: =B17 -> 08P09-THR-300A
B19: 25ODY-PRO-PKG2 | C19: =VLOOKUP(B19,'[1]26MY_ODYSSEY_DATA'!B:AR,3,FALSE) -> Protection Package 2 | D19: =B19 -> 25ODY-PRO-PKG2 | E19: =VLOOKUP(B19,'[1]26MY_ODYSSEY_DATA'!B:AR,9,FALSE) -> 393.3 | F19: =VLOOKUP(B19,'[1]26MY_ODYSSEY_DATA'!B:AR,10,FALSE) -> 729 | G19: =VLOOKUP(B19,'[1]26MY_ODYSSEY_DATA'!B:AR,7,FALSE) -> 0.6 | H19: =VLOOKUP(B19,'[1]26MY_ODYSSEY_DATA'!B:AR,11,FALSE) -> 829.8 | I19: =VLOOKUP(B19,'[1]26MY_ODYSSEY_DATA'!B:AR,12,FALSE) -> 0 | J19: =VLOOKUP(B19,'[1]26MY_ODYSSEY_DATA'!B:AR,13,FALSE) -> • | K19: =VLOOKUP(B19,'[1]26MY_ODYSSEY_DATA'!B:AR,14,FALSE) -> • | L19: =VLOOKUP(B19,'[1]26MY_ODYSSEY_DATA'!B:AR,15,FALSE) -> • | M19: =VLOOKUP(B19,'[1]26MY_ODYSSEY_DATA'!B:AR,16,FALSE) -> • | N19: =VLOOKUP($B19,'[1]26MY_ODYSSEY_DATA'!$B:$AR,17,FALSE) -> 0 | O19: =VLOOKUP($B19,'[1]26MY_ODYSSEY_DATA'!$B:$AR,18,FALSE) -> 0 | P19: =VLOOKUP($B19,'[1]26MY_ODYSSEY_DATA'!$B:$AR,19,FALSE) -> 0 | Q19: =IF(VLOOKUP(B19,'[1]26MY_ODYSSEY_DATA'!B:AR,20,FALSE)="","",VLOOKUP(B19,'[1]26MY_ODYSSEY_DATA'!B:AR,20,FALSE)) -> White 'ODYSSEY' lettering on Floor Mats. Cargo Tray - Folding.
B20: 08P17-THR-110A | C20: =VLOOKUP(B20,'[1]26MY_ODYSSEY_DATA'!B:AR,3,FALSE) -> All-Season Floor Mats - White Logo | D20: =B20 -> 08P17-THR-110A
B21: 08U45-THR-100B | C21: =VLOOKUP(B21,'[1]26MY_ODYSSEY_DATA'!B:AR,3,FALSE) -> Cargo Tray - Folding | D21: =B21 -> 08U45-THR-100B
B22: 08P09-THR-300A | C22: =VLOOKUP(B22,'[1]26MY_ODYSSEY_DATA'!B:AR,3,FALSE) -> Rear Splash Guards | D22: =B22 -> 08P09-THR-300A
B24: 21ODY-COLD-PKG | C24: =VLOOKUP(B24,'[1]26MY_ODYSSEY_DATA'!B:AR,3,FALSE) -> Cold Weather Package | D24: =B24 -> 21ODY-COLD-PKG | E24: =VLOOKUP(B24,'[1]26MY_ODYSSEY_DATA'!B:AR,9,FALSE) -> 224.2 | F24: =VLOOKUP(B24,'[1]26MY_ODYSSEY_DATA'!B:AR,10,FALSE) -> 374.3 | G24: =VLOOKUP(B24,'[1]26MY_ODYSSEY_DATA'!B:AR,7,FALSE) -> 1.4 | H24: =VLOOKUP(B24,'[1]26MY_ODYSSEY_DATA'!B:AR,11,FALSE) -> 609.5 | I24: =VLOOKUP(B24,'[1]26MY_ODYSSEY_DATA'!B:AR,12,FALSE) -> 0 | J24: =VLOOKUP(B24,'[1]26MY_ODYSSEY_DATA'!B:AR,13,FALSE) -> • | K24: =VLOOKUP(B24,'[1]26MY_ODYSSEY_DATA'!B:AR,14,FALSE) -> • | L24: =VLOOKUP(B24,'[1]26MY_ODYSSEY_DATA'!B:AR,15,FALSE) -> • | M24: =VLOOKUP(B24,'[1]26MY_ODYSSEY_DATA'!B:AR,16,FALSE) -> • | N24: =VLOOKUP($B24,'[1]26MY_ODYSSEY_DATA'!$B:$AR,17,FALSE) -> 0 | O24: =VLOOKUP($B24,'[1]26MY_ODYSSEY_DATA'!$B:$AR,18,FALSE) -> 0 | P24: =VLOOKUP($B24,'[1]26MY_ODYSSEY_DATA'!$B:$AR,19,FALSE) -> 0 | Q24: =IF(VLOOKUP(B24,'[1]26MY_ODYSSEY_DATA'!B:AR,20,FALSE)="","",VLOOKUP(B24,'[1]26MY_ODYSSEY_DATA'!B:AR,20,FALSE)) -> 5% discount applied.
B25: 08T44-SJA-401A | C25: =VLOOKUP(B25,'[1]26MY_ODYSSEY_DATA'!B:AR,3,FALSE) -> Engine Block Heater | D25: =B25 -> 08T44-SJA-401A
B26: 31670-BMS-004H | C26: =VLOOKUP(B26,'[1]26MY_ODYSSEY_DATA'!B:AR,3,FALSE) -> Optimate 12V Auto Battery Charger/Maintainer | D26: =B26 -> 31670-BMS-004H
B28: 25ODY-TOW-A1 or 25ODY-TOW-B1 | C28: =VLOOKUP(B28,'[1]26MY_ODYSSEY_DATA'!B:AR,3,FALSE) -> Towing Package | D28: =B28 -> 25ODY-TOW-A1 or 25ODY-TOW-B1 | E28: =VLOOKUP(B28,'[1]26MY_ODYSSEY_DATA'!B:AR,9,FALSE) -> 784.8 | F28: =VLOOKUP(B28,'[1]26MY_ODYSSEY_DATA'!B:AR,10,FALSE) -> 1296 | G28: =VLOOKUP(B28,'[1]26MY_ODYSSEY_DATA'!B:AR,7,FALSE) -> 2.3 | H28: =VLOOKUP(B28,'[1]26MY_ODYSSEY_DATA'!B:AR,11,FALSE) -> 1682.4 | I28: =VLOOKUP(B28,'[1]26MY_ODYSSEY_DATA'!B:AR,12,FALSE) -> 0 | J28: =VLOOKUP(B28,'[1]26MY_ODYSSEY_DATA'!B:AR,13,FALSE) -> • | K28: =VLOOKUP(B28,'[1]26MY_ODYSSEY_DATA'!B:AR,14,FALSE) -> • | L28: =VLOOKUP(B28,'[1]26MY_ODYSSEY_DATA'!B:AR,15,FALSE) -> N/A | M28: =VLOOKUP(B28,'[1]26MY_ODYSSEY_DATA'!B:AR,16,FALSE) -> N/A | N28: =VLOOKUP($B28,'[1]26MY_ODYSSEY_DATA'!$B:$AR,17,FALSE) -> 0 | O28: =VLOOKUP($B28,'[1]26MY_ODYSSEY_DATA'!$B:$AR,18,FALSE) -> 0 | P28: =VLOOKUP($B28,'[1]26MY_ODYSSEY_DATA'!$B:$AR,19,FALSE) -> 0 | Q28: =IF(VLOOKUP(B28,'[1]26MY_ODYSSEY_DATA'!B:AR,20,FALSE)="","",VLOOKUP(B28,'[1]26MY_ODYSSEY_DATA'!B:AR,20,FALSE)) -> 10% Discount Applied. Trailer Hitch Rating: Class II. Trailer Hitch Receiver Size: 2-in x 2-in. Towing Capacity: 1,587 kg / 3,500 lbs.
B29: 08L92-THR-300A | C29: =VLOOKUP(B29,'[1]26MY_ODYSSEY_DATA'!B:AR,3,FALSE) -> Trailer Hitch | D29: =B29 -> 08L92-THR-300A
B30: 08L92-SCV-300A or 08L92-SCV-100B | C30: =VLOOKUP(B30,'[1]26MY_ODYSSEY_DATA'!B:AR,3,FALSE) -> Trailer Hitch Ball - 1-7/8" or 2" | D30: =B30 -> 08L92-SCV-300A or 08L92-SCV-100B
B31: 08L91-THR-300 | C31: =VLOOKUP(B31,'[1]26MY_ODYSSEY_DATA'!B:AR,3,FALSE) -> Trailer Hitch Harness | D31: =B31 -> 08L91-THR-300
B32: 08L92-SJC-300A | C32: =VLOOKUP(B32,'[1]26MY_ODYSSEY_DATA'!B:AR,3,FALSE) -> Trailer Hitch Locking Pin | D32: =B32 -> 08L92-SJC-300A
B34: 25ODY-TOW-A2 or 25ODY-TOW-B2 | C34: =VLOOKUP(B34,'[1]26MY_ODYSSEY_DATA'!B:AR,3,FALSE) -> Towing Package | D34: =B34 -> 25ODY-TOW-A2 or 25ODY-TOW-B2 | E34: =VLOOKUP(B34,'[1]26MY_ODYSSEY_DATA'!B:AR,9,FALSE) -> 999 | F34: =VLOOKUP(B34,'[1]26MY_ODYSSEY_DATA'!B:AR,10,FALSE) -> 1653.3 | G34: =VLOOKUP(B34,'[1]26MY_ODYSSEY_DATA'!B:AR,7,FALSE) -> 2.5 | H34: =VLOOKUP(B34,'[1]26MY_ODYSSEY_DATA'!B:AR,11,FALSE) -> 2073.3 | I34: =VLOOKUP(B34,'[1]26MY_ODYSSEY_DATA'!B:AR,12,FALSE) -> 0 | J34: =VLOOKUP(B34,'[1]26MY_ODYSSEY_DATA'!B:AR,13,FALSE) -> N/A | K34: =VLOOKUP(B34,'[1]26MY_ODYSSEY_DATA'!B:AR,14,FALSE) -> N/A | L34: =VLOOKUP(B34,'[1]26MY_ODYSSEY_DATA'!B:AR,15,FALSE) -> • | M34: =VLOOKUP(B34,'[1]26MY_ODYSSEY_DATA'!B:AR,16,FALSE) -> • | N34: =VLOOKUP($B34,'[1]26MY_ODYSSEY_DATA'!$B:$AR,17,FALSE) -> 0 | O34: =VLOOKUP($B34,'[1]26MY_ODYSSEY_DATA'!$B:$AR,18,FALSE) -> 0 | P34: =VLOOKUP($B34,'[1]26MY_ODYSSEY_DATA'!$B:$AR,19,FALSE) -> 0 | Q34: =IF(VLOOKUP(B34,'[1]26MY_ODYSSEY_DATA'!B:AR,20,FALSE)="","",VLOOKUP(B34,'[1]26MY_ODYSSEY_DATA'!B:AR,20,FALSE)) -> 10% Discount Applied. Black Edition: Requires Hands-Free Power Tailgate Sensor Adapter since Hands-Free comes standard. Trailer Hitch Rating: Class II. Trailer Hitch Receiver Size: 2-in x 2-in. Towing Capacity: 1,587 kg / 3,500 lbs.
B35: 08L92-THR-300A | C35: =VLOOKUP(B35,'[1]26MY_ODYSSEY_DATA'!B:AR,3,FALSE) -> Trailer Hitch | D35: =B35 -> 08L92-THR-300A
B36: 08L91-THR-300A | C36: =VLOOKUP(B36,'[1]26MY_ODYSSEY_DATA'!B:AR,3,FALSE) -> Hands-Free Power Tailgate Sensor Adapter | D36: =B36 -> 08L91-THR-300A
B37: 08L92-SCV-300A or 08L92-SCV-100B | C37: =VLOOKUP(B37,'[1]26MY_ODYSSEY_DATA'!B:AR,3,FALSE) -> Trailer Hitch Ball - 1-7/8" or 2" | D37: =B37 -> 08L92-SCV-300A or 08L92-SCV-100B
B38: 08L91-THR-300 | C38: =VLOOKUP(B38,'[1]26MY_ODYSSEY_DATA'!B:AR,3,FALSE) -> Trailer Hitch Harness | D38: =B38 -> 08L91-THR-300
B39: 08L92-SJC-300A | C39: =VLOOKUP(B39,'[1]26MY_ODYSSEY_DATA'!B:AR,3,FALSE) -> Trailer Hitch Locking Pin | D39: =B39 -> 08L92-SJC-300A
C41: 2.0 Wheels and Wheel Accessories
C42: Description | D42: Part Number | E42: Dealer Net | F42: List Price | G42: FRT | H42: Installed Price | I42: Application | Q42: Comments
I43: ='[1]26MY_ODYSSEY_DATA'!M$6 -> 0 | J43: ='[1]26MY_ODYSSEY_DATA'!N$6 -> Sport | K43: ='[1]26MY_ODYSSEY_DATA'!O$6 -> Sport-L | L43: ='[1]26MY_ODYSSEY_DATA'!P$6 -> Touring | M43: ='[1]26MY_ODYSSEY_DATA'!Q$6 -> Black Edition | N43: ='[1]26MY_ODYSSEY_DATA'!R$6 -> 0 | O43: ='[1]26MY_ODYSSEY_DATA'!S$6 -> 0 | P43: ='[1]26MY_ODYSSEY_DATA'!T$6 -> 0
B44: 08W42-TG7-301A | C44: =VLOOKUP(B44,'[1]26MY_ODYSSEY_DATA'!B:AR,3,FALSE) -> Wheel Locks - Black | D44: =B44 -> 08W42-TG7-301A | E44: =VLOOKUP(B44,'[1]26MY_ODYSSEY_DATA'!B:AR,9,FALSE) -> 85 | F44: =VLOOKUP(B44,'[1]26MY_ODYSSEY_DATA'!B:AR,10,FALSE) -> 140 | G44: =VLOOKUP(B44,'[1]26MY_ODYSSEY_DATA'!B:AR,7,FALSE) -> 0.2 | H44: =VLOOKUP(B44,'[1]26MY_ODYSSEY_DATA'!B:AR,11,FALSE) -> 173.6 | I44: =VLOOKUP(B44,'[1]26MY_ODYSSEY_DATA'!B:AR,12,FALSE) -> 0 | J44: =VLOOKUP(B44,'[1]26MY_ODYSSEY_DATA'!B:AR,13,FALSE) -> • | K44: =VLOOKUP(B44,'[1]26MY_ODYSSEY_DATA'!B:AR,14,FALSE) -> • | L44: =VLOOKUP(B44,'[1]26MY_ODYSSEY_DATA'!B:AR,15,FALSE) -> • | M44: =VLOOKUP(B44,'[1]26MY_ODYSSEY_DATA'!B:AR,16,FALSE) -> • | N44: =VLOOKUP($B44,'[1]26MY_ODYSSEY_DATA'!$B:$AR,17,FALSE) -> 0 | O44: =VLOOKUP($B44,'[1]26MY_ODYSSEY_DATA'!$B:$AR,18,FALSE) -> 0 | P44: =VLOOKUP($B44,'[1]26MY_ODYSSEY_DATA'!$B:$AR,19,FALSE) -> 0 | Q44: =IF(VLOOKUP(B44,'[1]26MY_ODYSSEY_DATA'!B:AR,20,FALSE)="","",VLOOKUP(B44,'[1]26MY_ODYSSEY_DATA'!B:AR,20,FALSE))
B45: 08W42-TK4-301 | C45: =VLOOKUP(B45,'[1]26MY_ODYSSEY_DATA'!B:AR,3,FALSE) -> Wheel Locks - Chrome | D45: =B45 -> 08W42-TK4-301 | E45: =VLOOKUP(B45,'[1]26MY_ODYSSEY_DATA'!B:AR,9,FALSE) -> 91 | F45: =VLOOKUP(B45,'[1]26MY_ODYSSEY_DATA'!B:AR,10,FALSE) -> 152 | G45: =VLOOKUP(B45,'[1]26MY_ODYSSEY_DATA'!B:AR,7,FALSE) -> 0.2 | H45: =VLOOKUP(B45,'[1]26MY_ODYSSEY_DATA'!B:AR,11,FALSE) -> 185.6 | I45: =VLOOKUP(B45,'[1]26MY_ODYSSEY_DATA'!B:AR,12,FALSE) -> 0 | J45: =VLOOKUP(B45,'[1]26MY_ODYSSEY_DATA'!B:AR,13,FALSE) -> • | K45: =VLOOKUP(B45,'[1]26MY_ODYSSEY_DATA'!B:AR,14,FALSE) -> • | L45: =VLOOKUP(B45,'[1]26MY_ODYSSEY_DATA'!B:AR,15,FALSE) -> • | M45: =VLOOKUP(B45,'[1]26MY_ODYSSEY_DATA'!B:AR,16,FALSE) -> • | N45: =VLOOKUP($B45,'[1]26MY_ODYSSEY_DATA'!$B:$AR,17,FALSE) -> 0 | O45: =VLOOKUP($B45,'[1]26MY_ODYSSEY_DATA'!$B:$AR,18,FALSE) -> 0 | P45: =VLOOKUP($B45,'[1]26MY_ODYSSEY_DATA'!$B:$AR,19,FALSE) -> 0 | Q45: =IF(VLOOKUP(B45,'[1]26MY_ODYSSEY_DATA'!B:AR,20,FALSE)="","",VLOOKUP(B45,'[1]26MY_ODYSSEY_DATA'!B:AR,20,FALSE))
C47: 3.0 Exterior
C48: Description | D48: Part Number | E48: Dealer Net | F48: List Price | G48: FRT | H48: Installed Price | I48: Application | Q48: Comments
...

Sheet 25MY_ODYSSEY_SELL-EN
B3: 26MY Honda Odyssey
B4: 200
B6: POPULAR ACCESSORIES
B7: 20
B8: 150
B10: 20 | C10: ='26MY_ODYSSEY_APP_EN'!$C$99 -> All-Season Floor Mats - White Logo | H10: ='26MY_ODYSSEY_APP_EN'!$C$100 -> Cargo Tray - Deep | M10: ='26MY_ODYSSEY_APP_EN'!$C$101 -> Cargo Tray - Folding
B11: 20 | C11: ='26MY_ODYSSEY_APP_EN'!$H$99 -> 341.8 | D11: =-PMT($D$29/52,5*52,C11) -> 1.5585734 | E11: /wk * | F11: =$C$29 -> (6.99%) | H11: ='26MY_ODYSSEY_APP_EN'!$H$101 -> 283.8 | I11: =-PMT($D$29/52,5*52,H11) -> 1.2940993 | J11: /wk * | K11: =$C$29 -> (6.99%) | M11: ='26MY_ODYSSEY_APP_EN'!$H$111 -> 1069.6 | N11: =-PMT($D$29/52,5*52,M11) -> 4.8772678 | O11: /wk * | P11: =$C$29 -> (6.99%)
B13: &
B15: 20 | C15: =TEXT('26MY_ODYSSEY_APP_EN'!$C$62,0)&(TEXT($B$13,0)&TEXT('26MY_ODYSSEY_APP_EN'!$C$64,0)) -> Roof Rails - Black & Crossbars | H15: =TEXT('26MY_ODYSSEY_APP_EN'!$C$75,0)&(TEXT($B$13,0)&TEXT('26MY_ODYSSEY_APP_EN'!$C$78,0)) -> Trailer Hitch & Trailer Hitch Harness | M15: ='26MY_ODYSSEY_APP_EN'!$C$111 -> Illuminated Door Sill Trim - Front & Rear
B16: 50 | C16: ='26MY_ODYSSEY_APP_EN'!$H$62+'26MY_ODYSSEY_APP_EN'!$H$64 -> 1328.6 | D16: =-PMT($D$29/52,5*52,C16) -> 6.0582816 | E16: /wk * | F16: =$C$29 -> (6.99%) | H16: ='26MY_ODYSSEY_APP_EN'!$H$75+'26MY_ODYSSEY_APP_EN'!$H$78 -> 1616.4 | I16: =-PMT($D$29/52,5*52,H16) -> 7.3706205 | J16: /wk * | K16: =$C$29 -> (6.99%) | M16: ='26MY_ODYSSEY_APP_EN'!$H$111 -> 1069.6 | N16: =-PMT($D$29/52,5*52,M16) -> 4.8772678 | O16: /wk * | P16: =$C$29 -> (6.99%)
B18: 150
B20: 20 | C20: ='26MY_ODYSSEY_APP_EN'!$C$58 -> Hood Air Deflector | H20: ='26MY_ODYSSEY_APP_EN'!$C$57 -> Door Visor | M20: ='26MY_ODYSSEY_APP_EN'!$C$61 -> Tent
B21: 50 | C21: ='26MY_ODYSSEY_APP_EN'!$H$58 -> 424 | D21: =-PMT($D$29/52,5*52,C21) -> 1.9333971 | E21: /wk * | F21: =$C$29 -> (6.99%) | H21: ='26MY_ODYSSEY_APP_EN'!$H$57 -> 474 | I21: =-PMT($D$29/52,5*52,H21) -> 2.161392 | J21: /wk * | K21: =$C$29 -> (6.99%) | M21: ='26MY_ODYSSEY_APP_EN'!$H$61 -> 681 | N21: =-PMT($D$29/52,5*52,M21) -> 3.1052911 | O21: /wk * | P21: =$C$29 -> (6.99%)
C23: Genuine Honda Accessories purchased with a new Honda vehicle include a 3 year / 60,000 km manufacturer's warranty.
C24: Vehicle accessories purchased after vehicle sale include a 1 year / 20,000km manufacturer's warranty.
B25: 20 | C25: *Prices shown include the cost of installation.
B26: 60 | C26: *For informational purposes only. Weekly amounts shown are estimated payments based on a 60 month finance contract at 6.99% APR (including the cost of installation). Applicable taxes and fees are extra. Accessories cannot be financed on their own and must be financed through Honda Canada Finance Inc., on approved credit, in conjunction with a Honda vehicle. Representative finance example: $350.00 financed at 6.99% APR equals $1.60 weekly for 60 months. 260 weekly payments required. Cost of borrowing is $64.80 for a total obligation of $414.80. Actual payment amounts will vary based on APR, finance contract term and cost of the applicable accessories. Conditions apply. See your Honda dealer for full details.
C27: *More customized weekly payment options & accessories can be seen on Honda.ca - Build & Price
B28: 20
B29: 18 | C29: (6.99%) | D29: 0.0699
B30: 7.5 | C30: 12 | D30: 8 | E30: 8 | F30: 10 | G30: 8.5 | H30: 12 | I30: 8 | J30: 8 | K30: 10 | L30: 8.5 | M30: 12 | N30: 8 | O30: 8 | P30: 10 | Q30: 7.5
B31: Publication Date: | C31: ='[1]26MY_ODYSSEY_DATA'!$C$3 -> 45902 | D31: ='SELECT PROVINCE'!$A$23 -> All published prices, trim specifications, and availability are subject to change without prior notice. | P31: Province | Q31: ='[1]26MY_ODYSSEY_DATA'!L5 -> YT

Sheet 26MY_ODYSSEY_APP_FR
B2: Honda Internal | C2: Accessoires Honda
C3: Nom du modèle | D3: ='[1]26MY_ODYSSEY_DATA'!C1 -> Odyssey
C4: Année modèle | D4: ='[1]26MY_ODYSSEY_DATA'!C2 -> 2026
C5: S = De série (accessoire de série sur cette version).
C6: T = Taille des pneus (la taille de la jante accessoire diffère de la jante d’origine. Le client aura besoin de nouveaux pneus pour ces jantes).
C7: E = Échange d’équipement de série (la taille de la jante accessoire est la même que celle de la jante d’origine. Le client peut utiliser les pneus d’origine).
C8: N/A = Sans objet (l’accessoire ne peut être utilisé pour cette version).
H10: Province
C11: 1.0 Groupes et ensembles | H11: =prov_cd -> YT
C12: La description | D12: Numéro de pièce | E12: Prix net | F12: Prix de liste | G12: T.F.F. | H12: Prix installé | I12: Application | Q12: Commentaires
I13: ='[1]26MY_ODYSSEY_DATA'!M$6 -> 0 | J13: ='[1]26MY_ODYSSEY_DATA'!N$6 -> Sport | K13: ='[1]26MY_ODYSSEY_DATA'!O$6 -> Sport-L | L13: ='[1]26MY_ODYSSEY_DATA'!P$6 -> Touring | M13: ='[1]26MY_ODYSSEY_DATA'!Q$6 -> Black Edition | N13: ='[1]26MY_ODYSSEY_DATA'!R$6 -> 0 | O13: ='[1]26MY_ODYSSEY_DATA'!S$6 -> 0 | P13: ='[1]26MY_ODYSSEY_DATA'!T$6 -> 0
B14: 25ODY-PRO-PKG1 | C14: =VLOOKUP(B14,'[1]26MY_ODYSSEY_DATA'!B:AR,4,FALSE) -> Ensemble de protection 1 | D14: =B14 -> 25ODY-PRO-PKG1 | E14: =VLOOKUP(B14,'[1]26MY_ODYSSEY_DATA'!B:AR,9,FALSE) -> 375.3 | F14: =VLOOKUP(B14,'[1]26MY_ODYSSEY_DATA'!B:AR,10,FALSE) -> 695 | G14: =VLOOKUP(B14,'[1]26MY_ODYSSEY_DATA'!B:AR,7,FALSE) -> 0.6 | H14: =VLOOKUP(B14,'[1]26MY_ODYSSEY_DATA'!B:AR,11,FALSE) -> 795.8 | I14: =VLOOKUP(B14,'[1]26MY_ODYSSEY_DATA'!B:AR,12,FALSE) -> 0 | J14: =VLOOKUP(B14,'[1]26MY_ODYSSEY_DATA'!B:AR,13,FALSE) -> • | K14: =VLOOKUP(B14,'[1]26MY_ODYSSEY_DATA'!B:AR,14,FALSE) -> • | L14: =VLOOKUP(B14,'[1]26MY_ODYSSEY_DATA'!B:AR,15,FALSE) -> • | M14: =VLOOKUP(B14,'[1]26MY_ODYSSEY_DATA'!B:AR,16,FALSE) -> • | N14: =VLOOKUP($B14,'[1]26MY_ODYSSEY_DATA'!$B:$AR,17,FALSE) -> 0 | O14: =VLOOKUP($B14,'[1]26MY_ODYSSEY_DATA'!$B:$AR,18,FALSE) -> 0 | P14: =VLOOKUP($B14,'[1]26MY_ODYSSEY_DATA'!$B:$AR,19,FALSE) -> 0 | Q14: =IF(VLOOKUP(B14,'[1]26MY_ODYSSEY_DATA'!B:AR,21,FALSE)="","",VLOOKUP(B14,'[1]26MY_ODYSSEY_DATA'!B:AR,21,FALSE)) -> Inscription 'ODYSSEY' blanche sur les tapis de sol.Plateau de chargement - Profond.
B15: 08P17-THR-110A | C15: =VLOOKUP(B15,'[1]26MY_ODYSSEY_DATA'!B:AR,4,FALSE) -> Protège-tapis toutes saisons - logo blanc | D15: =B15 -> 08P17-THR-110A
B16: 08U45-THR-100A | C16: =VLOOKUP(B16,'[1]26MY_ODYSSEY_DATA'!B:AR,4,FALSE) -> Plateau de compartiment à bagages - profond | D16: =B16 -> 08U45-THR-100A
B17: 08P09-THR-300A | C17: =VLOOKUP(B17,'[1]26MY_ODYSSEY_DATA'!B:AR,4,FALSE) -> Garde-boue arrière | D17: =B17 -> 08P09-THR-300A
B19: 25ODY-PRO-PKG2 | C19: =VLOOKUP(B19,'[1]26MY_ODYSSEY_DATA'!B:AR,4,FALSE) -> Ensemble de protection 2 | D19: =B19 -> 25ODY-PRO-PKG2 | E19: =VLOOKUP(B19,'[1]26MY_ODYSSEY_DATA'!B:AR,9,FALSE) -> 393.3 | F19: =VLOOKUP(B19,'[1]26MY_ODYSSEY_DATA'!B:AR,10,FALSE) -> 729 | G19: =VLOOKUP(B19,'[1]26MY_ODYSSEY_DATA'!B:AR,7,FALSE) -> 0.6 | H19: =VLOOKUP(B19,'[1]26MY_ODYSSEY_DATA'!B:AR,11,FALSE) -> 829.8 | I19: =VLOOKUP(B19,'[1]26MY_ODYSSEY_DATA'!B:AR,12,FALSE) -> 0 | J19: =VLOOKUP(B19,'[1]26MY_ODYSSEY_DATA'!B:AR,13,FALSE) -> • | K19: =VLOOKUP(B19,'[1]26MY_ODYSSEY_DATA'!B:AR,14,FALSE) -> • | L19: =VLOOKUP(B19,'[1]26MY_ODYSSEY_DATA'!B:AR,15,FALSE) -> • | M19: =VLOOKUP(B19,'[1]26MY_ODYSSEY_DATA'!B:AR,16,FALSE) -> • | N19: =VLOOKUP($B19,'[1]26MY_ODYSSEY_DATA'!$B:$AR,17,FALSE) -> 0 | O19: =VLOOKUP($B19,'[1]26MY_ODYSSEY_DATA'!$B:$AR,18,FALSE) -> 0 | P19: =VLOOKUP($B19,'[1]26MY_ODYSSEY_DATA'!$B:$AR,19,FALSE) -> 0 | Q19: =IF(VLOOKUP(B19,'[1]26MY_ODYSSEY_DATA'!B:AR,21,FALSE)="","",VLOOKUP(B19,'[1]26MY_ODYSSEY_DATA'!B:AR,21,FALSE)) -> Inscription 'ODYSSEY' blanche sur les tapis de sol. Plateau de chargement - Pliable.
B20: 08P17-THR-110A | C20: =VLOOKUP(B20,'[1]26MY_ODYSSEY_DATA'!B:AR,4,FALSE) -> Protège-tapis toutes saisons - logo blanc | D20: =B20 -> 08P17-THR-110A
B21: 08U45-THR-100B | C21: =VLOOKUP(B21,'[1]26MY_ODYSSEY_DATA'!B:AR,4,FALSE) -> Plateaux de coffre pliants | D21: =B21 -> 08U45-THR-100B
B22: 08P09-THR-300A | C22: =VLOOKUP(B22,'[1]26MY_ODYSSEY_DATA'!B:AR,4,FALSE) -> Garde-boue arrière | D22: =B22 -> 08P09-THR-300A
B24: 21ODY-COLD-PKG | C24: =VLOOKUP(B24,'[1]26MY_ODYSSEY_DATA'!B:AR,4,FALSE) -> Ensemble de temps froid | D24: =B24 -> 21ODY-COLD-PKG | E24: =VLOOKUP(B24,'[1]26MY_ODYSSEY_DATA'!B:AR,9,FALSE) -> 224.2 | F24: =VLOOKUP(B24,'[1]26MY_ODYSSEY_DATA'!B:AR,10,FALSE) -> 374.3 | G24: =VLOOKUP(B24,'[1]26MY_ODYSSEY_DATA'!B:AR,7,FALSE) -> 1.4 | H24: =VLOOKUP(B24,'[1]26MY_ODYSSEY_DATA'!B:AR,11,FALSE) -> 609.5 | I24: =VLOOKUP(B24,'[1]26MY_ODYSSEY_DATA'!B:AR,12,FALSE) -> 0 | J24: =VLOOKUP(B24,'[1]26MY_ODYSSEY_DATA'!B:AR,13,FALSE) -> • | K24: =VLOOKUP(B24,'[1]26MY_ODYSSEY_DATA'!B:AR,14,FALSE) -> • | L24: =VLOOKUP(B24,'[1]26MY_ODYSSEY_DATA'!B:AR,15,FALSE) -> • | M24: =VLOOKUP(B24,'[1]26MY_ODYSSEY_DATA'!B:AR,16,FALSE) -> • | N24: =VLOOKUP($B24,'[1]26MY_ODYSSEY_DATA'!$B:$AR,17,FALSE) -> 0 | O24: =VLOOKUP($B24,'[1]26MY_ODYSSEY_DATA'!$B:$AR,18,FALSE) -> 0 | P24: =VLOOKUP($B24,'[1]26MY_ODYSSEY_DATA'!$B:$AR,19,FALSE) -> 0 | Q24: =IF(VLOOKUP(B24,'[1]26MY_ODYSSEY_DATA'!B:AR,21,FALSE)="","",VLOOKUP(B24,'[1]26MY_ODYSSEY_DATA'!B:AR,21,FALSE)) -> Rabais de 5% est appliqué.
B25: 08T44-SJA-401A | C25: =VLOOKUP(B25,'[1]26MY_ODYSSEY_DATA'!B:AR,4,FALSE) -> Chauffe-moteur | D25: =B25 -> 08T44-SJA-401A
B26: 31670-BMS-004H | C26: =VLOOKUP(B26,'[1]26MY_ODYSSEY_DATA'!B:AR,4,FALSE) -> Chargeur/mainteneur de charge de batterie automobile 12 V | D26: =B26 -> 31670-BMS-004H
B28: 25ODY-TOWA1 ou 25ODY-TOWB1 | C28: =VLOOKUP(B28,'[1]26MY_ODYSSEY_DATA'!B:AR,4,FALSE) -> Ensemble de remorquage | D28: =B28 -> 25ODY-TOWA1 ou 25ODY-TOWB1 | E28: =VLOOKUP(B28,'[1]26MY_ODYSSEY_DATA'!B:AR,9,FALSE) -> 784.8 | F28: =VLOOKUP(B28,'[1]26MY_ODYSSEY_DATA'!B:AR,10,FALSE) -> 1296 | G28: =VLOOKUP(B28,'[1]26MY_ODYSSEY_DATA'!B:AR,7,FALSE) -> 2.3 | H28: =VLOOKUP(B28,'[1]26MY_ODYSSEY_DATA'!B:AR,11,FALSE) -> 1682.4 | I28: =VLOOKUP(B28,'[1]26MY_ODYSSEY_DATA'!B:AR,12,FALSE) -> 0 | J28: =VLOOKUP(B28,'[1]26MY_ODYSSEY_DATA'!B:AR,13,FALSE) -> • | K28: =VLOOKUP(B28,'[1]26MY_ODYSSEY_DATA'!B:AR,14,FALSE) -> • | L28: =VLOOKUP(B28,'[1]26MY_ODYSSEY_DATA'!B:AR,15,FALSE) -> N/A | M28: =VLOOKUP(B28,'[1]26MY_ODYSSEY_DATA'!B:AR,16,FALSE) -> N/A | N28: =VLOOKUP($B28,'[1]26MY_ODYSSEY_DATA'!$B:$AR,17,FALSE) -> 0 | O28: =VLOOKUP($B28,'[1]26MY_ODYSSEY_DATA'!$B:$AR,18,FALSE) -> 0 | P28: =VLOOKUP($B28,'[1]26MY_ODYSSEY_DATA'!$B:$AR,19,FALSE) -> 0 | Q28: =IF(VLOOKUP(B28,'[1]26MY_ODYSSEY_DATA'!B:AR,21,FALSE)="","",VLOOKUP(B28,'[1]26MY_ODYSSEY_DATA'!B:AR,21,FALSE)) -> Rabais de 10 % est appliqué. Attelage de remorque: Classe II. Attelage de remorque dimensions du réceptacle: 2 po x 2 po. Capacité de remorquage: 1,360 kg / 3,000 lbs.
B29: 08L92-THR-300A | C29: =VLOOKUP(B29,'[1]26MY_ODYSSEY_DATA'!B:AR,4,FALSE) -> Attelage de remorque | D29: =B29 -> 08L92-THR-300A
B30: 08L92-SCV-300A ou 08L92-SCV-100B | C30: =VLOOKUP(B30,'[1]26MY_ODYSSEY_DATA'!B:AR,4,FALSE) -> Rotule d'attelage de 1 7/8 po ou 2 po | D30: =B30 -> 08L92-SCV-300A ou 08L92-SCV-100B
B31: 08L91-THR-300 | C31: =VLOOKUP(B31,'[1]26MY_ODYSSEY_DATA'!B:AR,4,FALSE) -> Harnais pour remorque | D31: =B31 -> 08L91-THR-300
B32: 08L92-SJC-300A | C32: =VLOOKUP(B32,'[1]26MY_ODYSSEY_DATA'!B:AR,4,FALSE) -> Goupille de verrouillage pour l'attelage de remorque | D32: =B32 -> 08L92-SJC-300A
B34: 25ODY-TOW-A2 ou 25ODY-TOW-B2 | C34: =VLOOKUP(B34,'[1]26MY_ODYSSEY_DATA'!B:AR,4,FALSE) -> Ensemble de remorquage | D34: =B34 -> 25ODY-TOW-A2 ou 25ODY-TOW-B2 | E34: =VLOOKUP(B34,'[1]26MY_ODYSSEY_DATA'!B:AR,9,FALSE) -> 999 | F34: =VLOOKUP(B34,'[1]26MY_ODYSSEY_DATA'!B:AR,10,FALSE) -> 1653.3 | G34: =VLOOKUP(B34,'[1]26MY_ODYSSEY_DATA'!B:AR,7,FALSE) -> 2.5 | H34: =VLOOKUP(B34,'[1]26MY_ODYSSEY_DATA'!B:AR,11,FALSE) -> 2073.3 | I34: =VLOOKUP(B34,'[1]26MY_ODYSSEY_DATA'!B:AR,12,FALSE) -> 0 | J34: =VLOOKUP(B34,'[1]26MY_ODYSSEY_DATA'!B:AR,13,FALSE) -> N/A | K34: =VLOOKUP(B34,'[1]26MY_ODYSSEY_DATA'!B:AR,14,FALSE) -> N/A | L34: =VLOOKUP(B34,'[1]26MY_ODYSSEY_DATA'!B:AR,15,FALSE) -> • | M34: =VLOOKUP(B34,'[1]26MY_ODYSSEY_DATA'!B:AR,16,FALSE) -> • | N34: =VLOOKUP($B34,'[1]26MY_ODYSSEY_DATA'!$B:$AR,17,FALSE) -> 0 | O34: =VLOOKUP($B34,'[1]26MY_ODYSSEY_DATA'!$B:$AR,18,FALSE) -> 0 | P34: =VLOOKUP($B34,'[1]26MY_ODYSSEY_DATA'!$B:$AR,19,FALSE) -> 0 | Q34: =IF(VLOOKUP(B34,'[1]26MY_ODYSSEY_DATA'!B:AR,21,FALSE)="","",VLOOKUP(B34,'[1]26MY_ODYSSEY_DATA'!B:AR,21,FALSE)) -> Rabais de 10 % est appliqué. Black Edition :Nécessite adaptateur de capteur de hayon électrique mains libres puisque le système mains libres est de série. Attelage de remorque: Classe II. Attelage de remorque dimensions du réceptacle: 2 po x 2 po. Capacité de remorquage: 1,360 kg / 3,000 lbs.
B35: 08L92-THR-300A | C35: =VLOOKUP(B35,'[1]26MY_ODYSSEY_DATA'!B:AR,4,FALSE) -> Attelage de remorque | D35: =B35 -> 08L92-THR-300A
B36: 08L91-THR-300A | C36: =VLOOKUP(B36,'[1]26MY_ODYSSEY_DATA'!B:AR,4,FALSE) -> Adaptateur de capteur de hayon électrique mains libres | D36: =B36 -> 08L91-THR-300A
B37: 08L92-SCV-300A ou 08L92-SCV-100B | C37: =VLOOKUP(B37,'[1]26MY_ODYSSEY_DATA'!B:AR,4,FALSE) -> Rotule d'attelage de 1 7/8 po ou 2 po | D37: =B37 -> 08L92-SCV-300A ou 08L92-SCV-100B
B38: 08L91-THR-300 | C38: =VLOOKUP(B38,'[1]26MY_ODYSSEY_DATA'!B:AR,4,FALSE) -> Harnais pour remorque | D38: =B38 -> 08L91-THR-300
B39: 08L92-SJC-300A | C39: =VLOOKUP(B39,'[1]26MY_ODYSSEY_DATA'!B:AR,4,FALSE) -> Goupille de verrouillage pour l'attelage de remorque | D39: =B39 -> 08L92-SJC-300A
C41: 2.0 Jantes et accessoires de jantes
C42: La description | D42: Numéro de pièce | E42: Prix net | F42: Prix de liste | G42: T.F.F. | H42: Prix installé | I42: Application | Q42: Commentaires
I43: ='[1]26MY_ODYSSEY_DATA'!M$6 -> 0 | J43: ='[1]26MY_ODYSSEY_DATA'!N$6 -> Sport | K43: ='[1]26MY_ODYSSEY_DATA'!O$6 -> Sport-L | L43: ='[1]26MY_ODYSSEY_DATA'!P$6 -> Touring | M43: ='[1]26MY_ODYSSEY_DATA'!Q$6 -> Black Edition | N43: ='[1]26MY_ODYSSEY_DATA'!R$6 -> 0 | O43: ='[1]26MY_ODYSSEY_DATA'!S$6 -> 0 | P43: ='[1]26MY_ODYSSEY_DATA'!T$6 -> 0
B44: 08W42-TG7-301A | C44: =VLOOKUP(B44,'[1]26MY_ODYSSEY_DATA'!B:AR,4,FALSE) -> Écrous de roue antivol - Noirs | D44: =B44 -> 08W42-TG7-301A | E44: =VLOOKUP(B44,'[1]26MY_ODYSSEY_DATA'!B:AR,9,FALSE) -> 85 | F44: =VLOOKUP(B44,'[1]26MY_ODYSSEY_DATA'!B:AR,10,FALSE) -> 140 | G44: =VLOOKUP(B44,'[1]26MY_ODYSSEY_DATA'!B:AR,7,FALSE) -> 0.2 | H44: =VLOOKUP(B44,'[1]26MY_ODYSSEY_DATA'!B:AR,11,FALSE) -> 173.6 | I44: =VLOOKUP(B44,'[1]26MY_ODYSSEY_DATA'!B:AR,12,FALSE) -> 0 | J44: =VLOOKUP(B44,'[1]26MY_ODYSSEY_DATA'!B:AR,13,FALSE) -> • | K44: =VLOOKUP(B44,'[1]26MY_ODYSSEY_DATA'!B:AR,14,FALSE) -> • | L44: =VLOOKUP(B44,'[1]26MY_ODYSSEY_DATA'!B:AR,15,FALSE) -> • | M44: =VLOOKUP(B44,'[1]26MY_ODYSSEY_DATA'!B:AR,16,FALSE) -> • | N44: =VLOOKUP($B44,'[1]26MY_ODYSSEY_DATA'!$B:$AR,17,FALSE) -> 0 | O44: =VLOOKUP($B44,'[1]26MY_ODYSSEY_DATA'!$B:$AR,18,FALSE) -> 0 | P44: =VLOOKUP($B44,'[1]26MY_ODYSSEY_DATA'!$B:$AR,19,FALSE) -> 0 | Q44: =IF(VLOOKUP(B44,'[1]26MY_ODYSSEY_DATA'!B:AR,21,FALSE)="","",VLOOKUP(B44,'[1]26MY_ODYSSEY_DATA'!B:AR,21,FALSE))
B45: 08W42-TK4-301 | C45: =VLOOKUP(B45,'[1]26MY_ODYSSEY_DATA'!B:AR,4,FALSE) -> Écrous de roue antivol - Chromés | D45: =B45 -> 08W42-TK4-301 | E45: =VLOOKUP(B45,'[1]26MY_ODYSSEY_DATA'!B:AR,9,FALSE) -> 91 | F45: =VLOOKUP(B45,'[1]26MY_ODYSSEY_DATA'!B:AR,10,FALSE) -> 152 | G45: =VLOOKUP(B45,'[1]26MY_ODYSSEY_DATA'!B:AR,7,FALSE) -> 0.2 | H45: =VLOOKUP(B45,'[1]26MY_ODYSSEY_DATA'!B:AR,11,FALSE) -> 185.6 | I45: =VLOOKUP(B45,'[1]26MY_ODYSSEY_DATA'!B:AR,12,FALSE) -> 0 | J45: =VLOOKUP(B45,'[1]26MY_ODYSSEY_DATA'!B:AR,13,FALSE) -> • | K45: =VLOOKUP(B45,'[1]26MY_ODYSSEY_DATA'!B:AR,14,FALSE) -> • | L45: =VLOOKUP(B45,'[1]26MY_ODYSSEY_DATA'!B:AR,15,FALSE) -> • | M45: =VLOOKUP(B45,'[1]26MY_ODYSSEY_DATA'!B:AR,16,FALSE) -> • | N45: =VLOOKUP($B45,'[1]26MY_ODYSSEY_DATA'!$B:$AR,17,FALSE) -> 0 | O45: =VLOOKUP($B45,'[1]26MY_ODYSSEY_DATA'!$B:$AR,18,FALSE) -> 0 | P45: =VLOOKUP($B45,'[1]26MY_ODYSSEY_DATA'!$B:$AR,19,FALSE) -> 0 | Q45: =IF(VLOOKUP(B45,'[1]26MY_ODYSSEY_DATA'!B:AR,21,FALSE)="","",VLOOKUP(B45,'[1]26MY_ODYSSEY_DATA'!B:AR,21,FALSE))
C47: 3.0 Extérieur
C48: La description | D48: Numéro de pièce | E48: Prix net | F48: Prix de liste | G48: T.F.F. | H48: Prix installé | I48: Application | Q48: Commentaires
...

Sheet 25MY_ODYSSEY_SELL-FR
B3: 26MY Honda Odyssey
B4: 200
B6: ACCESSOIRES POPULAIRES
B7: 20
B8: 150
B10: 20 | C10: ='26MY_ODYSSEY_APP_FR'!$C$100 -> Protège-tapis toutes saisons - logo blanc | H10: ='26MY_ODYSSEY_APP_FR'!$C$101 -> Plateau de compartiment à bagages - profond | M10: ='26MY_ODYSSEY_APP_FR'!$C$102 -> Plateaux de coffre pliants
B11: 20 | C11: ='26MY_ODYSSEY_APP_FR'!$H$100 -> 341.8 | D11: =-PMT($D$29/52,5*52,C11) -> 1.5585734 | E11: /wk * | F11: =$C$29 -> (6.99%) | H11: ='26MY_ODYSSEY_APP_FR'!$H$101 -> 249.8 | I11: =-PMT($D$29/52,5*52,H11) -> 1.1390627 | J11: /wk * | K11: =$C$29 -> (6.99%) | M11: ='26MY_ODYSSEY_APP_FR'!$H$102 -> 283.8 | N11: =-PMT($D$29/52,5*52,M11) -> 1.2940993 | O11: /wk * | P11: =$C$29 -> (6.99%)
B13: et
B15: 20 | C15: =TEXT('26MY_ODYSSEY_APP_FR'!$C$62,0)&(TEXT($B$13,0)&TEXT('26MY_ODYSSEY_APP_FR'!$C$64,0)) -> Rails de toit - Noir et Barres transversales | H15: =TEXT('26MY_ODYSSEY_APP_FR'!$C$75,0)&(TEXT($B$13,0)&TEXT('26MY_ODYSSEY_APP_FR'!$C$78,0)) -> Attelage de remorque et Harnais pour remorque | M15: ='26MY_ODYSSEY_APP_FR'!$C$112 -> Garniture lumineuses de bas de portière - Avant et arrière
B16: 50 | C16: ='26MY_ODYSSEY_APP_FR'!$H$62+'26MY_ODYSSEY_APP_FR'!$H$64 -> 1328.6 | D16: =-PMT($D$29/52,5*52,C16) -> 6.0582816 | E16: /wk * | F16: =$C$29 -> (6.99%) | H16: ='26MY_ODYSSEY_APP_FR'!$H$75+'26MY_ODYSSEY_APP_FR'!$H$78 -> 1616.4 | I16: =-PMT($D$29/52,5*52,H16) -> 7.3706205 | J16: /wk * | K16: =$C$29 -> (6.99%) | M16: ='26MY_ODYSSEY_APP_FR'!$H$112 -> 1069.6 | N16: =-PMT($D$29/52,5*52,M16) -> 4.8772678 | O16: /wk * | P16: =$C$29 -> (6.99%)
B18: 150
B20: 20 | C20: ='26MY_ODYSSEY_APP_FR'!$C$58 -> Déflecteur d’air du capot | H20: ='26MY_ODYSSEY_APP_FR'!$C$57 -> Pare-soleil de portière | M20: ='26MY_ODYSSEY_APP_FR'!$C$61 -> Tente
B21: 50 | C21: ='26MY_ODYSSEY_APP_FR'!$H$58 -> 424 | D21: =-PMT($D$29/52,5*52,C21) -> 1.9333971 | E21: /wk * | F21: =$C$29 -> (6.99%) | H21: ='26MY_ODYSSEY_APP_FR'!$H$57 -> 474 | I21: =-PMT($D$29/52,5*52,H21) -> 2.161392 | J21: /wk * | K21: =$C$29 -> (6.99%) | M21: ='26MY_ODYSSEY_APP_FR'!$H$61 -> 681 | N21: =-PMT($D$29/52,5*52,M21) -> 3.1052911 | O21: /wk * | P21: =$C$29 -> (6.99%)
C23: Les accessoires Honda d’origine achetés avec un véhicule Honda neuf incluent une garantie du fabricant de 3 ans ou 60 000 km.
C24: Les accessoires de véhicule achetés après la vente du véhicule incluent une garantie du fabricant de 1 an ou 20 000 km.
B25: 20 | C25: *Les prix indiqués incluent le coût d'installation.
B26: 60 | C26: *À titre d’information seulement. Les montants hebdomadaires indiqués sont des paiements estimés basés sur un contrat de financement de 60 mois à un taux annuel en pourcentage (TAP) de 6,99 % (coût d’installation compris). Taxes et frais applicables en sus. Les accessoires ne peuvent être financés seuls et doivent être financés par l’entremise de Honda Canada Finance Inc., sur approbation de crédit, conjointement avec un véhicule Honda. Exemple de financement représentatif : Un montant de 350,00 $ financé à un TAP de 6,99 % équivaut à un paiement hebdomadaire de 1,60 $ pendant 60 mois. 260 paiements hebdomadaires sont requis. Le coût d’emprunt est de 64,80 $, pour une obligation totale de 414,80 $. Le montant réel des paiements variera en fonction du TAP, de la période du contrat de financement et du coût des accessoires applicables. Certaines conditions s’appliquent. Veuillez visiter votre concessionnaire Honda pour obtenir tous les détails.
C27: *Vous pouvez voir d’autres options de paiements hebdomadaires personnalisés ainsi que des accessoires sur le site Honda.ca – Configuration et prix.
B28: 20
B29: 18 | C29: (6.99%) | D29: 0.0699
B30: 7.5 | C30: 12 | D30: 8 | E30: 8 | F30: 10 | G30: 8.5 | H30: 12 | I30: 8 | J30: 8 | K30: 10 | L30: 8.5 | M30: 12 | N30: 8 | O30: 8 | P30: 10 | Q30: 7.5
B31: Date de publication: | C31: ='[1]26MY_ODYSSEY_DATA'!$C$3 -> 45902 | D31: Tout prix, spécifications de versions et disponibilté d'accessoires publiés sont sujets à changer sans pré-avis. | P31: Province | Q31: ='[1]26MY_ODYSSEY_DATA'!L5 -> YT
