Workbook
Name prov_cd: 'SELECT PROVINCE'!$B$1
Name province_codes: 'SELECT PROVINCE'!$B$6:$B$16
Name rate_table: 'SELECT PROVINCE'!$B$6:$C$16

Sheet SELECT PROVINCE
A1: Select Province: Choissisez votre province: | B1: YT
B4: Current Labor Rates
B5: Taux de main d'oeuvre en cours
B6: AB | C6: 162
B7: BC | C7: 165
B8: MB | C8: 155
B9: NB | C9: 129
B10: NL | C10: 129
B11: NS | C11: 129
B12: ON | C12: 149 | F12: =prov_cd -> YT
B13: PEI | C13: 123
B14: QC | C14: 140
B15: SK | C15: 155
B16: YT | C16: 165
A23: All published prices, trim specifications, and availability are subject to change without prior notice.
A24: Tout prix, spécifications de versions et disponibilté d'accessoires publiés sont sujets à changer sans pré-avis.

Sheet 26MY_Pilot_APP_EN
B2: Honda Internal | C2: Honda Accessories
C3: Model Name | D3: ='[1]26MY_PILOT_DATA'!C2 -> Pilot
C4: Model Year | D4: ='[1]26MY_PILOT_DATA'!$C$3 -> 2026
C5: S = Standard (accessory comes standard on this trim)
C6: T = Tire Size Change (the size of the accessory wheel is smaller/larger than the OE Wheel. Customer will require new tires to fit these wheels.)
C7: E = Exchange Standard Equipment (the size of the accessory wheel is the same size as the OE wheel and therefore they can use the OE tire.)
C8: N/A = Not Applicable (accessory cannot be applied to this trim)
H10: Province
C11: 1.0 Packages and Kits | H11: =prov_cd -> YT
C12: Description | D12: Part Number | E12: Dealer Net | F12: List Price | G12: FRT | H12: Installed Price | I12: Application | Q12: Comments
I13: ='[1]26MY_PILOT_DATA'!$M$7 -> 0 | J13: ='[1]26MY_PILOT_DATA'!$M$7 -> 0 | K13: ='[1]26MY_PILOT_DATA'!$M$7 -> 0 | L13: ='[1]26MY_PILOT_DATA'!$P$7 -> Sport | M13: ='[1]26MY_PILOT_DATA'!$Q$7 -> EX-L | N13: ='[1]26MY_PILOT_DATA'!$R$7 -> TrailSport | O13: ='[1]26MY_PILOT_DATA'!$S$7 -> Touring | P13: ='[1]26MY_PILOT_DATA'!$T$7 -> Black Edition
B14: 23PIL-PRO-PK1 or 23PIL-PRO-PK2 | C14: =VLOOKUP(B14,'[1]26MY_PILOT_DATA'!B:V,3,FALSE) -> Protection Package | D14: =B14 -> 23PIL-PRO-PK1 or 23PIL-PRO-PK2 | E14: =VLOOKUP($B14,'[1]26MY_PILOT_DATA'!B:V,9,FALSE) -> 298.8 | F14: =VLOOKUP(B14,'[1]26MY_PILOT_DATA'!B:V,10,FALSE) -> 553 | G14: =VLOOKUP(B14,'[1]26MY_PILOT_DATA'!B:V,7,FALSE) -> 0.2 | H14: =VLOOKUP(B14,'[1]26MY_PILOT_DATA'!B:V,11,FALSE) -> 586 | I14: =VLOOKUP($B14,'[1]26MY_PILOT_DATA'!B:V,12,FALSE) -> 0 | J14: =VLOOKUP($B14,'[1]26MY_PILOT_DATA'!B:V,13,FALSE) -> 0 | K14: =VLOOKUP($B14,'[1]26MY_PILOT_DATA'!B:V,14,FALSE) -> 0 | L14: =VLOOKUP(B14,'[1]26MY_PILOT_DATA'!B:V,15,FALSE) -> • | M14: =VLOOKUP(B14,'[1]26MY_PILOT_DATA'!B:V,16,FALSE) -> • | N14: =VLOOKUP(B14,'[1]26MY_PILOT_DATA'!B:V,17,FALSE) -> • | O14: =VLOOKUP(B14,'[1]26MY_PILOT_DATA'!B:V,18,FALSE) -> • | P14: =VLOOKUP(B14,'[1]26MY_PILOT_DATA'!B:V,19,FALSE) -> • | Q14: =IF(VLOOKUP(B14,'[1]26MY_PILOT_DATA'!B:V,20,FALSE)="","",VLOOKUP(B14,'[1]26MY_PILOT_DATA'!B:V,20,FALSE)) -> 23PIL-PRO-PK1: applicable for Sport, EX-L, Touring, and Black Ed. trims 23PIL-PRO-PK2: applicable for TrailSport trim
B15: 08P17-T90-110 or 08P17-T90-300C | C15: =VLOOKUP(B15,'[1]26MY_PILOT_DATA'!B:V,3,FALSE) -> All Season Floor Mats | D15: =B15 -> 08P17-T90-110 or 08P17-T90-300C
B16: 08U45-T90-100 | C16: =VLOOKUP(B16,'[1]26MY_PILOT_DATA'!B:V,3,FALSE) -> Cargo Tray | D16: =B16 -> 08U45-T90-100
B18: 23PIL-PRO-PKA1 | C18: =VLOOKUP(B18,'[1]26MY_PILOT_DATA'!B:V,3,FALSE) -> Protection Package Advance | D18: =B18 -> 23PIL-PRO-PKA1 | E18: =VLOOKUP($B18,'[1]26MY_PILOT_DATA'!B:V,9,FALSE) -> 791.1 | F18: =VLOOKUP(B18,'[1]26MY_PILOT_DATA'!B:V,10,FALSE) -> 1318.5 | G18: =VLOOKUP(B18,'[1]26MY_PILOT_DATA'!B:V,7,FALSE) -> 1.2 | H18: =VLOOKUP(B18,'[1]26MY_PILOT_DATA'!B:V,11,FALSE) -> 1516.5 | I18: =VLOOKUP($B18,'[1]26MY_PILOT_DATA'!B:V,12,FALSE) -> 0 | J18: =VLOOKUP($B18,'[1]26MY_PILOT_DATA'!B:V,13,FALSE) -> 0 | K18: =VLOOKUP($B18,'[1]26MY_PILOT_DATA'!B:V,14,FALSE) -> 0 | L18: =VLOOKUP(B18,'[1]26MY_PILOT_DATA'!B:V,15,FALSE) -> • | M18: =VLOOKUP(B18,'[1]26MY_PILOT_DATA'!B:V,16,FALSE) -> • | N18: =VLOOKUP(B18,'[1]26MY_PILOT_DATA'!B:V,17,FALSE) -> N/A | O18: =VLOOKUP(B18,'[1]26MY_PILOT_DATA'!B:V,18,FALSE) -> • | P18: =VLOOKUP(B18,'[1]26MY_PILOT_DATA'!B:V,19,FALSE) -> • | Q18: =IF(VLOOKUP(B18,'[1]26MY_PILOT_DATA'!B:V,20,FALSE)="","",VLOOKUP(B18,'[1]26MY_PILOT_DATA'!B:V,20,FALSE)) -> 10% Discount applied 23PIL-PRO-PKA1: applicable for Sport, EX-L, Touring, and Black Ed. Trims 23PIL-PRO-PKA2: applicable for TrailSport trim.
B19: 08P17-T90-110 | C19: =VLOOKUP(B19,'[1]26MY_PILOT_DATA'!B:V,3,FALSE) -> All Season Floor Mats | D19: =B19 -> 08P17-T90-110
B20: 08U45-T90-100 | C20: =VLOOKUP(B20,'[1]26MY_PILOT_DATA'!B:V,3,FALSE) -> Cargo Tray | D20: =B20 -> 08U45-T90-100
B21: 08U35-T90-110 | C21: =VLOOKUP(B21,'[1]26MY_PILOT_DATA'!B:V,3,FALSE) -> Cargo Cover | D21: =B21 -> 08U35-T90-110
B22: 08P42-T90-100B | C22: =VLOOKUP(B22,'[1]26MY_PILOT_DATA'!B:V,3,FALSE) -> Seat Back Protector | D22: =B22 -> 08P42-T90-100B
B23: 08P42-T90-100A | C23: =VLOOKUP(B23,'[1]26MY_PILOT_DATA'!B:V,3,FALSE) -> Side Lining Protectors | D23: =B23 -> 08P42-T90-100A
B25: 23PIL-PRO-PKA2 | C25: =VLOOKUP(B25,'[1]26MY_PILOT_DATA'!B:V,3,FALSE) -> Protection Package Advance | D25: =B25 -> 23PIL-PRO-PKA2 | E25: =VLOOKUP($B25,'[1]26MY_PILOT_DATA'!B:V,9,FALSE) -> 776.7 | F25: =VLOOKUP(B25,'[1]26MY_PILOT_DATA'!B:V,10,FALSE) -> 1284.3 | G25: =VLOOKUP(B25,'[1]26MY_PILOT_DATA'!B:V,7,FALSE) -> 1.1 | H25: =VLOOKUP(B25,'[1]26MY_PILOT_DATA'!B:V,11,FALSE) -> 1465.8 | I25: =VLOOKUP($B25,'[1]26MY_PILOT_DATA'!B:V,12,FALSE) -> 0 | J25: =VLOOKUP($B25,'[1]26MY_PILOT_DATA'!B:V,13,FALSE) -> 0 | K25: =VLOOKUP($B25,'[1]26MY_PILOT_DATA'!B:V,14,FALSE) -> 0 | L25: =VLOOKUP(B25,'[1]26MY_PILOT_DATA'!B:V,15,FALSE) -> N/A | M25: =VLOOKUP(B25,'[1]26MY_PILOT_DATA'!B:V,16,FALSE) -> N/A | N25: =VLOOKUP(B25,'[1]26MY_PILOT_DATA'!B:V,17,FALSE) -> • | O25: =VLOOKUP(B25,'[1]26MY_PILOT_DATA'!B:V,18,FALSE) -> N/A | P25: =VLOOKUP(B25,'[1]26MY_PILOT_DATA'!B:V,19,FALSE) -> N/A
B26: 08P17-T90-310C | C26: =VLOOKUP(B26,'[1]26MY_PILOT_DATA'!B:V,3,FALSE) -> All Season Floor Mats TrailSport | D26: =B26 -> 08P17-T90-310C
B27: 08U45-T90-100 | C27: =VLOOKUP(B27,'[1]26MY_PILOT_DATA'!B:V,3,FALSE) -> Cargo Tray | D27: =B27 -> 08U45-T90-100
B28: 08U35-T90-110 | C28: =VLOOKUP(B28,'[1]26MY_PILOT_DATA'!B:V,3,FALSE) -> Cargo Cover | D28: =B28 -> 08U35-T90-110
B29: 08P42-T90-100C | C29: =VLOOKUP(B29,'[1]26MY_PILOT_DATA'!B:V,3,FALSE) -> Seat Back Protector | D29: =B29 -> 08P42-T90-100C
B30: 08P42-T90-100A | C30: =VLOOKUP(B30,'[1]26MY_PILOT_DATA'!B:V,3,FALSE) -> Side Lining Protectors | D30: =B30 -> 08P42-T90-100A
B32: 26PIL-TOW-B1 ou 26PIL-TOW-B2 | C32: =VLOOKUP(B32,'[1]26MY_PILOT_DATA'!B:V,3,FALSE) -> Towing Package | D32: See Comments | E32: =VLOOKUP($B32,'[1]26MY_PILOT_DATA'!B:V,9,FALSE) -> 998.1 | F32: =VLOOKUP(B32,'[1]26MY_PILOT_DATA'!B:V,10,FALSE) -> 1651.5 | G32: =VLOOKUP(B32,'[1]26MY_PILOT_DATA'!B:V,7,FALSE) -> 1.8 | H32: =VLOOKUP(B32,'[1]26MY_PILOT_DATA'!B:V,11,FALSE) -> 1948.5 | I32: =VLOOKUP($B32,'[1]26MY_PILOT_DATA'!B:V,12,FALSE) -> 0 | J32: =VLOOKUP($B32,'[1]26MY_PILOT_DATA'!B:V,13,FALSE) -> 0 | K32: =VLOOKUP($B32,'[1]26MY_PILOT_DATA'!B:V,14,FALSE) -> 0 | L32: =VLOOKUP(B32,'[1]26MY_PILOT_DATA'!B:V,15,FALSE) -> • | M32: =VLOOKUP(B32,'[1]26MY_PILOT_DATA'!B:V,16,FALSE) -> • | N32: =VLOOKUP(B32,'[1]26MY_PILOT_DATA'!B:V,17,FALSE) -> N/A | O32: =VLOOKUP(B32,'[1]26MY_PILOT_DATA'!B:V,18,FALSE) -> N/A | P32: =VLOOKUP(B32,'[1]26MY_PILOT_DATA'!B:V,19,FALSE) -> N/A | Q32: =IF(VLOOKUP(B32,'[1]26MY_PILOT_DATA'!B:V,20,FALSE)="","",VLOOKUP(B32,'[1]26MY_PILOT_DATA'!B:V,20,FALSE)) -> 10% Discount Applied ATF Cooler not needed for 23MY Pilot. Towing capacity is 5000lbs. Sport Trim(Trailer Hitch Panel Black) : 26PIL-TOW-B1: 1-7/8" Trailer Hitch Ball 26PIL-TOW-B2: 2" Trailer Hitch Ball EX-L Trim(Trailer Hitch Panel Silver): 26PIL-TOW-S1: 1-7/8" Trailer Hitch Ball 26PIL-TOW-S2: 2" Trailer Hitch Ball Touring Trim**(Trailer Hitch Panel Silver): 26PIL-TOW-SA1: 1-7/8" Trailer Hitch Ball 26PIL-TOW-SA2: 2" Trailer Hitch Ball Black Edition Trim**(Trailer Hitch Panel Black) : 26PIL-TOW-BA1: 1-7/8" Trailer Hitch Ball 26PIL-TOW-BA2: 2" Trailer Hitch Ball **Touring & Black Edition requires HFA Adapter - 08L91-T90-300A
B33: 08L92-T90-100 | C33: =VLOOKUP(B33,'[1]26MY_PILOT_DATA'!B:V,3,FALSE) -> Trailer Hitch | D33: =B33 -> 08L92-T90-100
B34: 08L91-T90-300B | C34: =VLOOKUP(B34,'[1]26MY_PILOT_DATA'!B:V,3,FALSE) -> Trailer Hitch Harness | D34: =B34 -> 08L91-T90-300B
B35: 08L92-T90-300D or 08L92-T90-300E | C35: =VLOOKUP(B35,'[1]26MY_PILOT_DATA'!B:V,3,FALSE) -> Trailer Hitch Panel Black or Silver | D35: =B35 -> 08L92-T90-300D or 08L92-T90-300E
B36: 08L92-T90-100A | C36: =VLOOKUP(B36,'[1]26MY_PILOT_DATA'!B:V,3,FALSE) -> Trailer Hitch Ball Mount | D36: =B36 -> 08L92-T90-100A
B37: 08L92-S9V-300G or 08L92-S9V-300H | C37: =VLOOKUP(B37,'[1]26MY_PILOT_DATA'!B:V,3,FALSE) -> Trailer Hitch Ball - 1-7/8" or 2" | D37: =B37 -> 08L92-S9V-300G or 08L92-S9V-300H
B38: 08L92-SJC-300A | C38: =VLOOKUP(B38,'[1]26MY_PILOT_DATA'!B:V,3,FALSE) -> Trailer Hitch Locking Pin | D38: =B38 -> 08L92-SJC-300A
B40: 26PIL-TOW-SA1 or 26PIL-TOW-SA2 | C40: =VLOOKUP(B40,'[1]26MY_PILOT_DATA'!B:V,3,FALSE) -> Towing Package | D40: See Comments | E40: =VLOOKUP($B40,'[1]26MY_PILOT_DATA'!B:V,9,FALSE) -> 1292.4 | F40: =VLOOKUP(B40,'[1]26MY_PILOT_DATA'!B:V,10,FALSE) -> 2071.8 | G40: =VLOOKUP(B40,'[1]26MY_PILOT_DATA'!B:V,7,FALSE) -> 1.9 | H40: =VLOOKUP(B40,'[1]26MY_PILOT_DATA'!B:V,11,FALSE) -> 2385.3 | I40: =VLOOKUP($B40,'[1]26MY_PILOT_DATA'!B:V,12,FALSE) -> 0 | J40: =VLOOKUP($B40,'[1]26MY_PILOT_DATA'!B:V,13,FALSE) -> 0 | K40: =VLOOKUP($B40,'[1]26MY_PILOT_DATA'!B:V,14,FALSE) -> 0 | L40: =VLOOKUP(B40,'[1]26MY_PILOT_DATA'!B:V,15,FALSE) -> N/A | M40: =VLOOKUP(B40,'[1]26MY_PILOT_DATA'!B:V,16,FALSE) -> N/A | N40: =VLOOKUP(B40,'[1]26MY_PILOT_DATA'!B:V,17,FALSE) -> N/A | O40: =VLOOKUP(B40,'[1]26MY_PILOT_DATA'!B:V,18,FALSE) -> • | P40: =VLOOKUP(B40,'[1]26MY_PILOT_DATA'!B:V,19,FALSE) -> •
B41: 08L92-T90-100 | C41: =VLOOKUP(B41,'[1]26MY_PILOT_DATA'!B:V,3,FALSE) -> Trailer Hitch | D41: =B41 -> 08L92-T90-100
B42: 08L91-T90-300B | C42: =VLOOKUP(B42,'[1]26MY_PILOT_DATA'!B:V,3,FALSE) -> Trailer Hitch Harness | D42: =B42 -> 08L91-T90-300B
B43: 08L92-T90-300D or 08L92-T90-300E | C43: =VLOOKUP(B43,'[1]26MY_PILOT_DATA'!B:V,3,FALSE) -> Trailer Hitch Panel Black or Silver | D43: =B43 -> 08L92-T90-300D or 08L92-T90-300E
B44: 08L92-T90-100A | C44: =VLOOKUP(B44,'[1]26MY_PILOT_DATA'!B:V,3,FALSE) -> Trailer Hitch Ball Mount | D44: =B44 -> 08L92-T90-100A
B45: 08L92-S9V-300G or 08L92-S9V-300H | C45: =VLOOKUP(B45,'[1]26MY_PILOT_DATA'!B:V,3,FALSE) -> Trailer Hitch Ball - 1-7/8" or 2" | D45: =B45 -> 08L92-S9V-300G or 08L92-S9V-300H
B46: 08L92-SJC-300A | C46: =VLOOKUP(B46,'[1]26MY_PILOT_DATA'!B:V,3,FALSE) -> Trailer Hitch Locking Pin | D46: =B46 -> 08L92-SJC-300A
...

Sheet 26MY_Pilot_SELL_EN
B3: 26MY Honda Pilot
B4: 200
B6: POPULAR ACCESSORIES
B7: 20
B8: 150
B10: 20 | C10: ='26MY_Pilot_APP_EN'!$C$133 -> All Season Floor Mats | H10: ='26MY_Pilot_APP_EN'!$C$135 -> Cargo Tray | M10: ='26MY_Pilot_APP_EN'!$C$155 -> Illuminated Door Sill
B11: 20 | C11: ='26MY_Pilot_APP_EN'!$H$133 -> 374.5 | D11: =-PMT($D$29/52,5*52,C11) -> 1.7076821 | E11: /wk * | F11: =$C$29 -> (6.99%) | H11: ='26MY_Pilot_APP_EN'!$H$135 -> 211.5 | I11: =-PMT($D$29/52,5*52,H11) -> 0.9644186 | J11: /wk * | K11: =$C$29 -> (6.99%) | M11: ='26MY_Pilot_APP_EN'!$H$155 -> 802.5 | N11: =-PMT($D$29/52,5*52,M11) -> 3.6593188 | O11: /wk * | P11: =$C$29 -> (6.99%)
B13: 150
B15: 20 | C15: ='26MY_Pilot_APP_EN'!$C$105 -> Crossbars | H15: ='26MY_Pilot_APP_EN'!$C$94 -> Door Visor | M15: Black Emblems -"H" Mark & AWD
B16: 50 | C16: ='26MY_Pilot_APP_EN'!$H$105 -> 443 | D16: =-PMT($D$29/52,5*52,C16) -> 2.0200352 | E16: /wk * | F16: =$C$29 -> (6.99%) | H16: ='26MY_Pilot_APP_EN'!$H$94 -> 529 | I16: =-PMT($D$29/52,5*52,H16) -> 2.4121865 | J16: /wk * | K16: =$C$29 -> (6.99%) | M16: =SUM('26MY_Pilot_APP_EN'!$H$87+'26MY_Pilot_APP_EN'!$H$88) -> 192 | N16: =-PMT($D$29/52,5*52,M16) -> 0.87550058 | O16: /wk * | P16: =$C$29 -> (6.99%)
B18: 150
B20: 20 | C20: ='26MY_Pilot_APP_EN'!$C$92 -> Running Boards Rugged | H20: Towing Package - Touring Trim | M20: ='26MY_Pilot_APP_EN'!$C$145 -> Separation Barrier
B21: 50 | C21: ='26MY_Pilot_APP_EN'!$H$92 -> 1452.5 | D21: =-PMT($D$29/52,5*52,C21) -> 6.623253 | E21: /wk * | F21: =$C$29 -> (6.99%) | H21: =SUM('26MY_Pilot_APP_EN'!$H$40:$H$47) -> 2385.3 | I21: =-PMT($D$29/52,5*52,H21) -> 10.876727 | J21: /wk * | K21: =$C$29 -> (6.99%) | M21: ='26MY_Pilot_APP_EN'!$H$145 -> 1159 | N21: =-PMT($D$29/52,5*52,M21) -> 5.2849227 | O21: /wk * | P21: =$C$29 -> (6.99%)
C23: Genuine Honda Accessories purchased with a new Honda vehicle include a 3 year / 60,000 km manufacturer's warranty.
C24: Vehicle accessories purchased after vehicle sale include a 1 year / 20,000km manufacturer's warranty.
B25: 20 | C25: *Prices shown include the cost of installation.
B26: 60 | C26: *For informational purposes only. Weekly amounts shown are estimated payments based on a 60 month finance contract at 6.99% APR (including the cost of installation). Applicable taxes and fees are extra. Accessories cannot be financed on their own and must be financed through Honda Canada Finance Inc., on approved credit, in conjunction with a Honda vehicle. Representative finance example: $350.00 financed at 6.99% APR equals $1.60 weekly for 60 months. 260 weekly payments required. Cost of borrowing is $64.80 for a total obligation of $414.80. Actual payment amounts will vary based on APR, finance contract term and cost of the applicable accessories. Conditions apply. See your Honda dealer for full details.
C27: *More customized weekly payment options & accessories can be seen on Honda.ca - Build & Price
B28: 20
B29: 18 | C29: (6.99%) | D29: 0.0699
B30: 7.5 | C30: 12 | D30: 8 | E30: 8 | F30: 10 | G30: 8.5 | H30: 12 | I30: 8 | J30: 8 | K30: 10 | L30: 8.5 | M30: 12 | N30: 8 | O30: 8 | P30: 10 | Q30: 7.5
B31: Publication Date: | C31: ='[1]26MY_PILOT_DATA'!$C$4 -> 46076 | D31: ='SELECT PROVINCE'!$A$23 -> All published prices, trim specifications, and availability are subject to change without prior notice. | P31: Province | Q31: ='[1]26MY_PILOT_DATA'!L6 -> YT

Sheet 26MY_Pilot_APP_FR
C2: Accessoires Honda
C3: Nom du modèle | D3: ='[1]26MY_PILOT_DATA'!$C$2 -> Pilot
C4: Année modèle | D4: ='26MY_Pilot_APP_EN'!D4 -> 2026
C5: S = De série (accessoire de série sur cette version).
C6: T = Taille des pneus (la taille de la jante accessoire diffère de la jante d’origine. Le client aura besoin de nouveaux pneus pour ces jantes).
C7: E = Échange d’équipement de série (la taille de la jante accessoire est la même que celle de la jante d’origine. Le client peut utiliser les pneus d’origine).
C8: N/A = Sans objet (l’accessoire ne peut être utilisé pour cette version).
H10: Province
C11: 1.0 Groupes et ensembles | H11: =prov_cd -> YT
C12: La description | D12: Numéro de pièce | E12: Prix net | F12: Prix de liste | G12: T.F.F. | H12: Prix installé | I12: Application | Q12: Commentaires
I13: ='[1]26MY_PILOT_DATA'!$M$6 -> 0 | J13: ='[1]26MY_PILOT_DATA'!$M$6 -> 0 | K13: ='[1]26MY_PILOT_DATA'!$M$6 -> 0 | L13: ='[1]26MY_PILOT_DATA'!$P$6 -> Sport | M13: ='[1]26MY_PILOT_DATA'!$Q$6 -> EX-L | N13: ='[1]26MY_PILOT_DATA'!$R$6 -> TrailSport | O13: ='[1]26MY_PILOT_DATA'!$S$6 -> Touring | P13: ='[1]26MY_PILOT_DATA'!$T$6 -> Black Edition
B14: 23PIL-PRO-PK1 ou 23PIL-PRO-PK2 | C14: =VLOOKUP(B14,'[1]26MY_PILOT_DATA'!B:V,4,FALSE) -> Ensemble de protection | D14: =B14 -> 23PIL-PRO-PK1 ou 23PIL-PRO-PK2 | E14: =VLOOKUP($B14,'[1]26MY_PILOT_DATA'!B:V,9,FALSE) -> 298.8 | F14: =VLOOKUP(B14,'[1]26MY_PILOT_DATA'!B:V,10,FALSE) -> 553 | G14: =VLOOKUP(B14,'[1]26MY_PILOT_DATA'!B:V,7,FALSE) -> 0.2 | H14: =VLOOKUP(B14,'[1]26MY_PILOT_DATA'!B:V,11,FALSE) -> 586 | I14: =VLOOKUP($B14,'[1]26MY_PILOT_DATA'!B:V,12,FALSE) -> 0 | J14: =VLOOKUP($B14,'[1]26MY_PILOT_DATA'!B:V,13,FALSE) -> 0 | K14: =VLOOKUP($B14,'[1]26MY_PILOT_DATA'!B:V,14,FALSE) -> 0 | L14: =VLOOKUP(B14,'[1]26MY_PILOT_DATA'!B:V,15,FALSE) -> • | M14: =VLOOKUP(B14,'[1]26MY_PILOT_DATA'!B:V,16,FALSE) -> • | N14: =VLOOKUP(B14,'[1]26MY_PILOT_DATA'!B:V,17,FALSE) -> • | O14: =VLOOKUP(B14,'[1]26MY_PILOT_DATA'!B:V,18,FALSE) -> • | P14: =VLOOKUP(B14,'[1]26MY_PILOT_DATA'!B:V,19,FALSE) -> • | Q14: =IF(VLOOKUP(B14,'[1]26MY_PILOT_DATA'!B:V,21,FALSE)="","",VLOOKUP(B14,'[1]26MY_PILOT_DATA'!B:V,21,FALSE)) -> 23PIL-PRO-PK1: s'applique aux versions Sport, EX-L, Touring, Black Edition 23PIL-PRO-PK2: s'applique aux version TrailSport
B15: 08P17-T90-110 ou 08P17-T90-300C | C15: =VLOOKUP(B15,'[1]26MY_PILOT_DATA'!B:V,4,FALSE) -> Protège-tapis toutes saisons | D15: =B15 -> 08P17-T90-110 ou 08P17-T90-300C
B16: 08U45-T90-100 | C16: =VLOOKUP(B16,'[1]26MY_PILOT_DATA'!B:V,4,FALSE) -> Plateau de compartiment à bagages | D16: =B16 -> 08U45-T90-100
B18: 23PIL-PRO-PKA1 | C18: =VLOOKUP(B18,'[1]26MY_PILOT_DATA'!B:V,4,FALSE) -> Ensemble de protection Avance | D18: =B18 -> 23PIL-PRO-PKA1 | E18: =VLOOKUP($B18,'[1]26MY_PILOT_DATA'!B:V,9,FALSE) -> 791.1 | F18: =VLOOKUP(B18,'[1]26MY_PILOT_DATA'!B:V,10,FALSE) -> 1318.5 | G18: =VLOOKUP(B18,'[1]26MY_PILOT_DATA'!B:V,7,FALSE) -> 1.2 | H18: =VLOOKUP(B18,'[1]26MY_PILOT_DATA'!B:V,11,FALSE) -> 1516.5 | I18: =VLOOKUP($B18,'[1]26MY_PILOT_DATA'!B:V,12,FALSE) -> 0 | J18: =VLOOKUP($B18,'[1]26MY_PILOT_DATA'!B:V,13,FALSE) -> 0 | K18: =VLOOKUP($B18,'[1]26MY_PILOT_DATA'!B:V,14,FALSE) -> 0 | L18: =VLOOKUP(B18,'[1]26MY_PILOT_DATA'!B:V,15,FALSE) -> • | M18: =VLOOKUP(B18,'[1]26MY_PILOT_DATA'!B:V,16,FALSE) -> • | N18: =VLOOKUP(B18,'[1]26MY_PILOT_DATA'!B:V,17,FALSE) -> N/A | O18: =VLOOKUP(B18,'[1]26MY_PILOT_DATA'!B:V,18,FALSE) -> • | P18: =VLOOKUP(B18,'[1]26MY_PILOT_DATA'!B:V,19,FALSE) -> • | Q18: =IF(VLOOKUP(B18,'[1]26MY_PILOT_DATA'!B:V,21,FALSE)="","",VLOOKUP(B18,'[1]26MY_PILOT_DATA'!B:V,21,FALSE)) -> Rabais de 10 % est appliqué 23PIL-PRO-PKA1: s'applique aux versions Sport, EX-L, Touring, Black Edition 23PIL-PRO-PKA2: s'applique aux version TrailSport
B19: 08P17-T90-110 | C19: =VLOOKUP(B19,'[1]26MY_PILOT_DATA'!B:V,4,FALSE) -> Protège-tapis toutes saisons | D19: =B19 -> 08P17-T90-110
B20: 08U45-T90-100 | C20: =VLOOKUP(B20,'[1]26MY_PILOT_DATA'!B:V,4,FALSE) -> Plateau de compartiment à bagages | D20: =B20 -> 08U45-T90-100
B21: 08U35-T90-110 | C21: =VLOOKUP(B21,'[1]26MY_PILOT_DATA'!B:V,4,FALSE) -> Couvercle de compartiment à bagages | D21: =B21 -> 08U35-T90-110
B22: 08P42-T90-100B | C22: =VLOOKUP(B22,'[1]26MY_PILOT_DATA'!B:V,4,FALSE) -> Protecteur de dossier de siège arrière | D22: =B22 -> 08P42-T90-100B
B23: 08P42-T90-100A | C23: =VLOOKUP(B23,'[1]26MY_PILOT_DATA'!B:V,4,FALSE) -> Protecteurs de doublure latérale | D23: =B23 -> 08P42-T90-100A
B25: 23PIL-PRO-PKA2 | C25: =VLOOKUP(B25,'[1]26MY_PILOT_DATA'!B:V,4,FALSE) -> Ensemble de protection Avance | D25: =B25 -> 23PIL-PRO-PKA2 | E25: =VLOOKUP($B25,'[1]26MY_PILOT_DATA'!B:V,9,FALSE) -> 776.7 | F25: =VLOOKUP(B25,'[1]26MY_PILOT_DATA'!B:V,10,FALSE) -> 1284.3 | G25: =VLOOKUP(B25,'[1]26MY_PILOT_DATA'!B:V,7,FALSE) -> 1.1 | H25: =VLOOKUP(B25,'[1]26MY_PILOT_DATA'!B:V,11,FALSE) -> 1465.8 | I25: =VLOOKUP($B25,'[1]26MY_PILOT_DATA'!B:V,12,FALSE) -> 0 | J25: =VLOOKUP($B25,'[1]26MY_PILOT_DATA'!B:V,13,FALSE) -> 0 | K25: =VLOOKUP($B25,'[1]26MY_PILOT_DATA'!B:V,14,FALSE) -> 0 | L25: =VLOOKUP(B25,'[1]26MY_PILOT_DATA'!B:V,15,FALSE) -> N/A | M25: =VLOOKUP(B25,'[1]26MY_PILOT_DATA'!B:V,16,FALSE) -> N/A | N25: =VLOOKUP(B25,'[1]26MY_PILOT_DATA'!B:V,17,FALSE) -> • | O25: =VLOOKUP(B25,'[1]26MY_PILOT_DATA'!B:V,18,FALSE) -> N/A | P25: =VLOOKUP(B25,'[1]26MY_PILOT_DATA'!B:V,19,FALSE) -> N/A
B26: 08P17-T90-310C | C26: =VLOOKUP(B26,'[1]26MY_PILOT_DATA'!B:V,4,FALSE) -> Protège-tapis toutes saisons, TrailSport | D26: =B26 -> 08P17-T90-310C
B27: 08U45-T90-100 | C27: =VLOOKUP(B27,'[1]26MY_PILOT_DATA'!B:V,4,FALSE) -> Plateau de compartiment à bagages | D27: =B27 -> 08U45-T90-100
B28: 08U35-T90-110 | C28: =VLOOKUP(B28,'[1]26MY_PILOT_DATA'!B:V,4,FALSE) -> Couvercle de compartiment à bagages | D28: =B28 -> 08U35-T90-110
B29: 08P42-T90-100C | C29: =VLOOKUP(B29,'[1]26MY_PILOT_DATA'!B:V,4,FALSE) -> Protecteur de dossier de siège arrière | D29: =B29 -> 08P42-T90-100C
B30: 08P42-T90-100A | C30: =VLOOKUP(B30,'[1]26MY_PILOT_DATA'!B:V,4,FALSE) -> Protecteurs de doublure latérale | D30: =B30 -> 08P42-T90-100A
B32: 26PIL-TOW-B1 ou 26PIL-TOW-B2 | C32: =VLOOKUP(B32,'[1]26MY_PILOT_DATA'!B:V,4,FALSE) -> Ensemble de remorquage | D32: Voir les commentaires | E32: =VLOOKUP($B32,'[1]26MY_PILOT_DATA'!B:V,9,FALSE) -> 998.1 | F32: =VLOOKUP(B32,'[1]26MY_PILOT_DATA'!B:V,10,FALSE) -> 1651.5 | G32: =VLOOKUP(B32,'[1]26MY_PILOT_DATA'!B:V,7,FALSE) -> 1.8 | H32: =VLOOKUP(B32,'[1]26MY_PILOT_DATA'!B:V,11,FALSE) -> 1948.5 | I32: =VLOOKUP($B32,'[1]26MY_PILOT_DATA'!B:V,12,FALSE) -> 0 | J32: =VLOOKUP($B32,'[1]26MY_PILOT_DATA'!B:V,13,FALSE) -> 0 | K32: =VLOOKUP($B32,'[1]26MY_PILOT_DATA'!B:V,14,FALSE) -> 0 | L32: =VLOOKUP(B32,'[1]26MY_PILOT_DATA'!B:V,15,FALSE) -> • | M32: =VLOOKUP(B32,'[1]26MY_PILOT_DATA'!B:V,16,FALSE) -> • | N32: =VLOOKUP(B32,'[1]26MY_PILOT_DATA'!B:V,17,FALSE) -> N/A | O32: =VLOOKUP(B32,'[1]26MY_PILOT_DATA'!B:V,18,FALSE) -> N/A | P32: =VLOOKUP(B32,'[1]26MY_PILOT_DATA'!B:V,19,FALSE) -> N/A | Q32: =IF(VLOOKUP(B32,'[1]26MY_PILOT_DATA'!B:V,21,FALSE)="","",VLOOKUP(B32,'[1]26MY_PILOT_DATA'!B:V,21,FALSE)) -> Rabais de 10 % est appliqué Refroidisseur de transmission non requis pour le Pilot 2023. La capacité de remorquage est de 5000 livres. Sport version(Capuchon d’attelage de remorque noir): 26PIL-TOW-B1: comprend un attelage de remorque de 1 7/8 po boule. 26PIL-TOW-B2: comprend attelage de remorque de 2 po boule. EX-L version(Capuchon d’attelage de remorque argent): 26PIL-TOW-S1: comprend un attelage de remorque de 1 7/8 po boule. 26PIL-TOW-S2: comprend attelage de remorque de 2 po boule. Touring version**(Capuchon d’attelage de remorque argent): 26PIL-TOW-SA1: comprend un attelage de remorque de 1 7/8 po boule. 26PIL-TOW-SA2: comprend attelage de remorque de 2 po boule. Black Edition version**(Capuchon d’attelage de remorque noir): 26PIL-TOW-BA1: comprend un attelage de remorque de 1 7/8 po boule. 26PIL-TOW-BA2: comprend attelage de remorque de 2 po boule. **Touring et Black Edition nécessitent un adaptateur d’accès mains libres pour attelage de remorque - 08L91-T90-300A
B33: 08L92-T90-100 | C33: =VLOOKUP(B33,'[1]26MY_PILOT_DATA'!B:V,4,FALSE) -> Attelage de remorque | D33: =B33 -> 08L92-T90-100
B34: 08L91-T90-300B | C34: =VLOOKUP(B34,'[1]26MY_PILOT_DATA'!B:V,4,FALSE) -> Faisceau de remorque | D34: =B34 -> 08L91-T90-300B
B35: 08L92-T90-300D ou 08L92-T90-300E | C35: =VLOOKUP(B35,'[1]26MY_PILOT_DATA'!B:V,4,FALSE) -> Capuchon d’attelage de remorque noir ou argent | D35: =B35 -> 08L92-T90-300D ou 08L92-T90-300E
B36: 08L92-T90-100A | C36: =VLOOKUP(B36,'[1]26MY_PILOT_DATA'!B:V,4,FALSE) -> Attelage de remorque - montage sur boule | D36: =B36 -> 08L92-T90-100A
B37: 08L92-S9V-300G ou 08L92-S9V-300H | C37: =VLOOKUP(B37,'[1]26MY_PILOT_DATA'!B:V,4,FALSE) -> Rotule d'attelage de 1 7/8 po ou 2 po | D37: =B37 -> 08L92-S9V-300G ou 08L92-S9V-300H
B38: 08L92-SJC-300A | C38: =VLOOKUP(B38,'[1]26MY_PILOT_DATA'!B:V,4,FALSE) -> Attelage de remorque - goupille de verrouillage | D38: =B38 -> 08L92-SJC-300A
B40: 26PIL-TOW-SA1 or 26PIL-TOW-SA2 | C40: =VLOOKUP(B40,'[1]26MY_PILOT_DATA'!B:V,4,FALSE) -> Ensemble de remorquage | D40: Voir les commentaires | E40: =VLOOKUP($B40,'[1]26MY_PILOT_DATA'!B:V,9,FALSE) -> 1292.4 | F40: =VLOOKUP(B40,'[1]26MY_PILOT_DATA'!B:V,10,FALSE) -> 2071.8 | G40: =VLOOKUP(B40,'[1]26MY_PILOT_DATA'!B:V,7,FALSE) -> 1.9 | H40: =VLOOKUP(B40,'[1]26MY_PILOT_DATA'!B:V,11,FALSE) -> 2385.3 | I40: =VLOOKUP($B40,'[1]26MY_PILOT_DATA'!B:V,12,FALSE) -> 0 | J40: =VLOOKUP($B40,'[1]26MY_PILOT_DATA'!B:V,13,FALSE) -> 0 | K40: =VLOOKUP($B40,'[1]26MY_PILOT_DATA'!B:V,14,FALSE) -> 0 | L40: =VLOOKUP(B40,'[1]26MY_PILOT_DATA'!B:V,15,FALSE) -> N/A | M40: =VLOOKUP(B40,'[1]26MY_PILOT_DATA'!B:V,16,FALSE) -> N/A | N40: =VLOOKUP(B40,'[1]26MY_PILOT_DATA'!B:V,17,FALSE) -> N/A | O40: =VLOOKUP(B40,'[1]26MY_PILOT_DATA'!B:V,18,FALSE) -> • | P40: =VLOOKUP(B40,'[1]26MY_PILOT_DATA'!B:V,19,FALSE) -> •
B41: 08L92-T90-100 | C41: =VLOOKUP(B41,'[1]26MY_PILOT_DATA'!B:V,4,FALSE) -> Attelage de remorque | D41: =B41 -> 08L92-T90-100
B42: 08L91-T90-300B | C42: =VLOOKUP(B42,'[1]26MY_PILOT_DATA'!B:V,4,FALSE) -> Faisceau de remorque | D42: =B42 -> 08L91-T90-300B
B43: 08L92-T90-300D ou 08L92-T90-300E | C43: =VLOOKUP(B43,'[1]26MY_PILOT_DATA'!B:V,4,FALSE) -> Capuchon d’attelage de remorque noir ou argent | D43: =B43 -> 08L92-T90-300D ou 08L92-T90-300E
B44: 08L92-T90-100A | C44: =VLOOKUP(B44,'[1]26MY_PILOT_DATA'!B:V,4,FALSE) -> Attelage de remorque - montage sur boule | D44: =B44 -> 08L92-T90-100A
B45: 08L92-S9V-300G ou 08L92-S9V-300H | C45: =VLOOKUP(B45,'[1]26MY_PILOT_DATA'!B:V,4,FALSE) -> Rotule d'attelage de 1 7/8 po ou 2 po | D45: =B45 -> 08L92-S9V-300G ou 08L92-S9V-300H
B46: 08L92-SJC-300A | C46: =VLOOKUP(B46,'[1]26MY_PILOT_DATA'!B:V,4,FALSE) -> Attelage de remorque - goupille de verrouillage | D46: =B46 -> 08L92-SJC-300A
...

Sheet 26MY_Pilot_SELL_FR
B3: 26MY Honda Pilot
B4: 200
B6: ACCESSOIRES POPULAIRES
B7: 20
B8: 150
B10: 20 | C10: ='26MY_Pilot_APP_FR'!$C$131 -> Protège-tapis toutes saisons | H10: ='26MY_Pilot_APP_FR'!$C$133 -> Plateau de compartiment à bagages | M10: ='26MY_Pilot_APP_FR'!$C$153 -> Garniture lumineuses de bas de portière
B11: 20 | C11: ='26MY_Pilot_APP_FR'!$H$131 -> 374.5 | D11: =-PMT($D$29/52,5*52,C11) -> 1.7076821 | E11: /wk * | F11: =$C$29 -> (6.99%) | H11: ='26MY_Pilot_APP_FR'!$H$133 -> 211.5 | I11: =-PMT($D$29/52,5*52,H11) -> 0.9644186 | J11: /wk * | K11: =$C$29 -> (6.99%) | M11: ='26MY_Pilot_APP_FR'!$H$153 -> 802.5 | N11: =-PMT($D$29/52,5*52,M11) -> 3.6593188 | O11: /wk * | P11: =$C$29 -> (6.99%)
B13: 150
B15: 20 | C15: ='26MY_Pilot_APP_FR'!$C$103 -> Porte-bagages de toit | H15: ='26MY_Pilot_APP_FR'!$C$92 -> Visières de portière | M15: Emblème, noirs lustré - Logo « H » & « AWD »
B16: 50 | C16: ='26MY_Pilot_APP_FR'!$H$103 -> 443 | D16: =-PMT($D$29/52,5*52,C16) -> 2.0200352 | E16: /wk * | F16: =$C$29 -> (6.99%) | H16: ='26MY_Pilot_APP_FR'!$H$92 -> 529 | I16: =-PMT($D$29/52,5*52,H16) -> 2.4121865 | J16: /wk * | K16: =$C$29 -> (6.99%) | M16: =SUM('26MY_Pilot_APP_FR'!$H$85+'26MY_Pilot_APP_FR'!$H$86) -> 192 | N16: =-PMT($D$29/52,5*52,M16) -> 0.87550058 | O16: /wk * | P16: =$C$29 -> (6.99%)
B18: 150
B20: 20 | C20: ='26MY_Pilot_APP_FR'!$C$90 -> Marchepieds robustes | H20: Ensemble de remorquage touring version | M20: ='26MY_Pilot_APP_FR'!$C$143 -> Barrière de séparation
B21: 50 | C21: ='26MY_Pilot_APP_FR'!$H$90 -> 1452.5 | D21: =-PMT($D$29/52,5*52,C21) -> 6.623253 | E21: /wk * | F21: =$C$29 -> (6.99%) | H21: =SUM('26MY_Pilot_APP_FR'!$H$40:$H$46) -> 2385.3 | I21: =-PMT($D$29/52,5*52,H21) -> 10.876727 | J21: /wk * | K21: =$C$29 -> (6.99%) | M21: ='26MY_Pilot_APP_FR'!$H$143 -> 1159 | N21: =-PMT($D$29/52,5*52,M21) -> 5.2849227 | O21: /wk * | P21: =$C$29 -> (6.99%)
C23: Les accessoires Honda d’origine achetés avec un véhicule Honda neuf incluent une garantie du fabricant de 3 ans ou 60 000 km.
C24: Les accessoires de véhicule achetés après la vente du véhicule incluent une garantie du fabricant de 1 an ou 20 000 km.
B25: 20 | C25: *Les prix indiqués incluent le coût d'installation.
B26: 60 | C26: *À titre d’information seulement. Les montants hebdomadaires indiqués sont des paiements estimés basés sur un contrat de financement de 60 mois à un taux annuel en pourcentage (TAP) de 6,99 % (coût d’installation compris). Taxes et frais applicables en sus. Les accessoires ne peuvent être financés seuls et doivent être financés par l’entremise de Honda Canada Finance Inc., sur approbation de crédit, conjointement avec un véhicule Honda. Exemple de financement représentatif : Un montant de 350,00 $ financé à un TAP de 6,99 % équivaut à un paiement hebdomadaire de 1,60 $ pendant 60 mois. 260 paiements hebdomadaires sont requis. Le coût d’emprunt est de 64,80 $, pour une obligation totale de 414,80 $. Le montant réel des paiements variera en fonction du TAP, de la période du contrat de financement et du coût des accessoires applicables. Certaines conditions s’appliquent. Veuillez visiter votre concessionnaire Honda pour obtenir tous les détails.
C27: *Vous pouvez voir d’autres options de paiements hebdomadaires personnalisés ainsi que des accessoires sur le site Honda.ca – Configuration et prix.
B28: 20
B29: 18 | C29: (6.99%) | D29: 0.0699
B30: 7.5 | C30: 12 | D30: 8 | E30: 8 | F30: 10 | G30: 8.5 | H30: 12 | I30: 8 | J30: 8 | K30: 10 | L30: 8.5 | M30: 12 | N30: 8 | O30: 8 | P30: 10 | Q30: 7.5
B31: Date de publication: | C31: ='[1]26MY_PILOT_DATA'!$C$4 -> 46076 | D31: Tout prix, spécifications de versions et disponibilté d'accessoires publiés sont sujets à changer sans pré-avis. | P31: Province | Q31: ='[1]26MY_PILOT_DATA'!L6 -> YT
